#VRML_SIM R2022a utf8
WorldInfo {
  info [
    "A Khepera robot equipped with a gripper"
  ]
  title "Khepera Gripper"
  CFM 0.001
  ERP 0.4
  basicTimeStep 10
  contactProperties [
    ContactProperties {
      material1 "gripper"
      material2 "stick"
      coulombFriction [
        10
      ]
      bounceVelocity 0.5
    }
    ContactProperties {
      material1 "khepera"
      coulombFriction [
        0.1
      ]
    }
  ]
}
Viewpoint {
  orientation -0.006417778102035406 -0.999851232656693 0.016010143007634276 5.521033447965387
  position -2.04502803638521 -0.07746012354627586 1.5076613234573326
}
TexturedBackground {
}
TexturedBackgroundLight {
  luminosity 0.5
}
DEF arena RectangleArena {
  translation -0.04 -0.07 0
  rotation 0 1 0 4.692820414042842e-06
  floorSize 2 2
}
DEF supervisor TinkerbotsBase {
  translation -0.41 0 0
  controller "ga_supervisor"
  supervisor TRUE
  synchronization FALSE
  extensionSlot [
    Receiver {
      channel 2
    }
    Emitter {
      channel 1
    }
  ]
}
DEF khepera Robot {
  translation -0.115433 0 0.0045528
  children [
    GPS {
      name "gps(1)"
    }
    Group {
      children [
        LightSensor {
          lookupTable [
            0 0 0
            4 1024 0
          ]
        }
        LED {
          recognitionColors [
            0 0 0
          ]
        }
        TouchSensor {
        }
        GPS {
        }
        DistanceSensor {
        }
        InertialUnit {
        }
        Receiver {
          channel 1
        }
        Emitter {
          channel 2
        }
        DEF LIFT_HINGE_JOINT HingeJoint {
          jointParameters HingeJointParameters {
            position -1.4
            axis 0 1 0
            anchor -0.01 0 0.022
          }
          device [
            RotationalMotor {
              name "motor"
            }
          ]
          endPoint Solid {
            translation -0.010000272342184861 2.437851864822672e-09 0.02199927550845633
            rotation 0.7058148425159846 -0.7058148425160009 -0.06042198414690506 3.0208953118880326
            children [
              DEF RIGHT_GRIP SliderJoint {
                jointParameters JointParameters {
                  axis 1 0 0
                }
                device [
                  LinearMotor {
                    name "right grip"
                    maxVelocity 0.1
                    maxPosition 0.029
                    maxForce 100
                  }
                ]
                endPoint Solid {
                  translation 3.7651380744692626e-13 0 -0.048
                  rotation 0 1 0 1.5708
                  children [
                    Shape {
                      appearance PBRAppearance {
                        baseColor 0.8 0.8 0.8
                        roughness 1
                        metalness 0
                      }
                      geometry IndexedFaceSet {
                        coord Coordinate {
                          point [
                            0 -0.004 0.004
                            0.03 -0.004 0.002
                            0.03 -0.004 0.0001
                            0 -0.004 0.0001
                            0 -0.004 0.004
                            0 0.004 0.004
                            0.03 0.004 0.002
                            0.03 0.004 0.0001
                            0 0.004 0.0001
                            0 0.004 0.004
                          ]
                        }
                        coordIndex [
                          4, 3, 2, 1, 0, -1, 5, 6, 7, 8, 9, -1, 0, 1, 6, 5, -1, 1, 2, 7, 6, -1, 2, 3, 8, 7, -1, 3, 4, 9, 8, -1
                        ]
                      }
                    }
                    DistanceSensor {
                      translation 0.015 0 0
                      rotation 0 1 0 1.5708
                      name "ds"
                      lookupTable [
                        0 0 0
                        0.05 1000 0
                      ]
                      type "infra-red"
                    }
                  ]
                  name "right grip"
                  contactMaterial "gripper"
                  boundingObject Transform {
                    translation 0.015 0 0.003
                    children [
                      Box {
                        size 0.028 0.007 0.005
                      }
                    ]
                  }
                  physics Physics {
                    density 100
                    centerOfMass [
                      0.01 0 0
                    ]
                  }
                }
              }
              DEF LEFT_GRIP SliderJoint {
                jointParameters JointParameters {
                  axis -1 0 0
                }
                device [
                  LinearMotor {
                    name "left grip"
                    maxVelocity 0.1
                    maxPosition 0.029
                    maxForce 100
                  }
                ]
                endPoint Solid {
                  translation 3.765140243932399e-13 0 -0.048
                  rotation 0 1 0 -1.5708
                  children [
                    Shape {
                      appearance PBRAppearance {
                        baseColor 0.8 0.8 0.8
                        roughness 1
                        metalness 0
                      }
                      geometry IndexedFaceSet {
                        coord Coordinate {
                          point [
                            0 -0.004 0.0001
                            -0.03 -0.004 0.0001
                            -0.03 -0.004 0.002
                            0 -0.004 0.004
                            0 -0.004 0.0001
                            0 0.004 0.0001
                            -0.03 0.004 0.0001
                            -0.03 0.004 0.002
                            0 0.004 0.004
                            0 0.004 0.0001
                          ]
                        }
                        coordIndex [
                          4, 3, 2, 1, 0, -1, 5, 6, 7, 8, 9, -1, 0, 1, 6, 5, -1, 1, 2, 7, 6, -1, 2, 3, 8, 7, -1, 3, 4, 9, 8, -1
                        ]
                      }
                    }
                  ]
                  name "left grip"
                  contactMaterial "gripper"
                  boundingObject Transform {
                    translation -0.015 0 0.003
                    children [
                      Box {
                        size 0.028 0.007 0.005
                      }
                    ]
                  }
                  physics Physics {
                    density 100
                    centerOfMass [
                      -0.01 0 0
                    ]
                  }
                }
              }
              Shape {
                appearance PBRAppearance {
                  baseColor 0.8 0.8 0.8
                  roughness 1
                  metalness 0
                }
                geometry IndexedFaceSet {
                  coord Coordinate {
                    point [
                      0.035 -0.004 0.006
                      0.035 -0.004 -0.048
                      -0.035 -0.004 -0.048
                      -0.035 -0.004 0.006
                      -0.025 -0.004 0.006
                      -0.025 -0.004 -0.03
                      -0.016 -0.004 -0.04
                      0.016 -0.004 -0.04
                      0.025 -0.004 -0.03
                      0.025 -0.004 0.006
                      0.035 -0.004 0.006
                      0.035 0.004 0.006
                      0.035 0.004 -0.048
                      -0.035 0.004 -0.048
                      -0.035 0.004 0.006
                      -0.025 0.004 0.006
                      -0.025 0.004 -0.03
                      -0.016 0.004 -0.04
                      0.016 0.004 -0.04
                      0.025 0.004 -0.03
                      0.025 0.004 0.006
                      0.035 0.004 0.006
                    ]
                  }
                  coordIndex [
                    10, 9, 8, 7, 6, 5, 4, 3, 2, 1, 0, -1, 11, 12, 13, 14, 15, 16, 17, 18, 19, 20, 21, -1, 0, 1, 12, 11, -1, 1, 2, 13, 12, -1, 2, 3, 14, 13, -1, 3, 4, 15, 14, -1, 4, 5, 16, 15, -1, 5, 6, 17, 16, -1, 6, 7, 18, 17, -1, 7, 8, 19, 18, -1, 8, 9, 20, 19, -1, 9, 10, 21, 20, -1
                  ]
                }
              }
            ]
            boundingObject Transform {
              translation 0 0 -0.021
              children [
                Box {
                  size 0.068 0.008 0.052
                }
              ]
            }
            physics Physics {
              density 100
              centerOfMass [
                0 0 -0.02
              ]
            }
          }
        }
        DEF GRIPPER_BASE Transform {
          translation -0.01 0 0.023
          rotation 0.5773502691896258 -0.5773502691896258 -0.5773502691896258 2.094395
          children [
            Shape {
              appearance PBRAppearance {
                baseColor 0.8 0.8 0.8
                roughness 1
                metalness 0
              }
              geometry Box {
                size 0.05 0.01 0.01
              }
            }
          ]
        }
        Camera {
          translation -0.01 0 0.035
          rotation -0.999759341318827 -0.016153505514822745 -0.014843305067519018 -5.307179586466759e-06
          children [
            Shape {
              appearance PBRAppearance {
                baseColor 0.70632 0.70632 0.70632
                roughness 1
                metalness 0
              }
              geometry DEF CAMERA Box {
                size 0.03 0.03 0.02
              }
            }
          ]
          boundingObject DEF CAMERA Box {
            size 0.03 0.03 0.02
          }
          physics Physics {
            density -1
            mass 0.02
          }
          fieldOfView 0.3
          recognition Recognition {
            maxRange 50
          }
        }
      ]
    }
    Shape {
      appearance PBRAppearance {
        baseColor 0.0539951 0.505576 0.0897663
        roughness 0.4
        metalness 0
      }
      geometry IndexedFaceSet {
        coord Coordinate {
          point [
            0.009 -0.0276 0.0025, 0.0194 -0.0215 0.0025, 0.0265 -0.0118 0.0025, 0.029 0 0.0025, 0.0265 0.0118 0.0025, 0.0194 0.0215 0.0025, 0.009 0.0276 0.0025, 0.009 0.0236 0.02, -0.009 0.0236 0.02, -0.009 -0.0236 0.02, 0.009 -0.0236 0.02, -0.009 0.0276 0.0025, -0.0194 0.0215 0.0025, -0.0265 0.0118 0.0025, -0.029 0 0.0025, -0.0265 -0.0118 0.0025, -0.0194 -0.0215 0.0025, -0.009 -0.0276 0.0025, 0.009 -0.0276 0.001, 0.0194 -0.0215 0.001, 0.0265 -0.0118 0.001, 0.029 0 0.001, 0.0265 0.0118 0.001, 0.0194 0.0215 0.001, 0.009 0.0276 0.001, 0.009 0.0236 0.001, -0.009 0.0236 0.001, -0.009 -0.0236 0.001, 0.009 -0.0236 0.001, -0.009 0.0276 0.001, -0.0194 0.0215 0.001, -0.0265 0.0118 0.001, -0.029 0 0.001, -0.0265 -0.0118 0.001, -0.0194 -0.0215 0.001, -0.009 -0.0276 0.001
          ]
        }
        coordIndex [
          0, 1, 2, 3, 4, 5, 6, -1, 11, 12, 13, 14, 15, 16, 17, -1, 24, 23, 22, 21, 20, 19, 18, -1, 35, 34, 33, 32, 31, 30, 29, -1, 1, 0, 18, 19, -1, 2, 1, 19, 20, -1, 3, 2, 20, 21, -1, 4, 3, 21, 22, -1, 5, 4, 22, 23, -1, 6, 5, 23, 24, -1, 0, 6, 24, 18, -1, 17, 16, 34, 35, -1, 16, 15, 33, 34, -1, 15, 14, 32, 33, -1, 14, 13, 31, 32, -1, 13, 12, 30, 31, -1, 12, 11, 29, 30, -1, 11, 17, 35, 29, -1, 7, 10, 28, 25, -1, 9, 8, 26, 27, -1, 8, 7, 25, 26, -1, 10, 9, 27, 28, -1, 28, 27, 26, 25, -1
        ]
        creaseAngle 0.5
      }
    }
    HingeJoint {
      jointParameters HingeJointParameters {
        axis 0 1 0
        anchor 0 0 0.0075
      }
      device [
        RotationalMotor {
          name "left wheel motor"
        }
        PositionSensor {
          name "left wheel sensor"
          resolution 0.0314
        }
      ]
      endPoint Solid {
        translation 0 0.025999999999999943 0.0075
        rotation -0.6502504768340481 0.650250476834056 -0.3928722880964958 2.3928989999999644
        children [
          DEF WHEEL Transform {
            rotation 0.5773869352700204 -0.5773319352761864 0.5773319352761864 -2.094339
            children [
              Shape {
                appearance PBRAppearance {
                  baseColor 0.778497 0.793743 0.8
                  roughness 0.3
                  metalness 0
                }
                geometry Cylinder {
                  height 0.003
                  radius 0.0075
                }
              }
            ]
          }
        ]
        name "left wheel"
        boundingObject USE WHEEL
        physics Physics {
        }
      }
    }
    HingeJoint {
      jointParameters HingeJointParameters {
        axis 0 1 0
        anchor 0 0 0.0075
      }
      device [
        RotationalMotor {
          name "right wheel motor"
        }
        PositionSensor {
          name "right wheel sensor"
          resolution 0.0314
        }
      ]
      endPoint Solid {
        translation 0 -0.025999999999999693 0.0075
        rotation -0.6434150394574272 0.6434150394574275 -0.4147700254357759 2.3552449999999627
        children [
          USE WHEEL
        ]
        name "right wheel"
        boundingObject USE WHEEL
        physics Physics {
        }
      }
    }
    Transform {
      translation 0 0 0.02
      rotation 0 0 1 -1.570796
      children [
        Shape {
          appearance PBRAppearance {
            baseColor 0.015 0.48 0.1796
            roughness 0.4
            metalness 0
          }
          geometry Cylinder {
            height 0.0015
            radius 0.028
          }
        }
      ]
    }
    DEF LS0 LightSensor {
      translation 0.012 0.0245 0.0144
      rotation 0.6109342596550577 0.5598032379237042 0.5598032379237042 2.044752
      name "ls0"
      lookupTable [
        0 500 0.1
        0.2 10 0.1
      ]
    }
    DEF LS1 LightSensor {
      translation 0.021 0.0185 0.0144
      rotation 0.862854253731822 0.35740910510009427 0.35740910510009427 1.717773
      name "ls1"
      lookupTable [
        0 500 0.1
        0.2 10 0.1
      ]
    }
    DEF LS2 LightSensor {
      translation 0.027 0.0075 0.0144
      rotation -1 0 0 -1.570796
      name "ls2"
      lookupTable [
        0 500 0.1
        0.2 10 0.1
      ]
    }
    DEF LS3 LightSensor {
      translation 0.027 -0.0075 0.0144
      rotation -1 0 0 -1.570796
      name "ls3"
      lookupTable [
        0 500 0.1
        0.2 10 0.1
      ]
    }
    DEF LS4 LightSensor {
      translation 0.021 -0.0185 0.0144
      rotation 0.8628568705192763 -0.357405946367489 -0.357405946367489 1.717771
      name "ls4"
      lookupTable [
        0 500 0.1
        0.2 10 0.1
      ]
    }
    DEF LS5 LightSensor {
      translation 0.012 -0.0245 0.0144
      rotation 0.6109368239350584 -0.5598018386715711 -0.5598018386715711 2.044747
      name "ls5"
      lookupTable [
        0 500 0.1
        0.2 10 0.1
      ]
    }
    DEF LS6 LightSensor {
      translation -0.026 -0.009 0.0144
      rotation 0 -0.7071067811865476 -0.7071067811865476 -3.14159
      name "ls6"
      lookupTable [
        0 500 0.1
        0.2 10 0.1
      ]
    }
    DEF LS7 LightSensor {
      translation -0.026 0.009 0.0144
      rotation 0 -0.7071067811865476 -0.7071067811865476 -3.14159
      name "ls7"
      lookupTable [
        0 500 0.1
        0.2 10 0.1
      ]
    }
    DEF LED0 LED {
      translation 0.022 -0.013 0.021
      rotation 0.5773502691896258 -0.5773502691896258 -0.5773502691896258 2.094395
      children [
        PointLight {
          attenuation 0 0 12.56
          color 1 0 0
          intensity 0.2
          location 0 -0.013 0
          on FALSE
        }
        Shape {
          appearance PBRAppearance {
            baseColor 0.501961 0.501961 0.501961
            metalness 0
            emissiveIntensity 7
          }
          geometry Box {
            size 0.002 0.002 0.002
          }
        }
      ]
      name "led0"
    }
    DEF LED1 LED {
      translation 0.024 -0.01 0.021
      rotation 0.5773502691896258 -0.5773502691896258 -0.5773502691896258 2.094395
      children [
        Shape {
          appearance PBRAppearance {
            baseColor 0.501961 0.501961 0.501961
            metalness 0
          }
          geometry Box {
            size 0.002 0.002 0.002
          }
        }
      ]
      name "led1"
    }
    DEF RS232_OUT Emitter {
      name "rs232_out"
      type "serial"
      range 1000
      baudRate 57600
    }
    DEF RS232_IN Receiver {
      name "rs232_in"
      type "serial"
      baudRate 57600
    }
  ]
  name "k0"
  model "Khepera"
  description "A mini mobile robot by K-Team SA"
  contactMaterial "khepera"
  boundingObject Transform {
    translation 0 0 0.012
    rotation 0 0 1 -1.570796
    children [
      Cylinder {
        height 0.02
        radius 0.0285
      }
    ]
  }
  physics Physics {
    centerOfMass [
      0 0 0.005
    ]
  }
  controller "generalized_ga_controller"
  supervisor TRUE
  synchronization FALSE
}
DEF khepera2 Robot {
  translation 0.184567 0 0.004553
  rotation 0 0 1 2.61799
  children [
    GPS {
    }
    Group {
      children [
        LED {
          scale 3 3 3
        }
        LightSensor {
          scale 3 3 3
          lookupTable [
            0 0 0
            4 1024 0
          ]
        }
        TouchSensor {
        }
        DistanceSensor {
        }
        InertialUnit {
        }
        Receiver {
          channel 1
        }
        Emitter {
          channel 2
        }
        DEF LIFT_HINGE_JOINT HingeJoint {
          jointParameters HingeJointParameters {
            position -1.4
            axis 0 1 0
            anchor -0.01 0 0.022
          }
          device [
            RotationalMotor {
              name "motor"
            }
          ]
          endPoint Solid {
            translation -0.01 0 0.022
            rotation 0.7058148424148372 -0.7058148424148732 -0.060421986509762056 3.020894999999866
            children [
              DEF RIGHT_GRIP SliderJoint {
                jointParameters JointParameters {
                  axis 1 0 0
                }
                device [
                  LinearMotor {
                    name "right grip"
                    maxVelocity 0.1
                    maxPosition 0.029
                    maxForce 100
                  }
                ]
                endPoint Solid {
                  translation 0 0 -0.048
                  rotation 0 1 0 1.5708
                  children [
                    Shape {
                      appearance PBRAppearance {
                        baseColor 0.8 0.8 0.8
                        roughness 1
                        metalness 0
                      }
                      geometry IndexedFaceSet {
                        coord Coordinate {
                          point [
                            0 -0.004 0.004
                            0.03 -0.004 0.002
                            0.03 -0.004 0.0001
                            0 -0.004 0.0001
                            0 -0.004 0.004
                            0 0.004 0.004
                            0.03 0.004 0.002
                            0.03 0.004 0.0001
                            0 0.004 0.0001
                            0 0.004 0.004
                          ]
                        }
                        coordIndex [
                          4, 3, 2, 1, 0, -1, 5, 6, 7, 8, 9, -1, 0, 1, 6, 5, -1, 1, 2, 7, 6, -1, 2, 3, 8, 7, -1, 3, 4, 9, 8, -1
                        ]
                      }
                    }
                    DistanceSensor {
                      translation 0.015 0 0
                      rotation 0 1 0 1.5708
                      name "ds"
                      lookupTable [
                        0 0 0
                        0.05 1000 0
                      ]
                      type "infra-red"
                    }
                  ]
                  name "right grip"
                  contactMaterial "gripper"
                  boundingObject Transform {
                    translation 0.015 0 0.003
                    children [
                      Box {
                        size 0.028 0.007 0.005
                      }
                    ]
                  }
                  physics Physics {
                    density 100
                    centerOfMass [
                      0.01 0 0
                    ]
                  }
                }
              }
              DEF LEFT_GRIP SliderJoint {
                jointParameters JointParameters {
                  axis -1 0 0
                }
                device [
                  LinearMotor {
                    name "left grip"
                    maxVelocity 0.1
                    maxPosition 0.029
                    maxForce 100
                  }
                ]
                endPoint Solid {
                  translation 0 0 -0.048
                  rotation 0 1 0 -1.5708
                  children [
                    Shape {
                      appearance PBRAppearance {
                        baseColor 0.8 0.8 0.8
                        roughness 1
                        metalness 0
                      }
                      geometry IndexedFaceSet {
                        coord Coordinate {
                          point [
                            0 -0.004 0.0001
                            -0.03 -0.004 0.0001
                            -0.03 -0.004 0.002
                            0 -0.004 0.004
                            0 -0.004 0.0001
                            0 0.004 0.0001
                            -0.03 0.004 0.0001
                            -0.03 0.004 0.002
                            0 0.004 0.004
                            0 0.004 0.0001
                          ]
                        }
                        coordIndex [
                          4, 3, 2, 1, 0, -1, 5, 6, 7, 8, 9, -1, 0, 1, 6, 5, -1, 1, 2, 7, 6, -1, 2, 3, 8, 7, -1, 3, 4, 9, 8, -1
                        ]
                      }
                    }
                  ]
                  name "left grip"
                  contactMaterial "gripper"
                  boundingObject Transform {
                    translation -0.015 0 0.003
                    children [
                      Box {
                        size 0.028 0.007 0.005
                      }
                    ]
                  }
                  physics Physics {
                    density 100
                    centerOfMass [
                      -0.01 0 0
                    ]
                  }
                }
              }
              Shape {
                appearance PBRAppearance {
                  baseColor 0.8 0.8 0.8
                  roughness 1
                  metalness 0
                }
                geometry IndexedFaceSet {
                  coord Coordinate {
                    point [
                      0.035 -0.004 0.006
                      0.035 -0.004 -0.048
                      -0.035 -0.004 -0.048
                      -0.035 -0.004 0.006
                      -0.025 -0.004 0.006
                      -0.025 -0.004 -0.03
                      -0.016 -0.004 -0.04
                      0.016 -0.004 -0.04
                      0.025 -0.004 -0.03
                      0.025 -0.004 0.006
                      0.035 -0.004 0.006
                      0.035 0.004 0.006
                      0.035 0.004 -0.048
                      -0.035 0.004 -0.048
                      -0.035 0.004 0.006
                      -0.025 0.004 0.006
                      -0.025 0.004 -0.03
                      -0.016 0.004 -0.04
                      0.016 0.004 -0.04
                      0.025 0.004 -0.03
                      0.025 0.004 0.006
                      0.035 0.004 0.006
                    ]
                  }
                  coordIndex [
                    10, 9, 8, 7, 6, 5, 4, 3, 2, 1, 0, -1, 11, 12, 13, 14, 15, 16, 17, 18, 19, 20, 21, -1, 0, 1, 12, 11, -1, 1, 2, 13, 12, -1, 2, 3, 14, 13, -1, 3, 4, 15, 14, -1, 4, 5, 16, 15, -1, 5, 6, 17, 16, -1, 6, 7, 18, 17, -1, 7, 8, 19, 18, -1, 8, 9, 20, 19, -1, 9, 10, 21, 20, -1
                  ]
                }
              }
            ]
            boundingObject Transform {
              translation 0 0 -0.021
              children [
                Box {
                  size 0.068 0.008 0.052
                }
              ]
            }
            physics Physics {
              density 100
              centerOfMass [
                0 0 -0.02
              ]
            }
          }
        }
        DEF GRIPPER_BASE Transform {
          translation -0.01 0 0.023
          rotation 0.5773502691896258 -0.5773502691896258 -0.5773502691896258 2.094395
          children [
            Shape {
              appearance PBRAppearance {
                baseColor 0.8 0.8 0.8
                roughness 1
                metalness 0
              }
              geometry Box {
                size 0.05 0.01 0.01
              }
            }
          ]
        }
        Camera {
          translation -0.01 0 0.035
          rotation -0.999759341318827 -0.016153505514822745 -0.014843305067519018 -5.307179586466759e-06
          children [
            Shape {
              appearance PBRAppearance {
                baseColor 0.70632 0.70632 0.70632
                roughness 1
                metalness 0
              }
              geometry DEF CAMERA Box {
                size 0.03 0.03 0.02
              }
            }
          ]
          boundingObject DEF CAMERA Box {
            size 0.03 0.03 0.02
          }
          physics Physics {
            density -1
            mass 0.02
          }
          fieldOfView 0.3
          recognition Recognition {
          }
        }
      ]
    }
    Shape {
      appearance PBRAppearance {
        baseColor 0.0539951 0.505576 0.0897663
        roughness 0.4
        metalness 0
      }
      geometry IndexedFaceSet {
        coord Coordinate {
          point [
            0.009 -0.0276 0.0025, 0.0194 -0.0215 0.0025, 0.0265 -0.0118 0.0025, 0.029 0 0.0025, 0.0265 0.0118 0.0025, 0.0194 0.0215 0.0025, 0.009 0.0276 0.0025, 0.009 0.0236 0.02, -0.009 0.0236 0.02, -0.009 -0.0236 0.02, 0.009 -0.0236 0.02, -0.009 0.0276 0.0025, -0.0194 0.0215 0.0025, -0.0265 0.0118 0.0025, -0.029 0 0.0025, -0.0265 -0.0118 0.0025, -0.0194 -0.0215 0.0025, -0.009 -0.0276 0.0025, 0.009 -0.0276 0.001, 0.0194 -0.0215 0.001, 0.0265 -0.0118 0.001, 0.029 0 0.001, 0.0265 0.0118 0.001, 0.0194 0.0215 0.001, 0.009 0.0276 0.001, 0.009 0.0236 0.001, -0.009 0.0236 0.001, -0.009 -0.0236 0.001, 0.009 -0.0236 0.001, -0.009 0.0276 0.001, -0.0194 0.0215 0.001, -0.0265 0.0118 0.001, -0.029 0 0.001, -0.0265 -0.0118 0.001, -0.0194 -0.0215 0.001, -0.009 -0.0276 0.001
          ]
        }
        coordIndex [
          0, 1, 2, 3, 4, 5, 6, -1, 11, 12, 13, 14, 15, 16, 17, -1, 24, 23, 22, 21, 20, 19, 18, -1, 35, 34, 33, 32, 31, 30, 29, -1, 1, 0, 18, 19, -1, 2, 1, 19, 20, -1, 3, 2, 20, 21, -1, 4, 3, 21, 22, -1, 5, 4, 22, 23, -1, 6, 5, 23, 24, -1, 0, 6, 24, 18, -1, 17, 16, 34, 35, -1, 16, 15, 33, 34, -1, 15, 14, 32, 33, -1, 14, 13, 31, 32, -1, 13, 12, 30, 31, -1, 12, 11, 29, 30, -1, 11, 17, 35, 29, -1, 7, 10, 28, 25, -1, 9, 8, 26, 27, -1, 8, 7, 25, 26, -1, 10, 9, 27, 28, -1, 28, 27, 26, 25, -1
        ]
        creaseAngle 0.5
      }
    }
    HingeJoint {
      jointParameters HingeJointParameters {
        axis 0 1 0
        anchor 0 0 0.0075
      }
      device [
        RotationalMotor {
          name "left wheel motor"
        }
        PositionSensor {
          name "left wheel sensor"
          resolution 0.0314
        }
      ]
      endPoint Solid {
        translation 0 0.02600000000000004 0.0075
        rotation -0.6502504768340506 0.6502504768340525 -0.392872288096497 2.3928989999999857
        children [
          DEF WHEEL Transform {
            rotation 0.5773869352700204 -0.5773319352761864 0.5773319352761864 -2.094339
            children [
              Shape {
                appearance PBRAppearance {
                  baseColor 0.778497 0.793743 0.8
                  roughness 0.3
                  metalness 0
                }
                geometry Cylinder {
                  height 0.003
                  radius 0.0075
                }
              }
            ]
          }
        ]
        name "left wheel"
        boundingObject USE WHEEL
        physics Physics {
        }
      }
    }
    HingeJoint {
      jointParameters HingeJointParameters {
        axis 0 1 0
        anchor 0 0 0.0075
      }
      device [
        RotationalMotor {
          name "right wheel motor"
        }
        PositionSensor {
          name "right wheel sensor"
          resolution 0.0314
        }
      ]
      endPoint Solid {
        translation 0 -0.02599999999999982 0.0075
        rotation -0.6434150394574285 0.6434150394574284 -0.4147700254357725 2.3552449999999894
        children [
          USE WHEEL
        ]
        name "right wheel"
        boundingObject USE WHEEL
        physics Physics {
        }
      }
    }
    Transform {
      translation 0 0 0.02
      rotation 0 0 1 -1.570796
      children [
        Shape {
          appearance PBRAppearance {
            baseColor 0.015 0.48 0.1796
            roughness 0.4
            metalness 0
          }
          geometry Cylinder {
            height 0.0015
            radius 0.028
          }
        }
      ]
    }
    DEF LS1 LightSensor {
      translation 0.021 0.0185 0.0144
      rotation 0.862854253731822 0.35740910510009427 0.35740910510009427 1.717773
      name "ls1"
      lookupTable [
        0 500 0.1
        0.2 10 0.1
      ]
    }
    DEF LS2 LightSensor {
      translation 0.027 0.0075 0.0144
      rotation -1 0 0 -1.570796
      name "ls2"
      lookupTable [
        0 500 0.1
        0.2 10 0.1
      ]
    }
    DEF LS3 LightSensor {
      translation 0.027 -0.0075 0.0144
      rotation -1 0 0 -1.570796
      name "ls3"
      lookupTable [
        0 500 0.1
        0.2 10 0.1
      ]
    }
    DEF LS4 LightSensor {
      translation 0.021 -0.0185 0.0144
      rotation 0.8628568705192763 -0.357405946367489 -0.357405946367489 1.717771
      name "ls4"
      lookupTable [
        0 500 0.1
        0.2 10 0.1
      ]
    }
    DEF LS5 LightSensor {
      translation 0.012 -0.0245 0.0144
      rotation 0.6109368239350584 -0.5598018386715711 -0.5598018386715711 2.044747
      name "ls5"
      lookupTable [
        0 500 0.1
        0.2 10 0.1
      ]
    }
    DEF LS6 LightSensor {
      translation -0.026 -0.009 0.0144
      rotation 0 -0.7071067811865476 -0.7071067811865476 -3.14159
      name "ls6"
      lookupTable [
        0 500 0.1
        0.2 10 0.1
      ]
    }
    DEF LS7 LightSensor {
      translation -0.026 0.009 0.0144
      rotation 0 -0.7071067811865476 -0.7071067811865476 -3.14159
      name "ls7"
      lookupTable [
        0 500 0.1
        0.2 10 0.1
      ]
    }
    DEF LED0 LED {
      translation 0.022 -0.003 0.011
      rotation 0.5773502691896258 -0.5773502691896258 -0.5773502691896258 2.094395
      scale 3 3 3
      children [
        PointLight {
          attenuation 0 0 12.56
          color 1 0 0
          intensity 0.25
          location 0 0.3 0
          on FALSE
        }
        Shape {
          appearance PBRAppearance {
            baseColor 0.501961 0.501961 0.501961
            metalness 0
            emissiveColor 1 0.149126 0
          }
          geometry Box {
            size 0.002 0.002 0.002
          }
        }
      ]
      name "led0"
    }
    DEF LED1 LED {
      translation -0.036 -3.72832e-16 0.021
      rotation 0.5773502691896258 -0.5773502691896258 -0.5773502691896258 2.094395
      scale 3 3 3
      children [
        Shape {
          appearance PBRAppearance {
            baseColor 0.501961 0.501961 0.501961
            metalness 0
          }
          geometry Box {
            size 0.002 0.002 0.002
          }
        }
      ]
      name "led1"
    }
    DEF RS232_OUT Emitter {
      name "rs232_out"
      type "serial"
      range 1000
      baudRate 57600
    }
    DEF RS232_IN Receiver {
      name "rs232_in"
      type "serial"
      baudRate 57600
    }
  ]
  name "k1"
  model "Khepera"
  description "A mini mobile robot by K-Team SA"
  contactMaterial "khepera"
  boundingObject Transform {
    translation 0 0 0.012
    rotation 0 0 1 -1.570796
    children [
      Cylinder {
        height 0.02
        radius 0.0285
      }
    ]
  }
  physics Physics {
    centerOfMass [
      0 0 0.005
    ]
  }
  controller "generalized_ga_controller"
  supervisor TRUE
  synchronization FALSE
}
DEF khepera3 Robot {
  translation 0.604567 0 0.004553
  children [
    GPS {
    }
    Group {
      children [
        LED {
        }
        LightSensor {
          lookupTable [
            0 0 0
            4 1024 0
          ]
        }
        TouchSensor {
        }
        DistanceSensor {
        }
        InertialUnit {
        }
        Receiver {
          channel 1
        }
        Emitter {
          channel 2
        }
        DEF LIFT_HINGE_JOINT HingeJoint {
          jointParameters HingeJointParameters {
            position -1.4
            axis 0 1 0
            anchor -0.01 0 0.022
          }
          device [
            RotationalMotor {
              name "motor"
            }
          ]
          endPoint Solid {
            translation -0.01 0 0.022
            rotation 0.7058148424148402 -0.7058148424148706 -0.060421986509761966 3.0208949999998924
            children [
              DEF RIGHT_GRIP SliderJoint {
                jointParameters JointParameters {
                  axis 1 0 0
                }
                device [
                  LinearMotor {
                    name "right grip"
                    maxVelocity 0.1
                    maxPosition 0.029
                    maxForce 100
                  }
                ]
                endPoint Solid {
                  translation 0 0 -0.048
                  rotation 0 1 0 1.5708
                  children [
                    Shape {
                      appearance PBRAppearance {
                        baseColor 0.8 0.8 0.8
                        roughness 1
                        metalness 0
                      }
                      geometry IndexedFaceSet {
                        coord Coordinate {
                          point [
                            0 -0.004 0.004
                            0.03 -0.004 0.002
                            0.03 -0.004 0.0001
                            0 -0.004 0.0001
                            0 -0.004 0.004
                            0 0.004 0.004
                            0.03 0.004 0.002
                            0.03 0.004 0.0001
                            0 0.004 0.0001
                            0 0.004 0.004
                          ]
                        }
                        coordIndex [
                          4, 3, 2, 1, 0, -1, 5, 6, 7, 8, 9, -1, 0, 1, 6, 5, -1, 1, 2, 7, 6, -1, 2, 3, 8, 7, -1, 3, 4, 9, 8, -1
                        ]
                      }
                    }
                    DistanceSensor {
                      translation 0.015 0 0
                      rotation 0 1 0 1.5708
                      name "ds"
                      lookupTable [
                        0 0 0
                        0.05 1000 0
                      ]
                      type "infra-red"
                    }
                  ]
                  name "right grip"
                  contactMaterial "gripper"
                  boundingObject Transform {
                    translation 0.015 0 0.003
                    children [
                      Box {
                        size 0.028 0.007 0.005
                      }
                    ]
                  }
                  physics Physics {
                    density 100
                    centerOfMass [
                      0.01 0 0
                    ]
                  }
                }
              }
              DEF LEFT_GRIP SliderJoint {
                jointParameters JointParameters {
                  axis -1 0 0
                }
                device [
                  LinearMotor {
                    name "left grip"
                    maxVelocity 0.1
                    maxPosition 0.029
                    maxForce 100
                  }
                ]
                endPoint Solid {
                  translation 0 0 -0.048
                  rotation 0 1 0 -1.5708
                  children [
                    Shape {
                      appearance PBRAppearance {
                        baseColor 0.8 0.8 0.8
                        roughness 1
                        metalness 0
                      }
                      geometry IndexedFaceSet {
                        coord Coordinate {
                          point [
                            0 -0.004 0.0001
                            -0.03 -0.004 0.0001
                            -0.03 -0.004 0.002
                            0 -0.004 0.004
                            0 -0.004 0.0001
                            0 0.004 0.0001
                            -0.03 0.004 0.0001
                            -0.03 0.004 0.002
                            0 0.004 0.004
                            0 0.004 0.0001
                          ]
                        }
                        coordIndex [
                          4, 3, 2, 1, 0, -1, 5, 6, 7, 8, 9, -1, 0, 1, 6, 5, -1, 1, 2, 7, 6, -1, 2, 3, 8, 7, -1, 3, 4, 9, 8, -1
                        ]
                      }
                    }
                  ]
                  name "left grip"
                  contactMaterial "gripper"
                  boundingObject Transform {
                    translation -0.015 0 0.003
                    children [
                      Box {
                        size 0.028 0.007 0.005
                      }
                    ]
                  }
                  physics Physics {
                    density 100
                    centerOfMass [
                      -0.01 0 0
                    ]
                  }
                }
              }
              Shape {
                appearance PBRAppearance {
                  baseColor 0.8 0.8 0.8
                  roughness 1
                  metalness 0
                }
                geometry IndexedFaceSet {
                  coord Coordinate {
                    point [
                      0.035 -0.004 0.006
                      0.035 -0.004 -0.048
                      -0.035 -0.004 -0.048
                      -0.035 -0.004 0.006
                      -0.025 -0.004 0.006
                      -0.025 -0.004 -0.03
                      -0.016 -0.004 -0.04
                      0.016 -0.004 -0.04
                      0.025 -0.004 -0.03
                      0.025 -0.004 0.006
                      0.035 -0.004 0.006
                      0.035 0.004 0.006
                      0.035 0.004 -0.048
                      -0.035 0.004 -0.048
                      -0.035 0.004 0.006
                      -0.025 0.004 0.006
                      -0.025 0.004 -0.03
                      -0.016 0.004 -0.04
                      0.016 0.004 -0.04
                      0.025 0.004 -0.03
                      0.025 0.004 0.006
                      0.035 0.004 0.006
                    ]
                  }
                  coordIndex [
                    10, 9, 8, 7, 6, 5, 4, 3, 2, 1, 0, -1, 11, 12, 13, 14, 15, 16, 17, 18, 19, 20, 21, -1, 0, 1, 12, 11, -1, 1, 2, 13, 12, -1, 2, 3, 14, 13, -1, 3, 4, 15, 14, -1, 4, 5, 16, 15, -1, 5, 6, 17, 16, -1, 6, 7, 18, 17, -1, 7, 8, 19, 18, -1, 8, 9, 20, 19, -1, 9, 10, 21, 20, -1
                  ]
                }
              }
            ]
            boundingObject Transform {
              translation 0 0 -0.021
              children [
                Box {
                  size 0.068 0.008 0.052
                }
              ]
            }
            physics Physics {
              density 100
              centerOfMass [
                0 0 -0.02
              ]
            }
          }
        }
        DEF GRIPPER_BASE Transform {
          translation -0.01 0 0.023
          rotation 0.5773502691896258 -0.5773502691896258 -0.5773502691896258 2.094395
          children [
            Shape {
              appearance PBRAppearance {
                baseColor 0.8 0.8 0.8
                roughness 1
                metalness 0
              }
              geometry Box {
                size 0.05 0.01 0.01
              }
            }
          ]
        }
        Camera {
          translation -0.01 0 0.035
          rotation -0.999759341318827 -0.016153505514822745 -0.014843305067519018 -5.307179586466759e-06
          children [
            Shape {
              appearance PBRAppearance {
                baseColor 0.70632 0.70632 0.70632
                roughness 1
                metalness 0
              }
              geometry DEF CAMERA Box {
                size 0.03 0.03 0.02
              }
            }
          ]
          boundingObject DEF CAMERA Box {
            size 0.03 0.03 0.02
          }
          physics Physics {
            density -1
            mass 0.02
          }
          fieldOfView 0.3
          recognition Recognition {
          }
        }
      ]
    }
    Shape {
      appearance PBRAppearance {
        baseColor 0.0539951 0.505576 0.0897663
        roughness 0.4
        metalness 0
      }
      geometry IndexedFaceSet {
        coord Coordinate {
          point [
            0.009 -0.0276 0.0025, 0.0194 -0.0215 0.0025, 0.0265 -0.0118 0.0025, 0.029 0 0.0025, 0.0265 0.0118 0.0025, 0.0194 0.0215 0.0025, 0.009 0.0276 0.0025, 0.009 0.0236 0.02, -0.009 0.0236 0.02, -0.009 -0.0236 0.02, 0.009 -0.0236 0.02, -0.009 0.0276 0.0025, -0.0194 0.0215 0.0025, -0.0265 0.0118 0.0025, -0.029 0 0.0025, -0.0265 -0.0118 0.0025, -0.0194 -0.0215 0.0025, -0.009 -0.0276 0.0025, 0.009 -0.0276 0.001, 0.0194 -0.0215 0.001, 0.0265 -0.0118 0.001, 0.029 0 0.001, 0.0265 0.0118 0.001, 0.0194 0.0215 0.001, 0.009 0.0276 0.001, 0.009 0.0236 0.001, -0.009 0.0236 0.001, -0.009 -0.0236 0.001, 0.009 -0.0236 0.001, -0.009 0.0276 0.001, -0.0194 0.0215 0.001, -0.0265 0.0118 0.001, -0.029 0 0.001, -0.0265 -0.0118 0.001, -0.0194 -0.0215 0.001, -0.009 -0.0276 0.001
          ]
        }
        coordIndex [
          0, 1, 2, 3, 4, 5, 6, -1, 11, 12, 13, 14, 15, 16, 17, -1, 24, 23, 22, 21, 20, 19, 18, -1, 35, 34, 33, 32, 31, 30, 29, -1, 1, 0, 18, 19, -1, 2, 1, 19, 20, -1, 3, 2, 20, 21, -1, 4, 3, 21, 22, -1, 5, 4, 22, 23, -1, 6, 5, 23, 24, -1, 0, 6, 24, 18, -1, 17, 16, 34, 35, -1, 16, 15, 33, 34, -1, 15, 14, 32, 33, -1, 14, 13, 31, 32, -1, 13, 12, 30, 31, -1, 12, 11, 29, 30, -1, 11, 17, 35, 29, -1, 7, 10, 28, 25, -1, 9, 8, 26, 27, -1, 8, 7, 25, 26, -1, 10, 9, 27, 28, -1, 28, 27, 26, 25, -1
        ]
        creaseAngle 0.5
      }
    }
    HingeJoint {
      jointParameters HingeJointParameters {
        axis 0 1 0
        anchor 0 0 0.0075
      }
      device [
        RotationalMotor {
          name "left wheel motor"
        }
        PositionSensor {
          name "left wheel sensor"
          resolution 0.0314
        }
      ]
      endPoint Solid {
        translation 0 0.026 0.0075
        rotation -0.6502504768340517 0.6502504768340517 -0.3928722880964969 2.392899
        children [
          DEF WHEEL Transform {
            rotation 0.5773869352700204 -0.5773319352761864 0.5773319352761864 -2.094339
            children [
              Shape {
                appearance PBRAppearance {
                  baseColor 0.778497 0.793743 0.8
                  roughness 0.3
                  metalness 0
                }
                geometry Cylinder {
                  height 0.003
                  radius 0.0075
                }
              }
            ]
          }
        ]
        name "left wheel"
        boundingObject USE WHEEL
        physics Physics {
        }
      }
    }
    HingeJoint {
      jointParameters HingeJointParameters {
        axis 0 1 0
        anchor 0 0 0.0075
      }
      device [
        RotationalMotor {
          name "right wheel motor"
        }
        PositionSensor {
          name "right wheel sensor"
          resolution 0.0314
        }
      ]
      endPoint Solid {
        translation 0 -0.026 0.0075
        rotation -0.6434150394574285 0.6434150394574285 -0.4147700254357724 2.355245
        children [
          USE WHEEL
        ]
        name "right wheel"
        boundingObject USE WHEEL
        physics Physics {
        }
      }
    }
    Transform {
      translation 0 0 0.02
      rotation 0 0 1 -1.570796
      children [
        Shape {
          appearance PBRAppearance {
            baseColor 0.015 0.48 0.1796
            roughness 0.4
            metalness 0
          }
          geometry Cylinder {
            height 0.0015
            radius 0.028
          }
        }
      ]
    }
    DEF LS0 LightSensor {
      translation 0.012 0.0245 0.0144
      rotation 0.6109342596550577 0.5598032379237042 0.5598032379237042 2.044752
      name "ls0"
      lookupTable [
        0 500 0.1
        0.2 10 0.1
      ]
    }
    DEF LS1 LightSensor {
      translation 0.021 0.0185 0.0144
      rotation 0.862854253731822 0.35740910510009427 0.35740910510009427 1.717773
      name "ls1"
      lookupTable [
        0 500 0.1
        0.2 10 0.1
      ]
    }
    DEF LS2 LightSensor {
      translation 0.027 0.0075 0.0144
      rotation -1 0 0 -1.570796
      name "ls2"
      lookupTable [
        0 500 0.1
        0.2 10 0.1
      ]
    }
    DEF LS3 LightSensor {
      translation 0.027 -0.0075 0.0144
      rotation -1 0 0 -1.570796
      name "ls3"
      lookupTable [
        0 500 0.1
        0.2 10 0.1
      ]
    }
    DEF LS4 LightSensor {
      translation 0.021 -0.0185 0.0144
      rotation 0.8628568705192763 -0.357405946367489 -0.357405946367489 1.717771
      name "ls4"
      lookupTable [
        0 500 0.1
        0.2 10 0.1
      ]
    }
    DEF LS5 LightSensor {
      translation 0.012 -0.0245 0.0144
      rotation 0.6109368239350584 -0.5598018386715711 -0.5598018386715711 2.044747
      name "ls5"
      lookupTable [
        0 500 0.1
        0.2 10 0.1
      ]
    }
    DEF LS6 LightSensor {
      translation -0.026 -0.009 0.0144
      rotation 0 -0.7071067811865476 -0.7071067811865476 -3.14159
      name "ls6"
      lookupTable [
        0 500 0.1
        0.2 10 0.1
      ]
    }
    DEF LS7 LightSensor {
      translation -0.026 0.009 0.0144
      rotation 0 -0.7071067811865476 -0.7071067811865476 -3.14159
      name "ls7"
      lookupTable [
        0 500 0.1
        0.2 10 0.1
      ]
    }
    DEF LED0 LED {
      translation 0.022 -0.013 0.021
      rotation 0.5773502691896258 -0.5773502691896258 -0.5773502691896258 2.094395
      children [
        PointLight {
          attenuation 0 0 12.56
          color 1 0 0
          intensity 0.25
          location 0 0.3 0
          on FALSE
        }
        Shape {
          appearance PBRAppearance {
            baseColor 0.501961 0.501961 0.501961
            metalness 0
          }
          geometry Box {
            size 0.002 0.002 0.002
          }
        }
      ]
      name "led0"
    }
    DEF LED1 LED {
      translation 0.024 -0.01 0.021
      rotation 0.5773502691896258 -0.5773502691896258 -0.5773502691896258 2.094395
      children [
        Shape {
          appearance PBRAppearance {
            baseColor 0.501961 0.501961 0.501961
            metalness 0
          }
          geometry Box {
            size 0.002 0.002 0.002
          }
        }
      ]
      name "led1"
    }
    DEF RS232_OUT Emitter {
      name "rs232_out"
      type "serial"
      range 1000
      baudRate 57600
    }
    DEF RS232_IN Receiver {
      name "rs232_in"
      type "serial"
      baudRate 57600
    }
  ]
  name "k2"
  model "Khepera"
  description "A mini mobile robot by K-Team SA"
  contactMaterial "khepera"
  boundingObject Transform {
    translation 0 0 0.012
    rotation 0 0 1 -1.570796
    children [
      Cylinder {
        height 0.02
        radius 0.0285
      }
    ]
  }
  physics Physics {
    centerOfMass [
      0 0 0.005
    ]
  }
  controller "generalized_ga_controller"
  supervisor TRUE
  synchronization FALSE
}
