#VRML_SIM R2022a utf8
WorldInfo {
  info [
    "A Khepera robot equipped with a gripper"
  ]
  title "Khepera Gripper"
  CFM 0.001
  ERP 0.4
  basicTimeStep 10
  contactProperties [
    ContactProperties {
      material1 "gripper"
      material2 "stick"
      coulombFriction [
        10
      ]
      bounceVelocity 0.5
    }
    ContactProperties {
      material1 "khepera"
      coulombFriction [
        0.1
      ]
    }
  ]
}
Viewpoint {
  orientation 0.22176965906190546 -0.09996005208569032 -0.9699619612678593 3.965895256088618
  position 2.0654341073142395 -2.232675826238217 1.5450649935952425
}
TexturedBackground {
}
TexturedBackgroundLight {
}
RectangleArena {
  translation -0.04 -0.07 0
  floorSize 2 2
}
DEF supervisor TinkerbotsBase {
  translation -0.2 0 0
  controller "ga_supervisor"
  supervisor TRUE
  extensionSlot [
    Receiver {
      channel 2
    }
    Emitter {
      channel 1
    }
  ]
}
DEF r1 Solid {
  translation 0.32 -0.67 0.0199994
  rotation 0 1 0 4.6928e-06
  children [
    DEF STICK_SHAPE Shape {
      appearance PBRAppearance {
        baseColor 1 0.155604 0.246125
        roughness 0.783569247
        metalness 0
      }
      geometry Cylinder {
        height 0.06
        radius 0.008
      }
    }
  ]
  name "red stick"
  model "red-rod-1"
  contactMaterial "stick"
  boundingObject Box {
    size 0.013 0.013 0.06
  }
  physics Physics {
    density 100
  }
  recognitionColors [
    0.8 0 0
  ]
}
DEF r9 Solid {
  translation 0.58 -0.67 0.0199989
  rotation 0 1 0 4.6928e-06
  children [
    DEF STICK_SHAPE Shape {
      appearance PBRAppearance {
        baseColor 1 0.155604 0.246125
        roughness 0.783569247
        metalness 0
      }
      geometry Cylinder {
        height 0.06
        radius 0.008
      }
    }
  ]
  name "red stick(2)"
  model "red-rod-1"
  contactMaterial "stick"
  boundingObject Box {
    size 0.013 0.013 0.06
  }
  physics Physics {
    density 100
  }
  recognitionColors [
    0.8 0 0
  ]
}
DEF r2 Solid {
  translation 0.07 -0.42 0.019999
  rotation 0 1 0 4.6928e-06
  children [
    DEF STICK_SHAPE Shape {
      appearance PBRAppearance {
        baseColor 1 0.155604 0.246125
        roughness 0.783569247
        metalness 0
      }
      geometry Cylinder {
        height 0.06
        radius 0.008
      }
    }
  ]
  name "red stick(1)"
  model "red-rod-1"
  contactMaterial "stick"
  boundingObject Box {
    size 0.013 0.013 0.06
  }
  physics Physics {
    density 100
  }
  recognitionColors [
    0.8 0 0
  ]
}
DEF r4 Solid {
  translation 0.59 -0.43 0.0199991
  rotation 0 1 0 4.6928e-06
  children [
    DEF STICK_SHAPE Shape {
      appearance PBRAppearance {
        baseColor 1 0.155604 0.246125
        roughness 0.783569247
        metalness 0
      }
      geometry Cylinder {
        height 0.06
        radius 0.008
      }
    }
  ]
  name "red stick(3)"
  model "red-rod-1"
  contactMaterial "stick"
  boundingObject Box {
    size 0.013 0.013 0.06
  }
  physics Physics {
    density 100
  }
  recognitionColors [
    0.8 0 0
  ]
}
DEF r5 Solid {
  translation -0.19 -0.43 0.0199996
  rotation 0 1 0 4.6928e-06
  children [
    DEF STICK_SHAPE Shape {
      appearance PBRAppearance {
        baseColor 1 0.155604 0.246125
        roughness 0.783569247
        metalness 0
      }
      geometry Cylinder {
        height 0.06
        radius 0.008
      }
    }
  ]
  name "red stick(4)"
  model "red-rod-1"
  contactMaterial "stick"
  boundingObject Box {
    size 0.013 0.013 0.06
  }
  physics Physics {
    density 100
  }
  recognitionColors [
    0.8 0 0
  ]
}
DEF r6 Solid {
  translation 0.06 -0.66 0.019999
  rotation 0 1 0 4.6928e-06
  children [
    DEF STICK_SHAPE Shape {
      appearance PBRAppearance {
        baseColor 1 0.155604 0.246125
        roughness 0.783569247
        metalness 0
      }
      geometry Cylinder {
        height 0.06
        radius 0.008
      }
    }
  ]
  name "red stick(5)"
  model "red-rod-1"
  contactMaterial "stick"
  boundingObject Box {
    size 0.013 0.013 0.06
  }
  physics Physics {
    density 100
  }
  recognitionColors [
    0.8 0 0
  ]
}
DEF r7 Solid {
  translation -0.17 -0.68 0.0200005
  rotation 0 1 0 4.6928e-06
  children [
    DEF STICK_SHAPE Shape {
      appearance PBRAppearance {
        baseColor 1 0.155604 0.246125
        roughness 0.783569247
        metalness 0
      }
      geometry Cylinder {
        height 0.06
        radius 0.008
      }
    }
  ]
  name "red stick(6)"
  model "red-rod-1"
  contactMaterial "stick"
  boundingObject Box {
    size 0.013 0.013 0.06
  }
  physics Physics {
    density 100
  }
  recognitionColors [
    0.8 0 0
  ]
}
DEF r8 Solid {
  translation 0.31 -0.41 0.0199972
  rotation 0 1 0 4.6928e-06
  children [
    DEF STICK_SHAPE Shape {
      appearance PBRAppearance {
        baseColor 1 0.155604 0.246125
        roughness 0.783569247
        metalness 0
      }
      geometry Cylinder {
        height 0.06
        radius 0.008
      }
    }
  ]
  name "red stick(7)"
  model "red-rod-1"
  contactMaterial "stick"
  boundingObject Box {
    size 0.013 0.013 0.06
  }
  physics Physics {
    density 100
  }
  recognitionColors [
    0.8 0 0
  ]
}
DEF khepera Khepera1 {
  translation 0.0245671 0 0.0045528
  name "khepera camera"
  controller "khepera_gripper"
  supervisor TRUE
  extensionSlot [
    TouchSensor {
    }
    GPS {
    }
    DistanceSensor {
    }
    InertialUnit {
    }
    Receiver {
      channel 1
    }
    Emitter {
      channel 2
    }
    DEF LIFT_HINGE_JOINT HingeJoint {
      jointParameters HingeJointParameters {
        position -1.4
        axis 0 1 0
        anchor -0.01 0 0.022
      }
      device [
        RotationalMotor {
          name "motor"
        }
      ]
      endPoint Solid {
        translation -0.01 0 0.022
        rotation 0.7058148424148399 -0.7058148424148707 -0.060421986509761896 3.0208949999998924
        children [
          DEF RIGHT_GRIP SliderJoint {
            jointParameters JointParameters {
              axis 1 0 0
            }
            device [
              LinearMotor {
                name "right grip"
                maxVelocity 0.1
                maxPosition 0.029
                maxForce 100
              }
            ]
            endPoint Solid {
              translation 0 0 -0.048
              rotation 0 1 0 1.5708
              children [
                Shape {
                  appearance PBRAppearance {
                    baseColor 0.8 0.8 0.8
                    roughness 1
                    metalness 0
                  }
                  geometry IndexedFaceSet {
                    coord Coordinate {
                      point [
                        0 -0.004 0.004
                        0.03 -0.004 0.002
                        0.03 -0.004 0.0001
                        0 -0.004 0.0001
                        0 -0.004 0.004
                        0 0.004 0.004
                        0.03 0.004 0.002
                        0.03 0.004 0.0001
                        0 0.004 0.0001
                        0 0.004 0.004
                      ]
                    }
                    coordIndex [
                      4, 3, 2, 1, 0, -1, 5, 6, 7, 8, 9, -1, 0, 1, 6, 5, -1, 1, 2, 7, 6, -1, 2, 3, 8, 7, -1, 3, 4, 9, 8, -1
                    ]
                  }
                }
                DistanceSensor {
                  translation 0.015 0 0
                  rotation 0 1 0 1.5708
                  name "ds"
                  lookupTable [
                    0 0 0
                    0.05 1000 0
                  ]
                  type "infra-red"
                }
              ]
              name "right grip"
              contactMaterial "gripper"
              boundingObject Transform {
                translation 0.015 0 0.003
                children [
                  Box {
                    size 0.028 0.007 0.005
                  }
                ]
              }
              physics Physics {
                density 100
                centerOfMass [
                  0.01 0 0
                ]
              }
            }
          }
          DEF LEFT_GRIP SliderJoint {
            jointParameters JointParameters {
              axis -1 0 0
            }
            device [
              LinearMotor {
                name "left grip"
                maxVelocity 0.1
                maxPosition 0.029
                maxForce 100
              }
            ]
            endPoint Solid {
              translation 0 0 -0.048
              rotation 0 1 0 -1.5708
              children [
                Shape {
                  appearance PBRAppearance {
                    baseColor 0.8 0.8 0.8
                    roughness 1
                    metalness 0
                  }
                  geometry IndexedFaceSet {
                    coord Coordinate {
                      point [
                        0 -0.004 0.0001
                        -0.03 -0.004 0.0001
                        -0.03 -0.004 0.002
                        0 -0.004 0.004
                        0 -0.004 0.0001
                        0 0.004 0.0001
                        -0.03 0.004 0.0001
                        -0.03 0.004 0.002
                        0 0.004 0.004
                        0 0.004 0.0001
                      ]
                    }
                    coordIndex [
                      4, 3, 2, 1, 0, -1, 5, 6, 7, 8, 9, -1, 0, 1, 6, 5, -1, 1, 2, 7, 6, -1, 2, 3, 8, 7, -1, 3, 4, 9, 8, -1
                    ]
                  }
                }
              ]
              name "left grip"
              contactMaterial "gripper"
              boundingObject Transform {
                translation -0.015 0 0.003
                children [
                  Box {
                    size 0.028 0.007 0.005
                  }
                ]
              }
              physics Physics {
                density 100
                centerOfMass [
                  -0.01 0 0
                ]
              }
            }
          }
          Shape {
            appearance PBRAppearance {
              baseColor 0.8 0.8 0.8
              roughness 1
              metalness 0
            }
            geometry IndexedFaceSet {
              coord Coordinate {
                point [
                  0.035 -0.004 0.006
                  0.035 -0.004 -0.048
                  -0.035 -0.004 -0.048
                  -0.035 -0.004 0.006
                  -0.025 -0.004 0.006
                  -0.025 -0.004 -0.03
                  -0.016 -0.004 -0.04
                  0.016 -0.004 -0.04
                  0.025 -0.004 -0.03
                  0.025 -0.004 0.006
                  0.035 -0.004 0.006
                  0.035 0.004 0.006
                  0.035 0.004 -0.048
                  -0.035 0.004 -0.048
                  -0.035 0.004 0.006
                  -0.025 0.004 0.006
                  -0.025 0.004 -0.03
                  -0.016 0.004 -0.04
                  0.016 0.004 -0.04
                  0.025 0.004 -0.03
                  0.025 0.004 0.006
                  0.035 0.004 0.006
                ]
              }
              coordIndex [
                10, 9, 8, 7, 6, 5, 4, 3, 2, 1, 0, -1, 11, 12, 13, 14, 15, 16, 17, 18, 19, 20, 21, -1, 0, 1, 12, 11, -1, 1, 2, 13, 12, -1, 2, 3, 14, 13, -1, 3, 4, 15, 14, -1, 4, 5, 16, 15, -1, 5, 6, 17, 16, -1, 6, 7, 18, 17, -1, 7, 8, 19, 18, -1, 8, 9, 20, 19, -1, 9, 10, 21, 20, -1
              ]
            }
          }
        ]
        boundingObject Transform {
          translation 0 0 -0.021
          children [
            Box {
              size 0.068 0.008 0.052
            }
          ]
        }
        physics Physics {
          density 100
          centerOfMass [
            0 0 -0.02
          ]
        }
      }
    }
    DEF GRIPPER_BASE Transform {
      translation -0.01 0 0.023
      rotation 0.5773502691896258 -0.5773502691896258 -0.5773502691896258 2.094395
      children [
        Shape {
          appearance PBRAppearance {
            baseColor 0.8 0.8 0.8
            roughness 1
            metalness 0
          }
          geometry Box {
            size 0.05 0.01 0.01
          }
        }
      ]
    }
    Camera {
      translation -0.01 0 0.035
      rotation -0.999759341318827 -0.016153505514822745 -0.014843305067519018 -5.307179586466759e-06
      children [
        Shape {
          appearance PBRAppearance {
            baseColor 0.70632 0.70632 0.70632
            roughness 1
            metalness 0
          }
          geometry DEF CAMERA Box {
            size 0.03 0.03 0.02
          }
        }
      ]
      boundingObject DEF CAMERA Box {
        size 0.03 0.03 0.02
      }
      physics Physics {
        density -1
        mass 0.02
      }
      recognition Recognition {
        maxRange 30
      }
    }
  ]
}
DEF khepera2 Khepera1 {
  translation 0.314567 0 0.004553
  name "khepera camera(1)"
  controller "khepera_gripper_2"
  supervisor TRUE
  extensionSlot [
    TouchSensor {
    }
    DistanceSensor {
    }
    InertialUnit {
    }
    Receiver {
      channel 1
    }
    Emitter {
      channel 2
    }
    DEF LIFT_HINGE_JOINT HingeJoint {
      jointParameters HingeJointParameters {
        position -1.4
        axis 0 1 0
        anchor -0.01 0 0.022
      }
      device [
        RotationalMotor {
          name "motor"
        }
      ]
      endPoint Solid {
        translation -0.01 0 0.022
        rotation 0.7058148424148399 -0.7058148424148707 -0.060421986509761896 3.0208949999998924
        children [
          DEF RIGHT_GRIP SliderJoint {
            jointParameters JointParameters {
              axis 1 0 0
            }
            device [
              LinearMotor {
                name "right grip"
                maxVelocity 0.1
                maxPosition 0.029
                maxForce 100
              }
            ]
            endPoint Solid {
              translation 0 0 -0.048
              rotation 0 1 0 1.5708
              children [
                Shape {
                  appearance PBRAppearance {
                    baseColor 0.8 0.8 0.8
                    roughness 1
                    metalness 0
                  }
                  geometry IndexedFaceSet {
                    coord Coordinate {
                      point [
                        0 -0.004 0.004
                        0.03 -0.004 0.002
                        0.03 -0.004 0.0001
                        0 -0.004 0.0001
                        0 -0.004 0.004
                        0 0.004 0.004
                        0.03 0.004 0.002
                        0.03 0.004 0.0001
                        0 0.004 0.0001
                        0 0.004 0.004
                      ]
                    }
                    coordIndex [
                      4, 3, 2, 1, 0, -1, 5, 6, 7, 8, 9, -1, 0, 1, 6, 5, -1, 1, 2, 7, 6, -1, 2, 3, 8, 7, -1, 3, 4, 9, 8, -1
                    ]
                  }
                }
                DistanceSensor {
                  translation 0.015 0 0
                  rotation 0 1 0 1.5708
                  name "ds"
                  lookupTable [
                    0 0 0
                    0.05 1000 0
                  ]
                  type "infra-red"
                }
              ]
              name "right grip"
              contactMaterial "gripper"
              boundingObject Transform {
                translation 0.015 0 0.003
                children [
                  Box {
                    size 0.028 0.007 0.005
                  }
                ]
              }
              physics Physics {
                density 100
                centerOfMass [
                  0.01 0 0
                ]
              }
            }
          }
          DEF LEFT_GRIP SliderJoint {
            jointParameters JointParameters {
              axis -1 0 0
            }
            device [
              LinearMotor {
                name "left grip"
                maxVelocity 0.1
                maxPosition 0.029
                maxForce 100
              }
            ]
            endPoint Solid {
              translation 0 0 -0.048
              rotation 0 1 0 -1.5708
              children [
                Shape {
                  appearance PBRAppearance {
                    baseColor 0.8 0.8 0.8
                    roughness 1
                    metalness 0
                  }
                  geometry IndexedFaceSet {
                    coord Coordinate {
                      point [
                        0 -0.004 0.0001
                        -0.03 -0.004 0.0001
                        -0.03 -0.004 0.002
                        0 -0.004 0.004
                        0 -0.004 0.0001
                        0 0.004 0.0001
                        -0.03 0.004 0.0001
                        -0.03 0.004 0.002
                        0 0.004 0.004
                        0 0.004 0.0001
                      ]
                    }
                    coordIndex [
                      4, 3, 2, 1, 0, -1, 5, 6, 7, 8, 9, -1, 0, 1, 6, 5, -1, 1, 2, 7, 6, -1, 2, 3, 8, 7, -1, 3, 4, 9, 8, -1
                    ]
                  }
                }
              ]
              name "left grip"
              contactMaterial "gripper"
              boundingObject Transform {
                translation -0.015 0 0.003
                children [
                  Box {
                    size 0.028 0.007 0.005
                  }
                ]
              }
              physics Physics {
                density 100
                centerOfMass [
                  -0.01 0 0
                ]
              }
            }
          }
          Shape {
            appearance PBRAppearance {
              baseColor 0.8 0.8 0.8
              roughness 1
              metalness 0
            }
            geometry IndexedFaceSet {
              coord Coordinate {
                point [
                  0.035 -0.004 0.006
                  0.035 -0.004 -0.048
                  -0.035 -0.004 -0.048
                  -0.035 -0.004 0.006
                  -0.025 -0.004 0.006
                  -0.025 -0.004 -0.03
                  -0.016 -0.004 -0.04
                  0.016 -0.004 -0.04
                  0.025 -0.004 -0.03
                  0.025 -0.004 0.006
                  0.035 -0.004 0.006
                  0.035 0.004 0.006
                  0.035 0.004 -0.048
                  -0.035 0.004 -0.048
                  -0.035 0.004 0.006
                  -0.025 0.004 0.006
                  -0.025 0.004 -0.03
                  -0.016 0.004 -0.04
                  0.016 0.004 -0.04
                  0.025 0.004 -0.03
                  0.025 0.004 0.006
                  0.035 0.004 0.006
                ]
              }
              coordIndex [
                10, 9, 8, 7, 6, 5, 4, 3, 2, 1, 0, -1, 11, 12, 13, 14, 15, 16, 17, 18, 19, 20, 21, -1, 0, 1, 12, 11, -1, 1, 2, 13, 12, -1, 2, 3, 14, 13, -1, 3, 4, 15, 14, -1, 4, 5, 16, 15, -1, 5, 6, 17, 16, -1, 6, 7, 18, 17, -1, 7, 8, 19, 18, -1, 8, 9, 20, 19, -1, 9, 10, 21, 20, -1
              ]
            }
          }
        ]
        boundingObject Transform {
          translation 0 0 -0.021
          children [
            Box {
              size 0.068 0.008 0.052
            }
          ]
        }
        physics Physics {
          density 100
          centerOfMass [
            0 0 -0.02
          ]
        }
      }
    }
    DEF GRIPPER_BASE Transform {
      translation -0.01 0 0.023
      rotation 0.5773502691896258 -0.5773502691896258 -0.5773502691896258 2.094395
      children [
        Shape {
          appearance PBRAppearance {
            baseColor 0.8 0.8 0.8
            roughness 1
            metalness 0
          }
          geometry Box {
            size 0.05 0.01 0.01
          }
        }
      ]
    }
    Camera {
      translation -0.01 0 0.035
      rotation -0.999759341318827 -0.016153505514822745 -0.014843305067519018 -5.307179586466759e-06
      children [
        Shape {
          appearance PBRAppearance {
            baseColor 0.70632 0.70632 0.70632
            roughness 1
            metalness 0
          }
          geometry DEF CAMERA Box {
            size 0.03 0.03 0.02
          }
        }
      ]
      boundingObject DEF CAMERA Box {
        size 0.03 0.03 0.02
      }
      physics Physics {
        density -1
        mass 0.02
      }
      recognition Recognition {
      }
    }
  ]
}
DEF khepera3 Khepera1 {
  translation 0.574567 0 0.004553
  name "khepera camera(2)"
  controller "khepera_gripper_3"
  supervisor TRUE
  extensionSlot [
    TouchSensor {
    }
    DistanceSensor {
    }
    InertialUnit {
    }
    Receiver {
      channel 1
    }
    Emitter {
      channel 2
    }
    DEF LIFT_HINGE_JOINT HingeJoint {
      jointParameters HingeJointParameters {
        position -1.4
        axis 0 1 0
        anchor -0.01 0 0.022
      }
      device [
        RotationalMotor {
          name "motor"
        }
      ]
      endPoint Solid {
        translation -0.01 0 0.022
        rotation 0.7058148424148402 -0.7058148424148706 -0.060421986509761966 3.0208949999998924
        children [
          DEF RIGHT_GRIP SliderJoint {
            jointParameters JointParameters {
              axis 1 0 0
            }
            device [
              LinearMotor {
                name "right grip"
                maxVelocity 0.1
                maxPosition 0.029
                maxForce 100
              }
            ]
            endPoint Solid {
              translation 0 0 -0.048
              rotation 0 1 0 1.5708
              children [
                Shape {
                  appearance PBRAppearance {
                    baseColor 0.8 0.8 0.8
                    roughness 1
                    metalness 0
                  }
                  geometry IndexedFaceSet {
                    coord Coordinate {
                      point [
                        0 -0.004 0.004
                        0.03 -0.004 0.002
                        0.03 -0.004 0.0001
                        0 -0.004 0.0001
                        0 -0.004 0.004
                        0 0.004 0.004
                        0.03 0.004 0.002
                        0.03 0.004 0.0001
                        0 0.004 0.0001
                        0 0.004 0.004
                      ]
                    }
                    coordIndex [
                      4, 3, 2, 1, 0, -1, 5, 6, 7, 8, 9, -1, 0, 1, 6, 5, -1, 1, 2, 7, 6, -1, 2, 3, 8, 7, -1, 3, 4, 9, 8, -1
                    ]
                  }
                }
                DistanceSensor {
                  translation 0.015 0 0
                  rotation 0 1 0 1.5708
                  name "ds"
                  lookupTable [
                    0 0 0
                    0.05 1000 0
                  ]
                  type "infra-red"
                }
              ]
              name "right grip"
              contactMaterial "gripper"
              boundingObject Transform {
                translation 0.015 0 0.003
                children [
                  Box {
                    size 0.028 0.007 0.005
                  }
                ]
              }
              physics Physics {
                density 100
                centerOfMass [
                  0.01 0 0
                ]
              }
            }
          }
          DEF LEFT_GRIP SliderJoint {
            jointParameters JointParameters {
              axis -1 0 0
            }
            device [
              LinearMotor {
                name "left grip"
                maxVelocity 0.1
                maxPosition 0.029
                maxForce 100
              }
            ]
            endPoint Solid {
              translation 0 0 -0.048
              rotation 0 1 0 -1.5708
              children [
                Shape {
                  appearance PBRAppearance {
                    baseColor 0.8 0.8 0.8
                    roughness 1
                    metalness 0
                  }
                  geometry IndexedFaceSet {
                    coord Coordinate {
                      point [
                        0 -0.004 0.0001
                        -0.03 -0.004 0.0001
                        -0.03 -0.004 0.002
                        0 -0.004 0.004
                        0 -0.004 0.0001
                        0 0.004 0.0001
                        -0.03 0.004 0.0001
                        -0.03 0.004 0.002
                        0 0.004 0.004
                        0 0.004 0.0001
                      ]
                    }
                    coordIndex [
                      4, 3, 2, 1, 0, -1, 5, 6, 7, 8, 9, -1, 0, 1, 6, 5, -1, 1, 2, 7, 6, -1, 2, 3, 8, 7, -1, 3, 4, 9, 8, -1
                    ]
                  }
                }
              ]
              name "left grip"
              contactMaterial "gripper"
              boundingObject Transform {
                translation -0.015 0 0.003
                children [
                  Box {
                    size 0.028 0.007 0.005
                  }
                ]
              }
              physics Physics {
                density 100
                centerOfMass [
                  -0.01 0 0
                ]
              }
            }
          }
          Shape {
            appearance PBRAppearance {
              baseColor 0.8 0.8 0.8
              roughness 1
              metalness 0
            }
            geometry IndexedFaceSet {
              coord Coordinate {
                point [
                  0.035 -0.004 0.006
                  0.035 -0.004 -0.048
                  -0.035 -0.004 -0.048
                  -0.035 -0.004 0.006
                  -0.025 -0.004 0.006
                  -0.025 -0.004 -0.03
                  -0.016 -0.004 -0.04
                  0.016 -0.004 -0.04
                  0.025 -0.004 -0.03
                  0.025 -0.004 0.006
                  0.035 -0.004 0.006
                  0.035 0.004 0.006
                  0.035 0.004 -0.048
                  -0.035 0.004 -0.048
                  -0.035 0.004 0.006
                  -0.025 0.004 0.006
                  -0.025 0.004 -0.03
                  -0.016 0.004 -0.04
                  0.016 0.004 -0.04
                  0.025 0.004 -0.03
                  0.025 0.004 0.006
                  0.035 0.004 0.006
                ]
              }
              coordIndex [
                10, 9, 8, 7, 6, 5, 4, 3, 2, 1, 0, -1, 11, 12, 13, 14, 15, 16, 17, 18, 19, 20, 21, -1, 0, 1, 12, 11, -1, 1, 2, 13, 12, -1, 2, 3, 14, 13, -1, 3, 4, 15, 14, -1, 4, 5, 16, 15, -1, 5, 6, 17, 16, -1, 6, 7, 18, 17, -1, 7, 8, 19, 18, -1, 8, 9, 20, 19, -1, 9, 10, 21, 20, -1
              ]
            }
          }
        ]
        boundingObject Transform {
          translation 0 0 -0.021
          children [
            Box {
              size 0.068 0.008 0.052
            }
          ]
        }
        physics Physics {
          density 100
          centerOfMass [
            0 0 -0.02
          ]
        }
      }
    }
    DEF GRIPPER_BASE Transform {
      translation -0.01 0 0.023
      rotation 0.5773502691896258 -0.5773502691896258 -0.5773502691896258 2.094395
      children [
        Shape {
          appearance PBRAppearance {
            baseColor 0.8 0.8 0.8
            roughness 1
            metalness 0
          }
          geometry Box {
            size 0.05 0.01 0.01
          }
        }
      ]
    }
    Camera {
      translation -0.01 0 0.035
      rotation -0.999759341318827 -0.016153505514822745 -0.014843305067519018 -5.307179586466759e-06
      children [
        Shape {
          appearance PBRAppearance {
            baseColor 0.70632 0.70632 0.70632
            roughness 1
            metalness 0
          }
          geometry DEF CAMERA Box {
            size 0.03 0.03 0.02
          }
        }
      ]
      boundingObject DEF CAMERA Box {
        size 0.03 0.03 0.02
      }
      physics Physics {
        density -1
        mass 0.02
      }
      recognition Recognition {
      }
    }
  ]
}
