#VRML_SIM R2022a utf8
WorldInfo {
  info [
    "A Khepera robot equipped with a gripper"
  ]
  title "Khepera Gripper"
  CFM 0.001
  ERP 0.4
  basicTimeStep 10
  FPS 30
  optimalThreadCount 3
  contactProperties [
    ContactProperties {
      material1 "gripper"
      material2 "stick"
      coulombFriction [
        10
      ]
      bounceVelocity 0.5
    }
    ContactProperties {
      material1 "khepera"
      coulombFriction [
        0.1
      ]
    }
  ]
}
Viewpoint {
  orientation -0.3296101342397867 -0.21360342327655985 0.919636198162602 4.216501828849145
  position 1.2721863854100195 2.8292946193685 2.5821889024503832
}
TexturedBackground {
  luminosity 0.5
}
TexturedBackgroundLight {
  luminosity 0.4
}
DEF arena RectangleArena {
  translation -0.04 -0.07 0
  rotation 0 1 0 4.692820414042842e-06
  floorSize 2 2
}
DEF supervisor TinkerbotsBase {
  translation -0.41 -1.71 0.0204938
  rotation 7.60892408421629e-13 1 6.074441725585955e-13 4.694645743801461e-06
  controller "ga_update_learner"
  supervisor TRUE
  extensionSlot [
    Receiver {
      channel 2
    }
    Emitter {
      channel 1
    }
    Emitter {
      name "emitter_processor"
      channel 5
    }
  ]
}
DEF khepera Robot {
  translation 0.28977200328873554 0.09037800420781392 9.096900227267835e-07
  rotation 0.03505831201338036 -0.07082879308324756 0.9968722068696383 0.9216262022369641
  children [
    Emitter {
      name "emitter_processor"
    }
    Receiver {
      name "receiver_processor"
      channel -1
    }
    GPS {
      name "gps(1)"
    }
    Group {
      children [
        DistanceSensor {
          translation 0 0 0.02
          rotation 0 0 1 -0.523
          name "distance sensor right"
        }
        DistanceSensor {
          translation 0 0 0.02
          rotation 0 0 1 0.523
          name "distance sensor left"
        }
        LightSensor {
          translation -0.02 5.30722e-08 0
          rotation 0 0 1 3.14159
          lookupTable [
            0 0 0
            4 1024 0
          ]
        }
        LED {
          translation 0.04 0 0
          recognitionColors [
            0 0 0
          ]
        }
        TouchSensor {
        }
        GPS {
        }
        DistanceSensor {
          translation 0 0 0.02
          rotation 0 1 0 0
        }
        InertialUnit {
        }
        Receiver {
          channel 1
        }
        Emitter {
          channel 2
        }
        DEF LIFT_HINGE_JOINT HingeJoint {
          jointParameters HingeJointParameters {
            position -1.3999963450018997
            axis 0 1 0
            anchor -0.01 0 0.022
          }
          device [
            RotationalMotor {
              name "motor"
            }
          ]
          endPoint Solid {
            translation -0.010000272344832877 2.437851864822667e-09 0.021999275509451743
            rotation 0.7058147871033154 -0.7058147871032284 -0.060423278732008985 3.0208927321362125
            children [
              DEF RIGHT_GRIP SliderJoint {
                jointParameters JointParameters {
                  position 0.00016830205045675813
                  axis 1 0 0
                }
                device [
                  LinearMotor {
                    name "right grip"
                    maxVelocity 0.1
                    minPosition -6.244776062687065e-14
                    maxPosition 0.029
                    maxForce 100
                  }
                ]
                endPoint Solid {
                  translation 0.00016830205083327195 0 -0.048
                  rotation 0 1 0 1.5708
                  children [
                    Shape {
                      appearance PBRAppearance {
                        baseColor 0.8 0.8 0.8
                        roughness 1
                        metalness 0
                      }
                      geometry IndexedFaceSet {
                        coord Coordinate {
                          point [
                            0 -0.004 0.004
                            0.03 -0.004 0.002
                            0.03 -0.004 0.0001
                            0 -0.004 0.0001
                            0 -0.004 0.004
                            0 0.004 0.004
                            0.03 0.004 0.002
                            0.03 0.004 0.0001
                            0 0.004 0.0001
                            0 0.004 0.004
                          ]
                        }
                        coordIndex [
                          4, 3, 2, 1, 0, -1, 5, 6, 7, 8, 9, -1, 0, 1, 6, 5, -1, 1, 2, 7, 6, -1, 2, 3, 8, 7, -1, 3, 4, 9, 8, -1
                        ]
                      }
                    }
                    DistanceSensor {
                      translation 0.015 0 0
                      rotation 0 1 0 1.5708
                      name "ds"
                      lookupTable [
                        0 0 0
                        0.05 1000 0
                      ]
                      type "infra-red"
                    }
                  ]
                  name "right grip"
                  contactMaterial "gripper"
                  boundingObject Transform {
                    translation 0.015 0 0.003
                    children [
                      Box {
                        size 0.028 0.007 0.005
                      }
                    ]
                  }
                  physics Physics {
                    density 100
                    centerOfMass [
                      0.01 0 0
                    ]
                  }
                }
              }
              DEF LEFT_GRIP SliderJoint {
                jointParameters JointParameters {
                  position -0.00016830672719630367
                  axis -1 0 0
                }
                device [
                  LinearMotor {
                    name "left grip"
                    maxVelocity 0.1
                    minPosition -0.00016864583241887318
                    maxPosition 0.029
                    maxForce 100
                  }
                ]
                endPoint Solid {
                  translation 0.0001683067275728177 0 -0.048
                  rotation 0 1 0 -1.5708
                  children [
                    Shape {
                      appearance PBRAppearance {
                        baseColor 0.8 0.8 0.8
                        roughness 1
                        metalness 0
                      }
                      geometry IndexedFaceSet {
                        coord Coordinate {
                          point [
                            0 -0.004 0.0001
                            -0.03 -0.004 0.0001
                            -0.03 -0.004 0.002
                            0 -0.004 0.004
                            0 -0.004 0.0001
                            0 0.004 0.0001
                            -0.03 0.004 0.0001
                            -0.03 0.004 0.002
                            0 0.004 0.004
                            0 0.004 0.0001
                          ]
                        }
                        coordIndex [
                          4, 3, 2, 1, 0, -1, 5, 6, 7, 8, 9, -1, 0, 1, 6, 5, -1, 1, 2, 7, 6, -1, 2, 3, 8, 7, -1, 3, 4, 9, 8, -1
                        ]
                      }
                    }
                  ]
                  name "left grip"
                  contactMaterial "gripper"
                  boundingObject Transform {
                    translation -0.015 0 0.003
                    children [
                      Box {
                        size 0.028 0.007 0.005
                      }
                    ]
                  }
                  physics Physics {
                    density 100
                    centerOfMass [
                      -0.01 0 0
                    ]
                  }
                }
              }
              Shape {
                appearance PBRAppearance {
                  baseColor 0.8 0.8 0.8
                  roughness 1
                  metalness 0
                }
                geometry IndexedFaceSet {
                  coord Coordinate {
                    point [
                      0.035 -0.004 0.006
                      0.035 -0.004 -0.048
                      -0.035 -0.004 -0.048
                      -0.035 -0.004 0.006
                      -0.025 -0.004 0.006
                      -0.025 -0.004 -0.03
                      -0.016 -0.004 -0.04
                      0.016 -0.004 -0.04
                      0.025 -0.004 -0.03
                      0.025 -0.004 0.006
                      0.035 -0.004 0.006
                      0.035 0.004 0.006
                      0.035 0.004 -0.048
                      -0.035 0.004 -0.048
                      -0.035 0.004 0.006
                      -0.025 0.004 0.006
                      -0.025 0.004 -0.03
                      -0.016 0.004 -0.04
                      0.016 0.004 -0.04
                      0.025 0.004 -0.03
                      0.025 0.004 0.006
                      0.035 0.004 0.006
                    ]
                  }
                  coordIndex [
                    10, 9, 8, 7, 6, 5, 4, 3, 2, 1, 0, -1, 11, 12, 13, 14, 15, 16, 17, 18, 19, 20, 21, -1, 0, 1, 12, 11, -1, 1, 2, 13, 12, -1, 2, 3, 14, 13, -1, 3, 4, 15, 14, -1, 4, 5, 16, 15, -1, 5, 6, 17, 16, -1, 6, 7, 18, 17, -1, 7, 8, 19, 18, -1, 8, 9, 20, 19, -1, 9, 10, 21, 20, -1
                  ]
                }
              }
            ]
            boundingObject Transform {
              translation 0 0 -0.021
              children [
                Box {
                  size 0.068 0.008 0.052
                }
              ]
            }
            physics Physics {
              density 100
              centerOfMass [
                0 0 -0.02
              ]
            }
          }
        }
        DEF GRIPPER_BASE Transform {
          translation -0.01 0 0.023
          rotation 0.5773502691896258 -0.5773502691896258 -0.5773502691896258 2.094395
          children [
            Shape {
              appearance PBRAppearance {
                baseColor 0.8 0.8 0.8
                roughness 1
                metalness 0
              }
              geometry Box {
                size 0.05 0.01 0.01
              }
            }
          ]
        }
        Camera {
          translation -0.01 0 0.035
          rotation -0.999759341318827 -0.016153505514822745 -0.014843305067519018 -5.307179586466759e-06
          children [
            Shape {
              appearance PBRAppearance {
                baseColor 0.70632 0.70632 0.70632
                roughness 1
                metalness 0
              }
              geometry DEF CAMERA Box {
                size 0.03 0.03 0.02
              }
            }
          ]
          boundingObject DEF CAMERA Box {
            size 0.03 0.03 0.02
          }
          physics Physics {
            density -1
            mass 0.02
          }
          fieldOfView 0.3
          recognition Recognition {
            maxRange 50
          }
        }
      ]
    }
    Shape {
      appearance PBRAppearance {
        baseColor 0.0539951 0.505576 0.0897663
        roughness 0.4
        metalness 0
      }
      geometry IndexedFaceSet {
        coord Coordinate {
          point [
            0.009 -0.0276 0.0025, 0.0194 -0.0215 0.0025, 0.0265 -0.0118 0.0025, 0.029 0 0.0025, 0.0265 0.0118 0.0025, 0.0194 0.0215 0.0025, 0.009 0.0276 0.0025, 0.009 0.0236 0.02, -0.009 0.0236 0.02, -0.009 -0.0236 0.02, 0.009 -0.0236 0.02, -0.009 0.0276 0.0025, -0.0194 0.0215 0.0025, -0.0265 0.0118 0.0025, -0.029 0 0.0025, -0.0265 -0.0118 0.0025, -0.0194 -0.0215 0.0025, -0.009 -0.0276 0.0025, 0.009 -0.0276 0.001, 0.0194 -0.0215 0.001, 0.0265 -0.0118 0.001, 0.029 0 0.001, 0.0265 0.0118 0.001, 0.0194 0.0215 0.001, 0.009 0.0276 0.001, 0.009 0.0236 0.001, -0.009 0.0236 0.001, -0.009 -0.0236 0.001, 0.009 -0.0236 0.001, -0.009 0.0276 0.001, -0.0194 0.0215 0.001, -0.0265 0.0118 0.001, -0.029 0 0.001, -0.0265 -0.0118 0.001, -0.0194 -0.0215 0.001, -0.009 -0.0276 0.001
          ]
        }
        coordIndex [
          0, 1, 2, 3, 4, 5, 6, -1, 11, 12, 13, 14, 15, 16, 17, -1, 24, 23, 22, 21, 20, 19, 18, -1, 35, 34, 33, 32, 31, 30, 29, -1, 1, 0, 18, 19, -1, 2, 1, 19, 20, -1, 3, 2, 20, 21, -1, 4, 3, 21, 22, -1, 5, 4, 22, 23, -1, 6, 5, 23, 24, -1, 0, 6, 24, 18, -1, 17, 16, 34, 35, -1, 16, 15, 33, 34, -1, 15, 14, 32, 33, -1, 14, 13, 31, 32, -1, 13, 12, 30, 31, -1, 12, 11, 29, 30, -1, 11, 17, 35, 29, -1, 7, 10, 28, 25, -1, 9, 8, 26, 27, -1, 8, 7, 25, 26, -1, 10, 9, 27, 28, -1, 28, 27, 26, 25, -1
        ]
        creaseAngle 0.5
      }
    }
    HingeJoint {
      jointParameters HingeJointParameters {
        position -44.05907833376422
        axis 0 1 0
        anchor 0 0 0.0075
      }
      device [
        RotationalMotor {
          name "left wheel motor"
        }
        PositionSensor {
          name "left wheel sensor"
          resolution 0.0314
        }
      ]
      endPoint Solid {
        translation 0 0.02599999999999993 0.0075
        rotation 0.641133314104578 -0.6411333100516222 0.4217773728965685 3.9398686124888385
        children [
          DEF WHEEL Transform {
            rotation 0.5773869352700204 -0.5773319352761864 0.5773319352761864 -2.094339
            children [
              Shape {
                appearance PBRAppearance {
                  baseColor 0.778497 0.793743 0.8
                  roughness 0.3
                  metalness 0
                }
                geometry Cylinder {
                  height 0.003
                  radius 0.0075
                }
              }
            ]
          }
        ]
        name "left wheel"
        boundingObject USE WHEEL
        physics Physics {
        }
      }
    }
    HingeJoint {
      jointParameters HingeJointParameters {
        position 160.93913794893925
        axis 0 1 0
        anchor 0 0 0.0075
      }
      device [
        RotationalMotor {
          name "right wheel motor"
        }
        PositionSensor {
          name "right wheel sensor"
          resolution 0.0314
        }
      ]
      endPoint Solid {
        translation 0 -0.025999999999999687 0.0075
        rotation 0.20740857710019792 -0.20740839147332163 -0.9560143520322906 1.6157635910617334
        children [
          USE WHEEL
        ]
        name "right wheel"
        boundingObject USE WHEEL
        physics Physics {
        }
      }
    }
    Transform {
      translation 0 0 0.02
      rotation 0 0 1 -1.570796
      children [
        Shape {
          appearance PBRAppearance {
            baseColor 0.015 0.48 0.1796
            roughness 0.4
            metalness 0
          }
          geometry Cylinder {
            height 0.0015
            radius 0.028
          }
        }
      ]
    }
    DEF LS0 LightSensor {
      translation 0.00215188 0.0227638 0.0144
      rotation 0.5102819257784789 0.6081179115480401 0.6081159115483309 2.19792
      name "ls0"
      lookupTable [
        0 0 0
        4 1024 0
      ]
    }
    DEF LS1 LightSensor {
      translation 0.0139291 0.0114289 0.0144
      rotation 0.6776599336428648 0.5199889490821645 0.5199889490821645 1.95044
      name "ls1"
      lookupTable [
        0 0 0
        4 1024 0
      ]
    }
    DEF LS2 LightSensor {
      translation 0.0123588 -0.0225 0.0144
      rotation -0.5773509358554485 0.5773489358556708 0.5773509358554485 -2.094395307179586
      name "ls2"
      lookupTable [
        0 0 0
        4 1024 0
      ]
    }
    DEF LS3 LightSensor {
      translation -0.00166025 -0.00785883 0.0144
      rotation -0.1861570160863869 0.6947460600350939 0.6947470600351803 -2.7734953071795863
      name "ls3"
      lookupTable [
        0 0 0
        4 1024 0
      ]
    }
    DEF LS4 LightSensor {
      translation -0.0072844 0.00978409 0.0144
      rotation 0.2810839910810645 0.6785979784677472 0.6785989784677153 2.59357
      name "ls4"
      lookupTable [
        0 0 0
        4 1024 0
      ]
    }
    DEF LS5 LightSensor {
      translation -0.0103523 -0.0251114 0.0144
      rotation -0.8053168807607647 0.4192049379304254 0.4192039379305735 -1.7856453071795864
      name "ls5"
      lookupTable [
        0 0 0
        4 1024 0
      ]
    }
    DEF LS6 LightSensor {
      translation -0.0163407 -0.00641179 0.0144
      rotation -0.09269154676500942 0.7040625956398727 0.7040625956398727 -2.9567353071795863
      name "ls6"
      lookupTable [
        0 0 0
        4 1024 0
      ]
    }
    DEF LS7 LightSensor {
      translation -0.016 0.00899998 0.0144
      rotation 0 -0.7071067811865476 -0.7071067811865476 -3.14159
      name "ls7"
      lookupTable [
        0 0 0
        4 1024 0
      ]
    }
    DEF LED0 LED {
      translation 0.042 -0.003 0.021
      rotation 0.5773502691896258 -0.5773502691896258 -0.5773502691896258 2.094395
      children [
        PointLight {
          attenuation 0 0 12.56
          color 1 0 0
          intensity 0.25
          on FALSE
          radius 10
        }
        Shape {
          appearance PBRAppearance {
            baseColor 0.501961 0.501961 0.501961
            metalness 0
            emissiveIntensity 7
          }
          geometry Box {
            size 0.002 0.002 0.002
          }
        }
      ]
      name "led0"
    }
    DEF LED1 LED {
      translation 0.024 -0.01 0.021
      rotation 0.5773502691896258 -0.5773502691896258 -0.5773502691896258 2.094395
      children [
        Shape {
          appearance PBRAppearance {
            baseColor 0.501961 0.501961 0.501961
            metalness 0
          }
          geometry Box {
            size 0.002 0.002 0.002
          }
        }
      ]
      name "led1"
    }
    DEF RS232_OUT Emitter {
      name "rs232_out"
      type "serial"
      range 1000
      baudRate 57600
    }
    DEF RS232_IN Receiver {
      name "rs232_in"
      type "serial"
      baudRate 57600
    }
  ]
  name "k0"
  model "Khepera"
  description "A mini mobile robot by K-Team SA"
  contactMaterial "khepera"
  boundingObject Transform {
    translation 0 0 0.012
    rotation 0 0 1 -1.570796
    children [
      Cylinder {
        height 0.02
        radius 0.0285
      }
    ]
  }
  physics Physics {
    centerOfMass [
      0 0 0.005
    ]
  }
  controller "updated_generalized_ga_learning"
  supervisor TRUE
}
DEF khepera Robot {
  translation -0.03459723268948559 -0.061264821131479706 2.4385012340685797e-06
  rotation -0.001464338082836391 -0.999134336815934 -0.041574423740601434 0.07035947333709068
  children [
    Emitter {
      name "emitter_processor"
    }
    Receiver {
      name "receiver_processor"
      channel 9
    }
    GPS {
      name "gps(1)"
    }
    Group {
      children [
        DistanceSensor {
          translation 0 0 0.02
          rotation 0 0 1 -0.523
          name "distance sensor right"
        }
        DistanceSensor {
          translation 0 0 0.02
          rotation 0 0 1 0.523
          name "distance sensor left"
        }
        LightSensor {
          translation -0.02 5.30722e-08 0
          rotation 0 0 1 3.14159
          lookupTable [
            0 0 0
            4 1024 0
          ]
        }
        LED {
          translation 0.04 0 0
          recognitionColors [
            0 0 0
          ]
        }
        TouchSensor {
        }
        GPS {
        }
        DistanceSensor {
          translation 0 0 0.02
          rotation 0 1 0 0
        }
        InertialUnit {
        }
        Receiver {
          channel 1
        }
        Emitter {
          channel 2
        }
        DEF LIFT_HINGE_JOINT HingeJoint {
          jointParameters HingeJointParameters {
            position -1.3998343502564827
            axis 0 1 0
            anchor -0.01 0 0.022
          }
          device [
            RotationalMotor {
              name "motor"
            }
          ]
          endPoint Solid {
            translation -0.010000272462192964 2.437851864822669e-09 0.02199927555357968
            rotation 0.7058123299334048 -0.705812329928773 -0.06048065669695984 3.020778394048457
            children [
              DEF RIGHT_GRIP SliderJoint {
                jointParameters JointParameters {
                  position 0.00017181085938966061
                  axis 1 0 0
                }
                device [
                  LinearMotor {
                    name "right grip"
                    maxVelocity 0.1
                    minPosition -6.244776062687065e-14
                    maxPosition 0.029
                    maxForce 100
                  }
                ]
                endPoint Solid {
                  translation 0.00017181085976617443 0 -0.048
                  rotation 0 1 0 1.5708
                  children [
                    Shape {
                      appearance PBRAppearance {
                        baseColor 0.8 0.8 0.8
                        roughness 1
                        metalness 0
                      }
                      geometry IndexedFaceSet {
                        coord Coordinate {
                          point [
                            0 -0.004 0.004
                            0.03 -0.004 0.002
                            0.03 -0.004 0.0001
                            0 -0.004 0.0001
                            0 -0.004 0.004
                            0 0.004 0.004
                            0.03 0.004 0.002
                            0.03 0.004 0.0001
                            0 0.004 0.0001
                            0 0.004 0.004
                          ]
                        }
                        coordIndex [
                          4, 3, 2, 1, 0, -1, 5, 6, 7, 8, 9, -1, 0, 1, 6, 5, -1, 1, 2, 7, 6, -1, 2, 3, 8, 7, -1, 3, 4, 9, 8, -1
                        ]
                      }
                    }
                    DistanceSensor {
                      translation 0.015 0 0
                      rotation 0 1 0 1.5708
                      name "ds"
                      lookupTable [
                        0 0 0
                        0.05 1000 0
                      ]
                      type "infra-red"
                    }
                  ]
                  name "right grip"
                  contactMaterial "gripper"
                  boundingObject Transform {
                    translation 0.015 0 0.003
                    children [
                      Box {
                        size 0.028 0.007 0.005
                      }
                    ]
                  }
                  physics Physics {
                    density 100
                    centerOfMass [
                      0.01 0 0
                    ]
                  }
                }
              }
              DEF LEFT_GRIP SliderJoint {
                jointParameters JointParameters {
                  position -0.00017181557795078258
                  axis -1 0 0
                }
                device [
                  LinearMotor {
                    name "left grip"
                    maxVelocity 0.1
                    minPosition -0.00017181559157368483
                    maxPosition 0.029
                    maxForce 100
                  }
                ]
                endPoint Solid {
                  translation 0.0001718155783272966 0 -0.048
                  rotation 0 1 0 -1.5708
                  children [
                    Shape {
                      appearance PBRAppearance {
                        baseColor 0.8 0.8 0.8
                        roughness 1
                        metalness 0
                      }
                      geometry IndexedFaceSet {
                        coord Coordinate {
                          point [
                            0 -0.004 0.0001
                            -0.03 -0.004 0.0001
                            -0.03 -0.004 0.002
                            0 -0.004 0.004
                            0 -0.004 0.0001
                            0 0.004 0.0001
                            -0.03 0.004 0.0001
                            -0.03 0.004 0.002
                            0 0.004 0.004
                            0 0.004 0.0001
                          ]
                        }
                        coordIndex [
                          4, 3, 2, 1, 0, -1, 5, 6, 7, 8, 9, -1, 0, 1, 6, 5, -1, 1, 2, 7, 6, -1, 2, 3, 8, 7, -1, 3, 4, 9, 8, -1
                        ]
                      }
                    }
                  ]
                  name "left grip"
                  contactMaterial "gripper"
                  boundingObject Transform {
                    translation -0.015 0 0.003
                    children [
                      Box {
                        size 0.028 0.007 0.005
                      }
                    ]
                  }
                  physics Physics {
                    density 100
                    centerOfMass [
                      -0.01 0 0
                    ]
                  }
                }
              }
              Shape {
                appearance PBRAppearance {
                  baseColor 0.8 0.8 0.8
                  roughness 1
                  metalness 0
                }
                geometry IndexedFaceSet {
                  coord Coordinate {
                    point [
                      0.035 -0.004 0.006
                      0.035 -0.004 -0.048
                      -0.035 -0.004 -0.048
                      -0.035 -0.004 0.006
                      -0.025 -0.004 0.006
                      -0.025 -0.004 -0.03
                      -0.016 -0.004 -0.04
                      0.016 -0.004 -0.04
                      0.025 -0.004 -0.03
                      0.025 -0.004 0.006
                      0.035 -0.004 0.006
                      0.035 0.004 0.006
                      0.035 0.004 -0.048
                      -0.035 0.004 -0.048
                      -0.035 0.004 0.006
                      -0.025 0.004 0.006
                      -0.025 0.004 -0.03
                      -0.016 0.004 -0.04
                      0.016 0.004 -0.04
                      0.025 0.004 -0.03
                      0.025 0.004 0.006
                      0.035 0.004 0.006
                    ]
                  }
                  coordIndex [
                    10, 9, 8, 7, 6, 5, 4, 3, 2, 1, 0, -1, 11, 12, 13, 14, 15, 16, 17, 18, 19, 20, 21, -1, 0, 1, 12, 11, -1, 1, 2, 13, 12, -1, 2, 3, 14, 13, -1, 3, 4, 15, 14, -1, 4, 5, 16, 15, -1, 5, 6, 17, 16, -1, 6, 7, 18, 17, -1, 7, 8, 19, 18, -1, 8, 9, 20, 19, -1, 9, 10, 21, 20, -1
                  ]
                }
              }
            ]
            boundingObject Transform {
              translation 0 0 -0.021
              children [
                Box {
                  size 0.068 0.008 0.052
                }
              ]
            }
            physics Physics {
              density 100
              centerOfMass [
                0 0 -0.02
              ]
            }
          }
        }
        DEF GRIPPER_BASE Transform {
          translation -0.01 0 0.023
          rotation 0.5773502691896258 -0.5773502691896258 -0.5773502691896258 2.094395
          children [
            Shape {
              appearance PBRAppearance {
                baseColor 0.8 0.8 0.8
                roughness 1
                metalness 0
              }
              geometry Box {
                size 0.05 0.01 0.01
              }
            }
          ]
        }
        Camera {
          translation -0.01 0 0.035
          rotation -0.999759341318827 -0.016153505514822745 -0.014843305067519018 -5.307179586466759e-06
          children [
            Shape {
              appearance PBRAppearance {
                baseColor 0.70632 0.70632 0.70632
                roughness 1
                metalness 0
              }
              geometry DEF CAMERA Box {
                size 0.03 0.03 0.02
              }
            }
          ]
          boundingObject DEF CAMERA Box {
            size 0.03 0.03 0.02
          }
          physics Physics {
            density -1
            mass 0.02
          }
          fieldOfView 0.3
          recognition Recognition {
            maxRange 50
          }
        }
      ]
    }
    Shape {
      appearance PBRAppearance {
        baseColor 0.0539951 0.505576 0.0897663
        roughness 0.4
        metalness 0
      }
      geometry IndexedFaceSet {
        coord Coordinate {
          point [
            0.009 -0.0276 0.0025, 0.0194 -0.0215 0.0025, 0.0265 -0.0118 0.0025, 0.029 0 0.0025, 0.0265 0.0118 0.0025, 0.0194 0.0215 0.0025, 0.009 0.0276 0.0025, 0.009 0.0236 0.02, -0.009 0.0236 0.02, -0.009 -0.0236 0.02, 0.009 -0.0236 0.02, -0.009 0.0276 0.0025, -0.0194 0.0215 0.0025, -0.0265 0.0118 0.0025, -0.029 0 0.0025, -0.0265 -0.0118 0.0025, -0.0194 -0.0215 0.0025, -0.009 -0.0276 0.0025, 0.009 -0.0276 0.001, 0.0194 -0.0215 0.001, 0.0265 -0.0118 0.001, 0.029 0 0.001, 0.0265 0.0118 0.001, 0.0194 0.0215 0.001, 0.009 0.0276 0.001, 0.009 0.0236 0.001, -0.009 0.0236 0.001, -0.009 -0.0236 0.001, 0.009 -0.0236 0.001, -0.009 0.0276 0.001, -0.0194 0.0215 0.001, -0.0265 0.0118 0.001, -0.029 0 0.001, -0.0265 -0.0118 0.001, -0.0194 -0.0215 0.001, -0.009 -0.0276 0.001
          ]
        }
        coordIndex [
          0, 1, 2, 3, 4, 5, 6, -1, 11, 12, 13, 14, 15, 16, 17, -1, 24, 23, 22, 21, 20, 19, 18, -1, 35, 34, 33, 32, 31, 30, 29, -1, 1, 0, 18, 19, -1, 2, 1, 19, 20, -1, 3, 2, 20, 21, -1, 4, 3, 21, 22, -1, 5, 4, 22, 23, -1, 6, 5, 23, 24, -1, 0, 6, 24, 18, -1, 17, 16, 34, 35, -1, 16, 15, 33, 34, -1, 15, 14, 32, 33, -1, 14, 13, 31, 32, -1, 13, 12, 30, 31, -1, 12, 11, 29, 30, -1, 11, 17, 35, 29, -1, 7, 10, 28, 25, -1, 9, 8, 26, 27, -1, 8, 7, 25, 26, -1, 10, 9, 27, 28, -1, 28, 27, 26, 25, -1
        ]
        creaseAngle 0.5
      }
    }
    HingeJoint {
      jointParameters HingeJointParameters {
        position -36.70855022476216
        axis 0 1 0
        anchor 0 0 0.0075
      }
      device [
        RotationalMotor {
          name "left wheel motor"
        }
        PositionSensor {
          name "left wheel sensor"
          resolution 0.0314
        }
      ]
      endPoint Solid {
        translation 0 0.025999999999999936 0.0075
        rotation -0.7066955971361739 0.706695643406428 -0.034096929168495146 3.073425033127895
        children [
          DEF WHEEL Transform {
            rotation 0.5773869352700204 -0.5773319352761864 0.5773319352761864 -2.094339
            children [
              Shape {
                appearance PBRAppearance {
                  baseColor 0.778497 0.793743 0.8
                  roughness 0.3
                  metalness 0
                }
                geometry Cylinder {
                  height 0.003
                  radius 0.0075
                }
              }
            ]
          }
        ]
        name "left wheel"
        boundingObject USE WHEEL
        physics Physics {
        }
      }
    }
    HingeJoint {
      jointParameters HingeJointParameters {
        position 164.08866230077464
        axis 0 1 0
        anchor 0 0 0.0075
      }
      device [
        RotationalMotor {
          name "right wheel motor"
        }
        PositionSensor {
          name "right wheel sensor"
          resolution 0.0314
        }
      ]
      endPoint Solid {
        translation 0 -0.02599999999999968 0.0075
        rotation -0.6992349307908752 0.6992348793546889 -0.14879884090850215 2.8461628918258093
        children [
          USE WHEEL
        ]
        name "right wheel"
        boundingObject USE WHEEL
        physics Physics {
        }
      }
    }
    Transform {
      translation 0 0 0.02
      rotation 0 0 1 -1.570796
      children [
        Shape {
          appearance PBRAppearance {
            baseColor 0.015 0.48 0.1796
            roughness 0.4
            metalness 0
          }
          geometry Cylinder {
            height 0.0015
            radius 0.028
          }
        }
      ]
    }
    DEF LS0 LightSensor {
      translation 0.00215188 0.0227638 0.0144
      rotation 0.5102819257784789 0.6081179115480401 0.6081159115483309 2.19792
      name "ls0"
      lookupTable [
        0 0 0
        4 1024 0
      ]
    }
    DEF LS1 LightSensor {
      translation 0.0139291 0.0114289 0.0144
      rotation 0.6776599336428648 0.5199889490821645 0.5199889490821645 1.95044
      name "ls1"
      lookupTable [
        0 0 0
        4 1024 0
      ]
    }
    DEF LS2 LightSensor {
      translation 0.0123588 -0.0225 0.0144
      rotation -0.5773509358554485 0.5773489358556708 0.5773509358554485 -2.094395307179586
      name "ls2"
      lookupTable [
        0 0 0
        4 1024 0
      ]
    }
    DEF LS3 LightSensor {
      translation -0.00166025 -0.00785883 0.0144
      rotation -0.1861570160863869 0.6947460600350939 0.6947470600351803 -2.7734953071795863
      name "ls3"
      lookupTable [
        0 0 0
        4 1024 0
      ]
    }
    DEF LS4 LightSensor {
      translation -0.0072844 0.00978409 0.0144
      rotation 0.2810839910810645 0.6785979784677472 0.6785989784677153 2.59357
      name "ls4"
      lookupTable [
        0 0 0
        4 1024 0
      ]
    }
    DEF LS5 LightSensor {
      translation -0.0103523 -0.0251114 0.0144
      rotation -0.8053168807607647 0.4192049379304254 0.4192039379305735 -1.7856453071795864
      name "ls5"
      lookupTable [
        0 0 0
        4 1024 0
      ]
    }
    DEF LS6 LightSensor {
      translation -0.0163407 -0.00641179 0.0144
      rotation -0.09269154676500942 0.7040625956398727 0.7040625956398727 -2.9567353071795863
      name "ls6"
      lookupTable [
        0 0 0
        4 1024 0
      ]
    }
    DEF LS7 LightSensor {
      translation -0.016 0.00899998 0.0144
      rotation 0 -0.7071067811865476 -0.7071067811865476 -3.14159
      name "ls7"
      lookupTable [
        0 0 0
        4 1024 0
      ]
    }
    DEF LED0 LED {
      translation 0.042 -0.003 0.021
      rotation 0.5773502691896258 -0.5773502691896258 -0.5773502691896258 2.094395
      children [
        PointLight {
          attenuation 0 0 12.56
          color 1 0 0
          intensity 0.25
          on FALSE
          radius 10
        }
        Shape {
          appearance PBRAppearance {
            baseColor 0.501961 0.501961 0.501961
            metalness 0
            emissiveIntensity 7
          }
          geometry Box {
            size 0.002 0.002 0.002
          }
        }
      ]
      name "led0"
    }
    DEF LED1 LED {
      translation 0.024 -0.01 0.021
      rotation 0.5773502691896258 -0.5773502691896258 -0.5773502691896258 2.094395
      children [
        Shape {
          appearance PBRAppearance {
            baseColor 0.501961 0.501961 0.501961
            metalness 0
          }
          geometry Box {
            size 0.002 0.002 0.002
          }
        }
      ]
      name "led1"
    }
    DEF RS232_OUT Emitter {
      name "rs232_out"
      type "serial"
      range 1000
      baudRate 57600
    }
    DEF RS232_IN Receiver {
      name "rs232_in"
      type "serial"
      baudRate 57600
    }
  ]
  name "k0(1)"
  model "Khepera"
  description "A mini mobile robot by K-Team SA"
  contactMaterial "khepera"
  boundingObject Transform {
    translation 0 0 0.012
    rotation 0 0 1 -1.570796
    children [
      Cylinder {
        height 0.02
        radius 0.0285
      }
    ]
  }
  physics Physics {
    centerOfMass [
      0 0 0.005
    ]
  }
  controller "updated_generalized_ga_learning"
  supervisor TRUE
}
DEF khepera Robot {
  translation 0.15977200339307632 -0.2696219952903166 1.5197566755453112e-06
  rotation 0.03505831201008873 -0.0708287943865157 0.9968722067771556 0.9216261875795121
  children [
    Emitter {
      name "emitter_processor"
    }
    Receiver {
      name "receiver_processor"
      channel 19
    }
    GPS {
      name "gps(1)"
    }
    Group {
      children [
        DistanceSensor {
          translation 0 0 0.02
          rotation 0 0 1 -0.523
          name "distance sensor right"
        }
        DistanceSensor {
          translation 0 0 0.02
          rotation 0 0 1 0.523
          name "distance sensor left"
        }
        LightSensor {
          translation -0.02 5.30722e-08 0
          rotation 0 0 1 3.14159
          lookupTable [
            0 0 0
            4 1024 0
          ]
        }
        LED {
          translation 0.04 0 0
          recognitionColors [
            0 0 0
          ]
        }
        TouchSensor {
        }
        GPS {
        }
        DistanceSensor {
          translation 0 0 0.02
          rotation 0 1 0 0
        }
        InertialUnit {
        }
        Receiver {
          channel 1
        }
        Emitter {
          channel 2
        }
        DEF LIFT_HINGE_JOINT HingeJoint {
          jointParameters HingeJointParameters {
            position -1.3999963450018995
            axis 0 1 0
            anchor -0.01 0 0.022
          }
          device [
            RotationalMotor {
              name "motor"
            }
          ]
          endPoint Solid {
            translation -0.010000272344832877 2.4378518648226675e-09 0.021999275509451743
            rotation 0.7058147871033154 -0.7058147871032284 -0.060423278732009096 3.0208927321362125
            children [
              DEF RIGHT_GRIP SliderJoint {
                jointParameters JointParameters {
                  position 0.0001683020504568361
                  axis 1 0 0
                }
                device [
                  LinearMotor {
                    name "right grip"
                    maxVelocity 0.1
                    minPosition -6.244776062687065e-14
                    maxPosition 0.029
                    maxForce 100
                  }
                ]
                endPoint Solid {
                  translation 0.00016830205083334993 0 -0.048
                  rotation 0 1 0 1.5708
                  children [
                    Shape {
                      appearance PBRAppearance {
                        baseColor 0.8 0.8 0.8
                        roughness 1
                        metalness 0
                      }
                      geometry IndexedFaceSet {
                        coord Coordinate {
                          point [
                            0 -0.004 0.004
                            0.03 -0.004 0.002
                            0.03 -0.004 0.0001
                            0 -0.004 0.0001
                            0 -0.004 0.004
                            0 0.004 0.004
                            0.03 0.004 0.002
                            0.03 0.004 0.0001
                            0 0.004 0.0001
                            0 0.004 0.004
                          ]
                        }
                        coordIndex [
                          4, 3, 2, 1, 0, -1, 5, 6, 7, 8, 9, -1, 0, 1, 6, 5, -1, 1, 2, 7, 6, -1, 2, 3, 8, 7, -1, 3, 4, 9, 8, -1
                        ]
                      }
                    }
                    DistanceSensor {
                      translation 0.015 0 0
                      rotation 0 1 0 1.5708
                      name "ds"
                      lookupTable [
                        0 0 0
                        0.05 1000 0
                      ]
                      type "infra-red"
                    }
                  ]
                  name "right grip"
                  contactMaterial "gripper"
                  boundingObject Transform {
                    translation 0.015 0 0.003
                    children [
                      Box {
                        size 0.028 0.007 0.005
                      }
                    ]
                  }
                  physics Physics {
                    density 100
                    centerOfMass [
                      0.01 0 0
                    ]
                  }
                }
              }
              DEF LEFT_GRIP SliderJoint {
                jointParameters JointParameters {
                  position -0.00016830672719643668
                  axis -1 0 0
                }
                device [
                  LinearMotor {
                    name "left grip"
                    maxVelocity 0.1
                    minPosition -0.00016864583241887318
                    maxPosition 0.029
                    maxForce 100
                  }
                ]
                endPoint Solid {
                  translation 0.0001683067275729507 0 -0.048
                  rotation 0 1 0 -1.5708
                  children [
                    Shape {
                      appearance PBRAppearance {
                        baseColor 0.8 0.8 0.8
                        roughness 1
                        metalness 0
                      }
                      geometry IndexedFaceSet {
                        coord Coordinate {
                          point [
                            0 -0.004 0.0001
                            -0.03 -0.004 0.0001
                            -0.03 -0.004 0.002
                            0 -0.004 0.004
                            0 -0.004 0.0001
                            0 0.004 0.0001
                            -0.03 0.004 0.0001
                            -0.03 0.004 0.002
                            0 0.004 0.004
                            0 0.004 0.0001
                          ]
                        }
                        coordIndex [
                          4, 3, 2, 1, 0, -1, 5, 6, 7, 8, 9, -1, 0, 1, 6, 5, -1, 1, 2, 7, 6, -1, 2, 3, 8, 7, -1, 3, 4, 9, 8, -1
                        ]
                      }
                    }
                  ]
                  name "left grip"
                  contactMaterial "gripper"
                  boundingObject Transform {
                    translation -0.015 0 0.003
                    children [
                      Box {
                        size 0.028 0.007 0.005
                      }
                    ]
                  }
                  physics Physics {
                    density 100
                    centerOfMass [
                      -0.01 0 0
                    ]
                  }
                }
              }
              Shape {
                appearance PBRAppearance {
                  baseColor 0.8 0.8 0.8
                  roughness 1
                  metalness 0
                }
                geometry IndexedFaceSet {
                  coord Coordinate {
                    point [
                      0.035 -0.004 0.006
                      0.035 -0.004 -0.048
                      -0.035 -0.004 -0.048
                      -0.035 -0.004 0.006
                      -0.025 -0.004 0.006
                      -0.025 -0.004 -0.03
                      -0.016 -0.004 -0.04
                      0.016 -0.004 -0.04
                      0.025 -0.004 -0.03
                      0.025 -0.004 0.006
                      0.035 -0.004 0.006
                      0.035 0.004 0.006
                      0.035 0.004 -0.048
                      -0.035 0.004 -0.048
                      -0.035 0.004 0.006
                      -0.025 0.004 0.006
                      -0.025 0.004 -0.03
                      -0.016 0.004 -0.04
                      0.016 0.004 -0.04
                      0.025 0.004 -0.03
                      0.025 0.004 0.006
                      0.035 0.004 0.006
                    ]
                  }
                  coordIndex [
                    10, 9, 8, 7, 6, 5, 4, 3, 2, 1, 0, -1, 11, 12, 13, 14, 15, 16, 17, 18, 19, 20, 21, -1, 0, 1, 12, 11, -1, 1, 2, 13, 12, -1, 2, 3, 14, 13, -1, 3, 4, 15, 14, -1, 4, 5, 16, 15, -1, 5, 6, 17, 16, -1, 6, 7, 18, 17, -1, 7, 8, 19, 18, -1, 8, 9, 20, 19, -1, 9, 10, 21, 20, -1
                  ]
                }
              }
            ]
            boundingObject Transform {
              translation 0 0 -0.021
              children [
                Box {
                  size 0.068 0.008 0.052
                }
              ]
            }
            physics Physics {
              density 100
              centerOfMass [
                0 0 -0.02
              ]
            }
          }
        }
        DEF GRIPPER_BASE Transform {
          translation -0.01 0 0.023
          rotation 0.5773502691896258 -0.5773502691896258 -0.5773502691896258 2.094395
          children [
            Shape {
              appearance PBRAppearance {
                baseColor 0.8 0.8 0.8
                roughness 1
                metalness 0
              }
              geometry Box {
                size 0.05 0.01 0.01
              }
            }
          ]
        }
        Camera {
          translation -0.01 0 0.035
          rotation -0.999759341318827 -0.016153505514822745 -0.014843305067519018 -5.307179586466759e-06
          children [
            Shape {
              appearance PBRAppearance {
                baseColor 0.70632 0.70632 0.70632
                roughness 1
                metalness 0
              }
              geometry DEF CAMERA Box {
                size 0.03 0.03 0.02
              }
            }
          ]
          boundingObject DEF CAMERA Box {
            size 0.03 0.03 0.02
          }
          physics Physics {
            density -1
            mass 0.02
          }
          fieldOfView 0.3
          recognition Recognition {
            maxRange 50
          }
        }
      ]
    }
    Shape {
      appearance PBRAppearance {
        baseColor 0.0539951 0.505576 0.0897663
        roughness 0.4
        metalness 0
      }
      geometry IndexedFaceSet {
        coord Coordinate {
          point [
            0.009 -0.0276 0.0025, 0.0194 -0.0215 0.0025, 0.0265 -0.0118 0.0025, 0.029 0 0.0025, 0.0265 0.0118 0.0025, 0.0194 0.0215 0.0025, 0.009 0.0276 0.0025, 0.009 0.0236 0.02, -0.009 0.0236 0.02, -0.009 -0.0236 0.02, 0.009 -0.0236 0.02, -0.009 0.0276 0.0025, -0.0194 0.0215 0.0025, -0.0265 0.0118 0.0025, -0.029 0 0.0025, -0.0265 -0.0118 0.0025, -0.0194 -0.0215 0.0025, -0.009 -0.0276 0.0025, 0.009 -0.0276 0.001, 0.0194 -0.0215 0.001, 0.0265 -0.0118 0.001, 0.029 0 0.001, 0.0265 0.0118 0.001, 0.0194 0.0215 0.001, 0.009 0.0276 0.001, 0.009 0.0236 0.001, -0.009 0.0236 0.001, -0.009 -0.0236 0.001, 0.009 -0.0236 0.001, -0.009 0.0276 0.001, -0.0194 0.0215 0.001, -0.0265 0.0118 0.001, -0.029 0 0.001, -0.0265 -0.0118 0.001, -0.0194 -0.0215 0.001, -0.009 -0.0276 0.001
          ]
        }
        coordIndex [
          0, 1, 2, 3, 4, 5, 6, -1, 11, 12, 13, 14, 15, 16, 17, -1, 24, 23, 22, 21, 20, 19, 18, -1, 35, 34, 33, 32, 31, 30, 29, -1, 1, 0, 18, 19, -1, 2, 1, 19, 20, -1, 3, 2, 20, 21, -1, 4, 3, 21, 22, -1, 5, 4, 22, 23, -1, 6, 5, 23, 24, -1, 0, 6, 24, 18, -1, 17, 16, 34, 35, -1, 16, 15, 33, 34, -1, 15, 14, 32, 33, -1, 14, 13, 31, 32, -1, 13, 12, 30, 31, -1, 12, 11, 29, 30, -1, 11, 17, 35, 29, -1, 7, 10, 28, 25, -1, 9, 8, 26, 27, -1, 8, 7, 25, 26, -1, 10, 9, 27, 28, -1, 28, 27, 26, 25, -1
        ]
        creaseAngle 0.5
      }
    }
    HingeJoint {
      jointParameters HingeJointParameters {
        position -44.05907833376417
        axis 0 1 0
        anchor 0 0 0.0075
      }
      device [
        RotationalMotor {
          name "left wheel motor"
        }
        PositionSensor {
          name "left wheel sensor"
          resolution 0.0314
        }
      ]
      endPoint Solid {
        translation 0 0.025999999999999922 0.0075
        rotation 0.6411333141045841 -0.6411333100516284 0.4217773728965497 3.9398686124888065
        children [
          DEF WHEEL Transform {
            rotation 0.5773869352700204 -0.5773319352761864 0.5773319352761864 -2.094339
            children [
              Shape {
                appearance PBRAppearance {
                  baseColor 0.778497 0.793743 0.8
                  roughness 0.3
                  metalness 0
                }
                geometry Cylinder {
                  height 0.003
                  radius 0.0075
                }
              }
            ]
          }
        ]
        name "left wheel"
        boundingObject USE WHEEL
        physics Physics {
        }
      }
    }
    HingeJoint {
      jointParameters HingeJointParameters {
        position 160.9391379489394
        axis 0 1 0
        anchor 0 0 0.0075
      }
      device [
        RotationalMotor {
          name "right wheel motor"
        }
        PositionSensor {
          name "right wheel sensor"
          resolution 0.0314
        }
      ]
      endPoint Solid {
        translation 0 -0.02599999999999968 0.0075
        rotation 0.20740857710013297 -0.20740839147325663 -0.9560143520323189 1.615763591061704
        children [
          USE WHEEL
        ]
        name "right wheel"
        boundingObject USE WHEEL
        physics Physics {
        }
      }
    }
    Transform {
      translation 0 0 0.02
      rotation 0 0 1 -1.570796
      children [
        Shape {
          appearance PBRAppearance {
            baseColor 0.015 0.48 0.1796
            roughness 0.4
            metalness 0
          }
          geometry Cylinder {
            height 0.0015
            radius 0.028
          }
        }
      ]
    }
    DEF LS0 LightSensor {
      translation 0.00215188 0.0227638 0.0144
      rotation 0.5102819257784789 0.6081179115480401 0.6081159115483309 2.19792
      name "ls0"
      lookupTable [
        0 0 0
        4 1024 0
      ]
    }
    DEF LS1 LightSensor {
      translation 0.0139291 0.0114289 0.0144
      rotation 0.6776599336428648 0.5199889490821645 0.5199889490821645 1.95044
      name "ls1"
      lookupTable [
        0 0 0
        4 1024 0
      ]
    }
    DEF LS2 LightSensor {
      translation 0.0123588 -0.0225 0.0144
      rotation -0.5773509358554485 0.5773489358556708 0.5773509358554485 -2.094395307179586
      name "ls2"
      lookupTable [
        0 0 0
        4 1024 0
      ]
    }
    DEF LS3 LightSensor {
      translation -0.00166025 -0.00785883 0.0144
      rotation -0.1861570160863869 0.6947460600350939 0.6947470600351803 -2.7734953071795863
      name "ls3"
      lookupTable [
        0 0 0
        4 1024 0
      ]
    }
    DEF LS4 LightSensor {
      translation -0.0072844 0.00978409 0.0144
      rotation 0.2810839910810645 0.6785979784677472 0.6785989784677153 2.59357
      name "ls4"
      lookupTable [
        0 0 0
        4 1024 0
      ]
    }
    DEF LS5 LightSensor {
      translation -0.0103523 -0.0251114 0.0144
      rotation -0.8053168807607647 0.4192049379304254 0.4192039379305735 -1.7856453071795864
      name "ls5"
      lookupTable [
        0 0 0
        4 1024 0
      ]
    }
    DEF LS6 LightSensor {
      translation -0.0163407 -0.00641179 0.0144
      rotation -0.09269154676500942 0.7040625956398727 0.7040625956398727 -2.9567353071795863
      name "ls6"
      lookupTable [
        0 0 0
        4 1024 0
      ]
    }
    DEF LS7 LightSensor {
      translation -0.016 0.00899998 0.0144
      rotation 0 -0.7071067811865476 -0.7071067811865476 -3.14159
      name "ls7"
      lookupTable [
        0 0 0
        4 1024 0
      ]
    }
    DEF LED0 LED {
      translation 0.042 -0.003 0.021
      rotation 0.5773502691896258 -0.5773502691896258 -0.5773502691896258 2.094395
      children [
        PointLight {
          attenuation 0 0 12.56
          color 1 0 0
          intensity 0.25
          on FALSE
          radius 10
        }
        Shape {
          appearance PBRAppearance {
            baseColor 0.501961 0.501961 0.501961
            metalness 0
            emissiveIntensity 7
          }
          geometry Box {
            size 0.002 0.002 0.002
          }
        }
      ]
      name "led0"
    }
    DEF LED1 LED {
      translation 0.024 -0.01 0.021
      rotation 0.5773502691896258 -0.5773502691896258 -0.5773502691896258 2.094395
      children [
        Shape {
          appearance PBRAppearance {
            baseColor 0.501961 0.501961 0.501961
            metalness 0
          }
          geometry Box {
            size 0.002 0.002 0.002
          }
        }
      ]
      name "led1"
    }
    DEF RS232_OUT Emitter {
      name "rs232_out"
      type "serial"
      range 1000
      baudRate 57600
    }
    DEF RS232_IN Receiver {
      name "rs232_in"
      type "serial"
      baudRate 57600
    }
  ]
  name "k0(2)"
  model "Khepera"
  description "A mini mobile robot by K-Team SA"
  contactMaterial "khepera"
  boundingObject Transform {
    translation 0 0 0.012
    rotation 0 0 1 -1.570796
    children [
      Cylinder {
        height 0.02
        radius 0.0285
      }
    ]
  }
  physics Physics {
    centerOfMass [
      0 0 0.005
    ]
  }
  controller "updated_generalized_ga_learning"
  supervisor TRUE
}
DEF khepera Robot {
  translation -0.10022799639821971 0.1003780057134175 2.739889981758295e-06
  rotation 0.03505831200360731 -0.07082879699305072 0.9968722065921864 0.9216261582643216
  children [
    Emitter {
      name "emitter_processor"
    }
    Receiver {
      name "receiver_processor"
      channel 29
    }
    GPS {
      name "gps(1)"
    }
    Group {
      children [
        DistanceSensor {
          translation 0 0 0.02
          rotation 0 0 1 -0.523
          name "distance sensor right"
        }
        DistanceSensor {
          translation 0 0 0.02
          rotation 0 0 1 0.523
          name "distance sensor left"
        }
        LightSensor {
          translation -0.02 5.30722e-08 0
          rotation 0 0 1 3.14159
          lookupTable [
            0 0 0
            4 1024 0
          ]
        }
        LED {
          translation 0.04 0 0
          recognitionColors [
            0 0 0
          ]
        }
        TouchSensor {
        }
        GPS {
        }
        DistanceSensor {
          translation 0 0 0.02
          rotation 0 1 0 0
        }
        InertialUnit {
        }
        Receiver {
          channel 1
        }
        Emitter {
          channel 2
        }
        DEF LIFT_HINGE_JOINT HingeJoint {
          jointParameters HingeJointParameters {
            position -1.3999963450018997
            axis 0 1 0
            anchor -0.01 0 0.022
          }
          device [
            RotationalMotor {
              name "motor"
            }
          ]
          endPoint Solid {
            translation -0.010000272344832877 2.437851864822667e-09 0.021999275509451743
            rotation 0.7058147871033154 -0.7058147871032284 -0.060423278732008985 3.0208927321362125
            children [
              DEF RIGHT_GRIP SliderJoint {
                jointParameters JointParameters {
                  position 0.00016830205045683218
                  axis 1 0 0
                }
                device [
                  LinearMotor {
                    name "right grip"
                    maxVelocity 0.1
                    minPosition -6.244776062687065e-14
                    maxPosition 0.029
                    maxForce 100
                  }
                ]
                endPoint Solid {
                  translation 0.000168302050833346 0 -0.048
                  rotation 0 1 0 1.5708
                  children [
                    Shape {
                      appearance PBRAppearance {
                        baseColor 0.8 0.8 0.8
                        roughness 1
                        metalness 0
                      }
                      geometry IndexedFaceSet {
                        coord Coordinate {
                          point [
                            0 -0.004 0.004
                            0.03 -0.004 0.002
                            0.03 -0.004 0.0001
                            0 -0.004 0.0001
                            0 -0.004 0.004
                            0 0.004 0.004
                            0.03 0.004 0.002
                            0.03 0.004 0.0001
                            0 0.004 0.0001
                            0 0.004 0.004
                          ]
                        }
                        coordIndex [
                          4, 3, 2, 1, 0, -1, 5, 6, 7, 8, 9, -1, 0, 1, 6, 5, -1, 1, 2, 7, 6, -1, 2, 3, 8, 7, -1, 3, 4, 9, 8, -1
                        ]
                      }
                    }
                    DistanceSensor {
                      translation 0.015 0 0
                      rotation 0 1 0 1.5708
                      name "ds"
                      lookupTable [
                        0 0 0
                        0.05 1000 0
                      ]
                      type "infra-red"
                    }
                  ]
                  name "right grip"
                  contactMaterial "gripper"
                  boundingObject Transform {
                    translation 0.015 0 0.003
                    children [
                      Box {
                        size 0.028 0.007 0.005
                      }
                    ]
                  }
                  physics Physics {
                    density 100
                    centerOfMass [
                      0.01 0 0
                    ]
                  }
                }
              }
              DEF LEFT_GRIP SliderJoint {
                jointParameters JointParameters {
                  position -0.00016830672719644158
                  axis -1 0 0
                }
                device [
                  LinearMotor {
                    name "left grip"
                    maxVelocity 0.1
                    minPosition -0.00016864583241887318
                    maxPosition 0.029
                    maxForce 100
                  }
                ]
                endPoint Solid {
                  translation 0.00016830672757295562 0 -0.048
                  rotation 0 1 0 -1.5708
                  children [
                    Shape {
                      appearance PBRAppearance {
                        baseColor 0.8 0.8 0.8
                        roughness 1
                        metalness 0
                      }
                      geometry IndexedFaceSet {
                        coord Coordinate {
                          point [
                            0 -0.004 0.0001
                            -0.03 -0.004 0.0001
                            -0.03 -0.004 0.002
                            0 -0.004 0.004
                            0 -0.004 0.0001
                            0 0.004 0.0001
                            -0.03 0.004 0.0001
                            -0.03 0.004 0.002
                            0 0.004 0.004
                            0 0.004 0.0001
                          ]
                        }
                        coordIndex [
                          4, 3, 2, 1, 0, -1, 5, 6, 7, 8, 9, -1, 0, 1, 6, 5, -1, 1, 2, 7, 6, -1, 2, 3, 8, 7, -1, 3, 4, 9, 8, -1
                        ]
                      }
                    }
                  ]
                  name "left grip"
                  contactMaterial "gripper"
                  boundingObject Transform {
                    translation -0.015 0 0.003
                    children [
                      Box {
                        size 0.028 0.007 0.005
                      }
                    ]
                  }
                  physics Physics {
                    density 100
                    centerOfMass [
                      -0.01 0 0
                    ]
                  }
                }
              }
              Shape {
                appearance PBRAppearance {
                  baseColor 0.8 0.8 0.8
                  roughness 1
                  metalness 0
                }
                geometry IndexedFaceSet {
                  coord Coordinate {
                    point [
                      0.035 -0.004 0.006
                      0.035 -0.004 -0.048
                      -0.035 -0.004 -0.048
                      -0.035 -0.004 0.006
                      -0.025 -0.004 0.006
                      -0.025 -0.004 -0.03
                      -0.016 -0.004 -0.04
                      0.016 -0.004 -0.04
                      0.025 -0.004 -0.03
                      0.025 -0.004 0.006
                      0.035 -0.004 0.006
                      0.035 0.004 0.006
                      0.035 0.004 -0.048
                      -0.035 0.004 -0.048
                      -0.035 0.004 0.006
                      -0.025 0.004 0.006
                      -0.025 0.004 -0.03
                      -0.016 0.004 -0.04
                      0.016 0.004 -0.04
                      0.025 0.004 -0.03
                      0.025 0.004 0.006
                      0.035 0.004 0.006
                    ]
                  }
                  coordIndex [
                    10, 9, 8, 7, 6, 5, 4, 3, 2, 1, 0, -1, 11, 12, 13, 14, 15, 16, 17, 18, 19, 20, 21, -1, 0, 1, 12, 11, -1, 1, 2, 13, 12, -1, 2, 3, 14, 13, -1, 3, 4, 15, 14, -1, 4, 5, 16, 15, -1, 5, 6, 17, 16, -1, 6, 7, 18, 17, -1, 7, 8, 19, 18, -1, 8, 9, 20, 19, -1, 9, 10, 21, 20, -1
                  ]
                }
              }
            ]
            boundingObject Transform {
              translation 0 0 -0.021
              children [
                Box {
                  size 0.068 0.008 0.052
                }
              ]
            }
            physics Physics {
              density 100
              centerOfMass [
                0 0 -0.02
              ]
            }
          }
        }
        DEF GRIPPER_BASE Transform {
          translation -0.01 0 0.023
          rotation 0.5773502691896258 -0.5773502691896258 -0.5773502691896258 2.094395
          children [
            Shape {
              appearance PBRAppearance {
                baseColor 0.8 0.8 0.8
                roughness 1
                metalness 0
              }
              geometry Box {
                size 0.05 0.01 0.01
              }
            }
          ]
        }
        Camera {
          translation -0.01 0 0.035
          rotation -0.999759341318827 -0.016153505514822745 -0.014843305067519018 -5.307179586466759e-06
          children [
            Shape {
              appearance PBRAppearance {
                baseColor 0.70632 0.70632 0.70632
                roughness 1
                metalness 0
              }
              geometry DEF CAMERA Box {
                size 0.03 0.03 0.02
              }
            }
          ]
          boundingObject DEF CAMERA Box {
            size 0.03 0.03 0.02
          }
          physics Physics {
            density -1
            mass 0.02
          }
          fieldOfView 0.3
          recognition Recognition {
            maxRange 50
          }
        }
      ]
    }
    Shape {
      appearance PBRAppearance {
        baseColor 0.0539951 0.505576 0.0897663
        roughness 0.4
        metalness 0
      }
      geometry IndexedFaceSet {
        coord Coordinate {
          point [
            0.009 -0.0276 0.0025, 0.0194 -0.0215 0.0025, 0.0265 -0.0118 0.0025, 0.029 0 0.0025, 0.0265 0.0118 0.0025, 0.0194 0.0215 0.0025, 0.009 0.0276 0.0025, 0.009 0.0236 0.02, -0.009 0.0236 0.02, -0.009 -0.0236 0.02, 0.009 -0.0236 0.02, -0.009 0.0276 0.0025, -0.0194 0.0215 0.0025, -0.0265 0.0118 0.0025, -0.029 0 0.0025, -0.0265 -0.0118 0.0025, -0.0194 -0.0215 0.0025, -0.009 -0.0276 0.0025, 0.009 -0.0276 0.001, 0.0194 -0.0215 0.001, 0.0265 -0.0118 0.001, 0.029 0 0.001, 0.0265 0.0118 0.001, 0.0194 0.0215 0.001, 0.009 0.0276 0.001, 0.009 0.0236 0.001, -0.009 0.0236 0.001, -0.009 -0.0236 0.001, 0.009 -0.0236 0.001, -0.009 0.0276 0.001, -0.0194 0.0215 0.001, -0.0265 0.0118 0.001, -0.029 0 0.001, -0.0265 -0.0118 0.001, -0.0194 -0.0215 0.001, -0.009 -0.0276 0.001
          ]
        }
        coordIndex [
          0, 1, 2, 3, 4, 5, 6, -1, 11, 12, 13, 14, 15, 16, 17, -1, 24, 23, 22, 21, 20, 19, 18, -1, 35, 34, 33, 32, 31, 30, 29, -1, 1, 0, 18, 19, -1, 2, 1, 19, 20, -1, 3, 2, 20, 21, -1, 4, 3, 21, 22, -1, 5, 4, 22, 23, -1, 6, 5, 23, 24, -1, 0, 6, 24, 18, -1, 17, 16, 34, 35, -1, 16, 15, 33, 34, -1, 15, 14, 32, 33, -1, 14, 13, 31, 32, -1, 13, 12, 30, 31, -1, 12, 11, 29, 30, -1, 11, 17, 35, 29, -1, 7, 10, 28, 25, -1, 9, 8, 26, 27, -1, 8, 7, 25, 26, -1, 10, 9, 27, 28, -1, 28, 27, 26, 25, -1
        ]
        creaseAngle 0.5
      }
    }
    HingeJoint {
      jointParameters HingeJointParameters {
        position -44.05907833376403
        axis 0 1 0
        anchor 0 0 0.0075
      }
      device [
        RotationalMotor {
          name "left wheel motor"
        }
        PositionSensor {
          name "left wheel sensor"
          resolution 0.0314
        }
      ]
      endPoint Solid {
        translation 0 0.02599999999999993 0.0075
        rotation 0.6411333141046018 -0.6411333100516461 0.42177737289649603 3.9398686124887154
        children [
          DEF WHEEL Transform {
            rotation 0.5773869352700204 -0.5773319352761864 0.5773319352761864 -2.094339
            children [
              Shape {
                appearance PBRAppearance {
                  baseColor 0.778497 0.793743 0.8
                  roughness 0.3
                  metalness 0
                }
                geometry Cylinder {
                  height 0.003
                  radius 0.0075
                }
              }
            ]
          }
        ]
        name "left wheel"
        boundingObject USE WHEEL
        physics Physics {
        }
      }
    }
    HingeJoint {
      jointParameters HingeJointParameters {
        position 160.93913794893928
        axis 0 1 0
        anchor 0 0 0.0075
      }
      device [
        RotationalMotor {
          name "right wheel motor"
        }
        PositionSensor {
          name "right wheel sensor"
          resolution 0.0314
        }
      ]
      endPoint Solid {
        translation 0 -0.02599999999999968 0.0075
        rotation 0.207408577100185 -0.2074083914733087 -0.9560143520322965 1.6157635910617274
        children [
          USE WHEEL
        ]
        name "right wheel"
        boundingObject USE WHEEL
        physics Physics {
        }
      }
    }
    Transform {
      translation 0 0 0.02
      rotation 0 0 1 -1.570796
      children [
        Shape {
          appearance PBRAppearance {
            baseColor 0.015 0.48 0.1796
            roughness 0.4
            metalness 0
          }
          geometry Cylinder {
            height 0.0015
            radius 0.028
          }
        }
      ]
    }
    DEF LS0 LightSensor {
      translation 0.00215188 0.0227638 0.0144
      rotation 0.5102819257784789 0.6081179115480401 0.6081159115483309 2.19792
      name "ls0"
      lookupTable [
        0 0 0
        4 1024 0
      ]
    }
    DEF LS1 LightSensor {
      translation 0.0139291 0.0114289 0.0144
      rotation 0.6776599336428648 0.5199889490821645 0.5199889490821645 1.95044
      name "ls1"
      lookupTable [
        0 0 0
        4 1024 0
      ]
    }
    DEF LS2 LightSensor {
      translation 0.0123588 -0.0225 0.0144
      rotation -0.5773509358554485 0.5773489358556708 0.5773509358554485 -2.094395307179586
      name "ls2"
      lookupTable [
        0 0 0
        4 1024 0
      ]
    }
    DEF LS3 LightSensor {
      translation -0.00166025 -0.00785883 0.0144
      rotation -0.1861570160863869 0.6947460600350939 0.6947470600351803 -2.7734953071795863
      name "ls3"
      lookupTable [
        0 0 0
        4 1024 0
      ]
    }
    DEF LS4 LightSensor {
      translation -0.0072844 0.00978409 0.0144
      rotation 0.2810839910810645 0.6785979784677472 0.6785989784677153 2.59357
      name "ls4"
      lookupTable [
        0 0 0
        4 1024 0
      ]
    }
    DEF LS5 LightSensor {
      translation -0.0103523 -0.0251114 0.0144
      rotation -0.8053168807607647 0.4192049379304254 0.4192039379305735 -1.7856453071795864
      name "ls5"
      lookupTable [
        0 0 0
        4 1024 0
      ]
    }
    DEF LS6 LightSensor {
      translation -0.0163407 -0.00641179 0.0144
      rotation -0.09269154676500942 0.7040625956398727 0.7040625956398727 -2.9567353071795863
      name "ls6"
      lookupTable [
        0 0 0
        4 1024 0
      ]
    }
    DEF LS7 LightSensor {
      translation -0.016 0.00899998 0.0144
      rotation 0 -0.7071067811865476 -0.7071067811865476 -3.14159
      name "ls7"
      lookupTable [
        0 0 0
        4 1024 0
      ]
    }
    DEF LED0 LED {
      translation 0.042 -0.003 0.021
      rotation 0.5773502691896258 -0.5773502691896258 -0.5773502691896258 2.094395
      children [
        PointLight {
          attenuation 0 0 12.56
          color 1 0 0
          intensity 0.25
          on FALSE
          radius 10
        }
        Shape {
          appearance PBRAppearance {
            baseColor 0.501961 0.501961 0.501961
            metalness 0
            emissiveIntensity 7
          }
          geometry Box {
            size 0.002 0.002 0.002
          }
        }
      ]
      name "led0"
    }
    DEF LED1 LED {
      translation 0.024 -0.01 0.021
      rotation 0.5773502691896258 -0.5773502691896258 -0.5773502691896258 2.094395
      children [
        Shape {
          appearance PBRAppearance {
            baseColor 0.501961 0.501961 0.501961
            metalness 0
          }
          geometry Box {
            size 0.002 0.002 0.002
          }
        }
      ]
      name "led1"
    }
    DEF RS232_OUT Emitter {
      name "rs232_out"
      type "serial"
      range 1000
      baudRate 57600
    }
    DEF RS232_IN Receiver {
      name "rs232_in"
      type "serial"
      baudRate 57600
    }
  ]
  name "k0(3)"
  model "Khepera"
  description "A mini mobile robot by K-Team SA"
  contactMaterial "khepera"
  boundingObject Transform {
    translation 0 0 0.012
    rotation 0 0 1 -1.570796
    children [
      Cylinder {
        height 0.02
        radius 0.0285
      }
    ]
  }
  physics Physics {
    centerOfMass [
      0 0 0.005
    ]
  }
  controller "updated_generalized_ga_learning"
  supervisor TRUE
}
DEF khepera Robot {
  translation -0.13619432312834726 -0.02516739149974009 2.909076457332377e-06
  rotation 0.03491087765481438 -0.11551545970153956 0.9926920011722229 0.5909917293891818
  children [
    Emitter {
      name "emitter_processor"
    }
    Receiver {
      name "receiver_processor"
      channel 39
    }
    GPS {
      name "gps(1)"
    }
    Group {
      children [
        DistanceSensor {
          translation 0 0 0.02
          rotation 0 0 1 -0.523
          name "distance sensor right"
        }
        DistanceSensor {
          translation 0 0 0.02
          rotation 0 0 1 0.523
          name "distance sensor left"
        }
        LightSensor {
          translation -0.02 5.30722e-08 0
          rotation 0 0 1 3.14159
          lookupTable [
            0 0 0
            4 1024 0
          ]
        }
        LED {
          translation 0.04 0 0
          recognitionColors [
            0 0 0
          ]
        }
        TouchSensor {
        }
        GPS {
        }
        DistanceSensor {
          translation 0 0 0.02
          rotation 0 1 0 0
        }
        InertialUnit {
        }
        Receiver {
          channel 1
        }
        Emitter {
          channel 2
        }
        DEF LIFT_HINGE_JOINT HingeJoint {
          jointParameters HingeJointParameters {
            position -1.3999972819099524
            axis 0 1 0
            anchor -0.01 0 0.022
          }
          device [
            RotationalMotor {
              name "motor"
            }
          ]
          endPoint Solid {
            translation -0.010000272344154095 2.4378518648226717e-09 0.021999275509196576
            rotation 0.7058148013076984 -0.7058148013076376 -0.06042294688306821 3.0208933934197773
            children [
              DEF RIGHT_GRIP SliderJoint {
                jointParameters JointParameters {
                  position 0.00017033253042265855
                  axis 1 0 0
                }
                device [
                  LinearMotor {
                    name "right grip"
                    maxVelocity 0.1
                    minPosition -6.244776062687065e-14
                    maxPosition 0.029
                    maxForce 100
                  }
                ]
                endPoint Solid {
                  translation 0.00017033253079917237 0 -0.048
                  rotation 0 1 0 1.5708
                  children [
                    Shape {
                      appearance PBRAppearance {
                        baseColor 0.8 0.8 0.8
                        roughness 1
                        metalness 0
                      }
                      geometry IndexedFaceSet {
                        coord Coordinate {
                          point [
                            0 -0.004 0.004
                            0.03 -0.004 0.002
                            0.03 -0.004 0.0001
                            0 -0.004 0.0001
                            0 -0.004 0.004
                            0 0.004 0.004
                            0.03 0.004 0.002
                            0.03 0.004 0.0001
                            0 0.004 0.0001
                            0 0.004 0.004
                          ]
                        }
                        coordIndex [
                          4, 3, 2, 1, 0, -1, 5, 6, 7, 8, 9, -1, 0, 1, 6, 5, -1, 1, 2, 7, 6, -1, 2, 3, 8, 7, -1, 3, 4, 9, 8, -1
                        ]
                      }
                    }
                    DistanceSensor {
                      translation 0.015 0 0
                      rotation 0 1 0 1.5708
                      name "ds"
                      lookupTable [
                        0 0 0
                        0.05 1000 0
                      ]
                      type "infra-red"
                    }
                  ]
                  name "right grip"
                  contactMaterial "gripper"
                  boundingObject Transform {
                    translation 0.015 0 0.003
                    children [
                      Box {
                        size 0.028 0.007 0.005
                      }
                    ]
                  }
                  physics Physics {
                    density 100
                    centerOfMass [
                      0.01 0 0
                    ]
                  }
                }
              }
              DEF LEFT_GRIP SliderJoint {
                jointParameters JointParameters {
                  position -0.00017033725561122135
                  axis -1 0 0
                }
                device [
                  LinearMotor {
                    name "left grip"
                    maxVelocity 0.1
                    minPosition -0.0001703126385176941
                    maxPosition 0.029
                    maxForce 100
                  }
                ]
                endPoint Solid {
                  translation 0.00017033725598773538 0 -0.048
                  rotation 0 1 0 -1.5708
                  children [
                    Shape {
                      appearance PBRAppearance {
                        baseColor 0.8 0.8 0.8
                        roughness 1
                        metalness 0
                      }
                      geometry IndexedFaceSet {
                        coord Coordinate {
                          point [
                            0 -0.004 0.0001
                            -0.03 -0.004 0.0001
                            -0.03 -0.004 0.002
                            0 -0.004 0.004
                            0 -0.004 0.0001
                            0 0.004 0.0001
                            -0.03 0.004 0.0001
                            -0.03 0.004 0.002
                            0 0.004 0.004
                            0 0.004 0.0001
                          ]
                        }
                        coordIndex [
                          4, 3, 2, 1, 0, -1, 5, 6, 7, 8, 9, -1, 0, 1, 6, 5, -1, 1, 2, 7, 6, -1, 2, 3, 8, 7, -1, 3, 4, 9, 8, -1
                        ]
                      }
                    }
                  ]
                  name "left grip"
                  contactMaterial "gripper"
                  boundingObject Transform {
                    translation -0.015 0 0.003
                    children [
                      Box {
                        size 0.028 0.007 0.005
                      }
                    ]
                  }
                  physics Physics {
                    density 100
                    centerOfMass [
                      -0.01 0 0
                    ]
                  }
                }
              }
              Shape {
                appearance PBRAppearance {
                  baseColor 0.8 0.8 0.8
                  roughness 1
                  metalness 0
                }
                geometry IndexedFaceSet {
                  coord Coordinate {
                    point [
                      0.035 -0.004 0.006
                      0.035 -0.004 -0.048
                      -0.035 -0.004 -0.048
                      -0.035 -0.004 0.006
                      -0.025 -0.004 0.006
                      -0.025 -0.004 -0.03
                      -0.016 -0.004 -0.04
                      0.016 -0.004 -0.04
                      0.025 -0.004 -0.03
                      0.025 -0.004 0.006
                      0.035 -0.004 0.006
                      0.035 0.004 0.006
                      0.035 0.004 -0.048
                      -0.035 0.004 -0.048
                      -0.035 0.004 0.006
                      -0.025 0.004 0.006
                      -0.025 0.004 -0.03
                      -0.016 0.004 -0.04
                      0.016 0.004 -0.04
                      0.025 0.004 -0.03
                      0.025 0.004 0.006
                      0.035 0.004 0.006
                    ]
                  }
                  coordIndex [
                    10, 9, 8, 7, 6, 5, 4, 3, 2, 1, 0, -1, 11, 12, 13, 14, 15, 16, 17, 18, 19, 20, 21, -1, 0, 1, 12, 11, -1, 1, 2, 13, 12, -1, 2, 3, 14, 13, -1, 3, 4, 15, 14, -1, 4, 5, 16, 15, -1, 5, 6, 17, 16, -1, 6, 7, 18, 17, -1, 7, 8, 19, 18, -1, 8, 9, 20, 19, -1, 9, 10, 21, 20, -1
                  ]
                }
              }
            ]
            boundingObject Transform {
              translation 0 0 -0.021
              children [
                Box {
                  size 0.068 0.008 0.052
                }
              ]
            }
            physics Physics {
              density 100
              centerOfMass [
                0 0 -0.02
              ]
            }
          }
        }
        DEF GRIPPER_BASE Transform {
          translation -0.01 0 0.023
          rotation 0.5773502691896258 -0.5773502691896258 -0.5773502691896258 2.094395
          children [
            Shape {
              appearance PBRAppearance {
                baseColor 0.8 0.8 0.8
                roughness 1
                metalness 0
              }
              geometry Box {
                size 0.05 0.01 0.01
              }
            }
          ]
        }
        Camera {
          translation -0.01 0 0.035
          rotation -0.999759341318827 -0.016153505514822745 -0.014843305067519018 -5.307179586466759e-06
          children [
            Shape {
              appearance PBRAppearance {
                baseColor 0.70632 0.70632 0.70632
                roughness 1
                metalness 0
              }
              geometry DEF CAMERA Box {
                size 0.03 0.03 0.02
              }
            }
          ]
          boundingObject DEF CAMERA Box {
            size 0.03 0.03 0.02
          }
          physics Physics {
            density -1
            mass 0.02
          }
          fieldOfView 0.3
          recognition Recognition {
            maxRange 50
          }
        }
      ]
    }
    Shape {
      appearance PBRAppearance {
        baseColor 0.0539951 0.505576 0.0897663
        roughness 0.4
        metalness 0
      }
      geometry IndexedFaceSet {
        coord Coordinate {
          point [
            0.009 -0.0276 0.0025, 0.0194 -0.0215 0.0025, 0.0265 -0.0118 0.0025, 0.029 0 0.0025, 0.0265 0.0118 0.0025, 0.0194 0.0215 0.0025, 0.009 0.0276 0.0025, 0.009 0.0236 0.02, -0.009 0.0236 0.02, -0.009 -0.0236 0.02, 0.009 -0.0236 0.02, -0.009 0.0276 0.0025, -0.0194 0.0215 0.0025, -0.0265 0.0118 0.0025, -0.029 0 0.0025, -0.0265 -0.0118 0.0025, -0.0194 -0.0215 0.0025, -0.009 -0.0276 0.0025, 0.009 -0.0276 0.001, 0.0194 -0.0215 0.001, 0.0265 -0.0118 0.001, 0.029 0 0.001, 0.0265 0.0118 0.001, 0.0194 0.0215 0.001, 0.009 0.0276 0.001, 0.009 0.0236 0.001, -0.009 0.0236 0.001, -0.009 -0.0236 0.001, 0.009 -0.0236 0.001, -0.009 0.0276 0.001, -0.0194 0.0215 0.001, -0.0265 0.0118 0.001, -0.029 0 0.001, -0.0265 -0.0118 0.001, -0.0194 -0.0215 0.001, -0.009 -0.0276 0.001
          ]
        }
        coordIndex [
          0, 1, 2, 3, 4, 5, 6, -1, 11, 12, 13, 14, 15, 16, 17, -1, 24, 23, 22, 21, 20, 19, 18, -1, 35, 34, 33, 32, 31, 30, 29, -1, 1, 0, 18, 19, -1, 2, 1, 19, 20, -1, 3, 2, 20, 21, -1, 4, 3, 21, 22, -1, 5, 4, 22, 23, -1, 6, 5, 23, 24, -1, 0, 6, 24, 18, -1, 17, 16, 34, 35, -1, 16, 15, 33, 34, -1, 15, 14, 32, 33, -1, 14, 13, 31, 32, -1, 13, 12, 30, 31, -1, 12, 11, 29, 30, -1, 11, 17, 35, 29, -1, 7, 10, 28, 25, -1, 9, 8, 26, 27, -1, 8, 7, 25, 26, -1, 10, 9, 27, 28, -1, 28, 27, 26, 25, -1
        ]
        creaseAngle 0.5
      }
    }
    HingeJoint {
      jointParameters HingeJointParameters {
        position -45.67699495847473
        axis 0 1 0
        anchor 0 0 0.0075
      }
      device [
        RotationalMotor {
          name "left wheel motor"
        }
        PositionSensor {
          name "left wheel sensor"
          resolution 0.0314
        }
      ]
      endPoint Solid {
        translation 0 0.025999999999999947 0.0075
        rotation 0.1761860026231227 -0.17618590110195292 0.9684611611895325 4.680347657928592
        children [
          DEF WHEEL Transform {
            rotation 0.5773869352700204 -0.5773319352761864 0.5773319352761864 -2.094339
            children [
              Shape {
                appearance PBRAppearance {
                  baseColor 0.778497 0.793743 0.8
                  roughness 0.3
                  metalness 0
                }
                geometry Cylinder {
                  height 0.003
                  radius 0.0075
                }
              }
            ]
          }
        ]
        name "left wheel"
        boundingObject USE WHEEL
        physics Physics {
        }
      }
    }
    HingeJoint {
      jointParameters HingeJointParameters {
        position 157.16123628231517
        axis 0 1 0
        anchor 0 0 0.0075
      }
      device [
        RotationalMotor {
          name "right wheel motor"
        }
        PositionSensor {
          name "right wheel sensor"
          resolution 0.0314
        }
      ]
      endPoint Solid {
        translation 0 -0.025999999999999683 0.0075
        rotation 0.652865433078073 -0.6528654268160128 0.3841008471223743 3.875043437144071
        children [
          USE WHEEL
        ]
        name "right wheel"
        boundingObject USE WHEEL
        physics Physics {
        }
      }
    }
    Transform {
      translation 0 0 0.02
      rotation 0 0 1 -1.570796
      children [
        Shape {
          appearance PBRAppearance {
            baseColor 0.015 0.48 0.1796
            roughness 0.4
            metalness 0
          }
          geometry Cylinder {
            height 0.0015
            radius 0.028
          }
        }
      ]
    }
    DEF LS0 LightSensor {
      translation 0.00215188 0.0227638 0.0144
      rotation 0.5102819257784789 0.6081179115480401 0.6081159115483309 2.19792
      name "ls0"
      lookupTable [
        0 0 0
        4 1024 0
      ]
    }
    DEF LS1 LightSensor {
      translation 0.0139291 0.0114289 0.0144
      rotation 0.6776599336428648 0.5199889490821645 0.5199889490821645 1.95044
      name "ls1"
      lookupTable [
        0 0 0
        4 1024 0
      ]
    }
    DEF LS2 LightSensor {
      translation 0.0123588 -0.0225 0.0144
      rotation -0.5773509358554485 0.5773489358556708 0.5773509358554485 -2.094395307179586
      name "ls2"
      lookupTable [
        0 0 0
        4 1024 0
      ]
    }
    DEF LS3 LightSensor {
      translation -0.00166025 -0.00785883 0.0144
      rotation -0.1861570160863869 0.6947460600350939 0.6947470600351803 -2.7734953071795863
      name "ls3"
      lookupTable [
        0 0 0
        4 1024 0
      ]
    }
    DEF LS4 LightSensor {
      translation -0.0072844 0.00978409 0.0144
      rotation 0.2810839910810645 0.6785979784677472 0.6785989784677153 2.59357
      name "ls4"
      lookupTable [
        0 0 0
        4 1024 0
      ]
    }
    DEF LS5 LightSensor {
      translation -0.0103523 -0.0251114 0.0144
      rotation -0.8053168807607647 0.4192049379304254 0.4192039379305735 -1.7856453071795864
      name "ls5"
      lookupTable [
        0 0 0
        4 1024 0
      ]
    }
    DEF LS6 LightSensor {
      translation -0.0163407 -0.00641179 0.0144
      rotation -0.09269154676500942 0.7040625956398727 0.7040625956398727 -2.9567353071795863
      name "ls6"
      lookupTable [
        0 0 0
        4 1024 0
      ]
    }
    DEF LS7 LightSensor {
      translation -0.016 0.00899998 0.0144
      rotation 0 -0.7071067811865476 -0.7071067811865476 -3.14159
      name "ls7"
      lookupTable [
        0 0 0
        4 1024 0
      ]
    }
    DEF LED0 LED {
      translation 0.042 -0.003 0.021
      rotation 0.5773502691896258 -0.5773502691896258 -0.5773502691896258 2.094395
      children [
        PointLight {
          attenuation 0 0 12.56
          color 1 0 0
          intensity 0.25
          on FALSE
          radius 10
        }
        Shape {
          appearance PBRAppearance {
            baseColor 0.501961 0.501961 0.501961
            metalness 0
            emissiveIntensity 7
          }
          geometry Box {
            size 0.002 0.002 0.002
          }
        }
      ]
      name "led0"
    }
    DEF LED1 LED {
      translation 0.024 -0.01 0.021
      rotation 0.5773502691896258 -0.5773502691896258 -0.5773502691896258 2.094395
      children [
        Shape {
          appearance PBRAppearance {
            baseColor 0.501961 0.501961 0.501961
            metalness 0
          }
          geometry Box {
            size 0.002 0.002 0.002
          }
        }
      ]
      name "led1"
    }
    DEF RS232_OUT Emitter {
      name "rs232_out"
      type "serial"
      range 1000
      baudRate 57600
    }
    DEF RS232_IN Receiver {
      name "rs232_in"
      type "serial"
      baudRate 57600
    }
  ]
  name "k0(4)"
  model "Khepera"
  description "A mini mobile robot by K-Team SA"
  contactMaterial "khepera"
  boundingObject Transform {
    translation 0 0 0.012
    rotation 0 0 1 -1.570796
    children [
      Cylinder {
        height 0.02
        radius 0.0285
      }
    ]
  }
  physics Physics {
    centerOfMass [
      0 0 0.005
    ]
  }
  controller "updated_generalized_ga_learning"
  supervisor TRUE
}
DEF supervisor TinkerbotsBase {
  translation -0.21049522741089025 1.9966399270097264 0.02049282947867803
  rotation 2.347322820006385e-06 -8.117253673410035e-08 0.9999999999972418 -3.0724584008432774
  name "Tinkerbots(1)"
  controller "ga_individual_supervisor"
  supervisor TRUE
  extensionSlot [
    Receiver {
      name "receiver_processor"
    }
    Receiver {
      channel 5
    }
    Emitter {
      channel 1
    }
  ]
}
DEF supervisor TinkerbotsBase {
  translation -0.06824348583689883 1.9988082034078885 0.02049216191673576
  rotation 2.3473228428771365e-06 -8.577652165549714e-08 0.9999999999972413 -3.0685406052037996
  name "Tinkerbots(2)"
  controller "ga_individual_supervisor"
  supervisor TRUE
  extensionSlot [
    Receiver {
      name "receiver_processor"
      channel 10
    }
    Receiver {
      channel 5
    }
    Emitter {
      channel 1
    }
  ]
}
DEF supervisor TinkerbotsBase {
  translation -0.0015488850015993743 1.9999995391933207 0.020491848930950927
  rotation 2.3473228701244267e-06 -8.977295316071703e-08 0.9999999999972409 -3.0651402631051274
  name "Tinkerbots(3)"
  controller "ga_individual_supervisor"
  supervisor TRUE
  extensionSlot [
    Receiver {
      name "receiver_processor"
      channel 20
    }
    Receiver {
      channel 5
    }
    Emitter {
      channel 1
    }
  ]
}
DEF supervisor TinkerbotsBase {
  translation 0.06162046804040613 2.001206514271275 0.02049155248852199
  rotation 2.347322897713437e-06 -9.265582148592769e-08 0.9999999999972408 -3.062687663541654
  name "Tinkerbots(4)"
  controller "ga_individual_supervisor"
  supervisor TRUE
  extensionSlot [
    Receiver {
      name "receiver_processor"
      channel 30
    }
    Receiver {
      channel 5
    }
    Emitter {
      channel 1
    }
  ]
}
DEF supervisor TinkerbotsBase {
  translation 0.20152331756713862 2.003398386830474 0.0204908959496314
  rotation 2.347322933741208e-06 -9.411354466817301e-08 0.9999999999972407 -3.0614475988022933
  name "Tinkerbots(5)"
  controller "ga_individual_supervisor"
  supervisor TRUE
  extensionSlot [
    Receiver {
      name "receiver_processor"
      channel 40
    }
    Receiver {
      channel 5
    }
    Emitter {
      channel 1
    }
  ]
}
