#VRML_SIM R2022a utf8
WorldInfo {
  info [
    "A Khepera robot equipped with a gripper"
  ]
  title "Khepera Gripper"
  CFM 0.001
  ERP 0.4
  basicTimeStep 10
  contactProperties [
    ContactProperties {
      material1 "gripper"
      material2 "stick"
      coulombFriction [
        10
      ]
      bounceVelocity 0.5
    }
    ContactProperties {
      material1 "khepera"
      coulombFriction [
        0.1
      ]
    }
  ]
}
Viewpoint {
  orientation -0.35816140579256034 -0.18306283158551762 0.9155372232151947 4.0169578613023615
  position 1.4379960767908893 1.987554881129134 2.6606453546672695
}
TexturedBackground {
  luminosity 0.5
}
TexturedBackgroundLight {
  luminosity 0.4
}
DEF arena RectangleArena {
  translation -0.04 -0.07 0
  rotation 0 1 0 4.692820414042842e-06
  floorSize 2 2
}
DEF supervisor TinkerbotsBase {
  translation -0.41 0 0
  controller "ga_updated_supervisor"
  supervisor TRUE
  extensionSlot [
    Emitter {
      name "emitter_processor"
      channel 5
    }
    Receiver {
      channel 2
    }
    Emitter {
      channel 1
    }
  ]
}
DEF khepera Robot {
  translation 0.1 -0.01 0.02
  rotation 0.022943592634373056 -0.570393840963951 0.8210508253131588 0.11483866441582982
  children [
    Emitter {
      name "emitter_processor"
    }
    Receiver {
      name "receiver_processor"
      channel -1
    }
    GPS {
      name "gps(1)"
    }
    Group {
      children [
        DistanceSensor {
          translation 0 0 0.02
          rotation 0 0 1 -0.523
          name "distance sensor right"
        }
        DistanceSensor {
          translation 0 0 0.02
          rotation 0 0 1 0.523
          name "distance sensor left"
        }
        LightSensor {
          translation -0.02 5.30722e-08 0
          rotation 0 0 1 3.14159
          lookupTable [
            0 0 0
            4 1024 0
          ]
        }
        LED {
          translation 0.04 0 0
          recognitionColors [
            0 0 0
          ]
        }
        TouchSensor {
        }
        GPS {
        }
        DistanceSensor {
          translation 0 0 0.02
          rotation 0 1 0 0
        }
        InertialUnit {
        }
        Receiver {
          channel 1
        }
        Emitter {
          channel 2
        }
        DEF LIFT_HINGE_JOINT HingeJoint {
          jointParameters HingeJointParameters {
            position -1.3999963543450258
            axis 0 1 0
            anchor -0.01 0 0.022
          }
          device [
            RotationalMotor {
              name "motor"
            }
          ]
          endPoint Solid {
            translation -0.010000272344826108 2.43785186482267e-09 0.021999275509449197
            rotation 0.7058147872449662 -0.7058147872448792 -0.06042327542271249 3.02089273873073
            children [
              DEF RIGHT_GRIP SliderJoint {
                jointParameters JointParameters {
                  position 0.00016848702506826413
                  axis 1 0 0
                }
                device [
                  LinearMotor {
                    name "right grip"
                    maxVelocity 0.1
                    minPosition -6.244776062687065e-14
                    maxPosition 0.029
                    maxForce 100
                  }
                ]
                endPoint Solid {
                  translation 0.00016848702544477795 0 -0.048
                  rotation 0 1 0 1.5708
                  children [
                    Shape {
                      appearance PBRAppearance {
                        baseColor 0.8 0.8 0.8
                        roughness 1
                        metalness 0
                      }
                      geometry IndexedFaceSet {
                        coord Coordinate {
                          point [
                            0 -0.004 0.004
                            0.03 -0.004 0.002
                            0.03 -0.004 0.0001
                            0 -0.004 0.0001
                            0 -0.004 0.004
                            0 0.004 0.004
                            0.03 0.004 0.002
                            0.03 0.004 0.0001
                            0 0.004 0.0001
                            0 0.004 0.004
                          ]
                        }
                        coordIndex [
                          4, 3, 2, 1, 0, -1, 5, 6, 7, 8, 9, -1, 0, 1, 6, 5, -1, 1, 2, 7, 6, -1, 2, 3, 8, 7, -1, 3, 4, 9, 8, -1
                        ]
                      }
                    }
                    DistanceSensor {
                      translation 0.015 0 0
                      rotation 0 1 0 1.5708
                      name "ds"
                      lookupTable [
                        0 0 0
                        0.05 1000 0
                      ]
                      type "infra-red"
                    }
                  ]
                  name "right grip"
                  contactMaterial "gripper"
                  boundingObject Transform {
                    translation 0.015 0 0.003
                    children [
                      Box {
                        size 0.028 0.007 0.005
                      }
                    ]
                  }
                  physics Physics {
                    density 100
                    centerOfMass [
                      0.01 0 0
                    ]
                  }
                }
              }
              DEF LEFT_GRIP SliderJoint {
                jointParameters JointParameters {
                  position -0.0001684916865150082
                  axis -1 0 0
                }
                device [
                  LinearMotor {
                    name "left grip"
                    maxVelocity 0.1
                    minPosition -0.00016864583241887318
                    maxPosition 0.029
                    maxForce 100
                  }
                ]
                endPoint Solid {
                  translation 0.00016849168689152223 0 -0.048
                  rotation 0 1 0 -1.5708
                  children [
                    Shape {
                      appearance PBRAppearance {
                        baseColor 0.8 0.8 0.8
                        roughness 1
                        metalness 0
                      }
                      geometry IndexedFaceSet {
                        coord Coordinate {
                          point [
                            0 -0.004 0.0001
                            -0.03 -0.004 0.0001
                            -0.03 -0.004 0.002
                            0 -0.004 0.004
                            0 -0.004 0.0001
                            0 0.004 0.0001
                            -0.03 0.004 0.0001
                            -0.03 0.004 0.002
                            0 0.004 0.004
                            0 0.004 0.0001
                          ]
                        }
                        coordIndex [
                          4, 3, 2, 1, 0, -1, 5, 6, 7, 8, 9, -1, 0, 1, 6, 5, -1, 1, 2, 7, 6, -1, 2, 3, 8, 7, -1, 3, 4, 9, 8, -1
                        ]
                      }
                    }
                  ]
                  name "left grip"
                  contactMaterial "gripper"
                  boundingObject Transform {
                    translation -0.015 0 0.003
                    children [
                      Box {
                        size 0.028 0.007 0.005
                      }
                    ]
                  }
                  physics Physics {
                    density 100
                    centerOfMass [
                      -0.01 0 0
                    ]
                  }
                }
              }
              Shape {
                appearance PBRAppearance {
                  baseColor 0.8 0.8 0.8
                  roughness 1
                  metalness 0
                }
                geometry IndexedFaceSet {
                  coord Coordinate {
                    point [
                      0.035 -0.004 0.006
                      0.035 -0.004 -0.048
                      -0.035 -0.004 -0.048
                      -0.035 -0.004 0.006
                      -0.025 -0.004 0.006
                      -0.025 -0.004 -0.03
                      -0.016 -0.004 -0.04
                      0.016 -0.004 -0.04
                      0.025 -0.004 -0.03
                      0.025 -0.004 0.006
                      0.035 -0.004 0.006
                      0.035 0.004 0.006
                      0.035 0.004 -0.048
                      -0.035 0.004 -0.048
                      -0.035 0.004 0.006
                      -0.025 0.004 0.006
                      -0.025 0.004 -0.03
                      -0.016 0.004 -0.04
                      0.016 0.004 -0.04
                      0.025 0.004 -0.03
                      0.025 0.004 0.006
                      0.035 0.004 0.006
                    ]
                  }
                  coordIndex [
                    10, 9, 8, 7, 6, 5, 4, 3, 2, 1, 0, -1, 11, 12, 13, 14, 15, 16, 17, 18, 19, 20, 21, -1, 0, 1, 12, 11, -1, 1, 2, 13, 12, -1, 2, 3, 14, 13, -1, 3, 4, 15, 14, -1, 4, 5, 16, 15, -1, 5, 6, 17, 16, -1, 6, 7, 18, 17, -1, 7, 8, 19, 18, -1, 8, 9, 20, 19, -1, 9, 10, 21, 20, -1
                  ]
                }
              }
            ]
            boundingObject Transform {
              translation 0 0 -0.021
              children [
                Box {
                  size 0.068 0.008 0.052
                }
              ]
            }
            physics Physics {
              density 100
              centerOfMass [
                0 0 -0.02
              ]
            }
          }
        }
        DEF GRIPPER_BASE Transform {
          translation -0.01 0 0.023
          rotation 0.5773502691896258 -0.5773502691896258 -0.5773502691896258 2.094395
          children [
            Shape {
              appearance PBRAppearance {
                baseColor 0.8 0.8 0.8
                roughness 1
                metalness 0
              }
              geometry Box {
                size 0.05 0.01 0.01
              }
            }
          ]
        }
        Camera {
          translation -0.01 0 0.035
          rotation -0.999759341318827 -0.016153505514822745 -0.014843305067519018 -5.307179586466759e-06
          children [
            Shape {
              appearance PBRAppearance {
                baseColor 0.70632 0.70632 0.70632
                roughness 1
                metalness 0
              }
              geometry DEF CAMERA Box {
                size 0.03 0.03 0.02
              }
            }
          ]
          boundingObject DEF CAMERA Box {
            size 0.03 0.03 0.02
          }
          physics Physics {
            density -1
            mass 0.02
          }
          fieldOfView 0.3
          recognition Recognition {
            maxRange 50
          }
        }
      ]
    }
    Shape {
      appearance PBRAppearance {
        baseColor 0.0539951 0.505576 0.0897663
        roughness 0.4
        metalness 0
      }
      geometry IndexedFaceSet {
        coord Coordinate {
          point [
            0.009 -0.0276 0.0025, 0.0194 -0.0215 0.0025, 0.0265 -0.0118 0.0025, 0.029 0 0.0025, 0.0265 0.0118 0.0025, 0.0194 0.0215 0.0025, 0.009 0.0276 0.0025, 0.009 0.0236 0.02, -0.009 0.0236 0.02, -0.009 -0.0236 0.02, 0.009 -0.0236 0.02, -0.009 0.0276 0.0025, -0.0194 0.0215 0.0025, -0.0265 0.0118 0.0025, -0.029 0 0.0025, -0.0265 -0.0118 0.0025, -0.0194 -0.0215 0.0025, -0.009 -0.0276 0.0025, 0.009 -0.0276 0.001, 0.0194 -0.0215 0.001, 0.0265 -0.0118 0.001, 0.029 0 0.001, 0.0265 0.0118 0.001, 0.0194 0.0215 0.001, 0.009 0.0276 0.001, 0.009 0.0236 0.001, -0.009 0.0236 0.001, -0.009 -0.0236 0.001, 0.009 -0.0236 0.001, -0.009 0.0276 0.001, -0.0194 0.0215 0.001, -0.0265 0.0118 0.001, -0.029 0 0.001, -0.0265 -0.0118 0.001, -0.0194 -0.0215 0.001, -0.009 -0.0276 0.001
          ]
        }
        coordIndex [
          0, 1, 2, 3, 4, 5, 6, -1, 11, 12, 13, 14, 15, 16, 17, -1, 24, 23, 22, 21, 20, 19, 18, -1, 35, 34, 33, 32, 31, 30, 29, -1, 1, 0, 18, 19, -1, 2, 1, 19, 20, -1, 3, 2, 20, 21, -1, 4, 3, 21, 22, -1, 5, 4, 22, 23, -1, 6, 5, 23, 24, -1, 0, 6, 24, 18, -1, 17, 16, 34, 35, -1, 16, 15, 33, 34, -1, 15, 14, 32, 33, -1, 14, 13, 31, 32, -1, 13, 12, 30, 31, -1, 12, 11, 29, 30, -1, 11, 17, 35, 29, -1, 7, 10, 28, 25, -1, 9, 8, 26, 27, -1, 8, 7, 25, 26, -1, 10, 9, 27, 28, -1, 28, 27, 26, 25, -1
        ]
        creaseAngle 0.5
      }
    }
    HingeJoint {
      jointParameters HingeJointParameters {
        position -40.79907988019871
        axis 0 1 0
        anchor 0 0 0.0075
      }
      device [
        RotationalMotor {
          name "left wheel motor"
        }
        PositionSensor {
          name "left wheel sensor"
          resolution 0.0314
        }
      ]
      endPoint Solid {
        translation 0 0.02599999999999993 0.0075
        rotation 0.44664349959805866 -0.44664362268310975 -0.7752541896586609 1.8226549398058822
        children [
          DEF WHEEL Transform {
            rotation 0.5773869352700204 -0.5773319352761864 0.5773319352761864 -2.094339
            children [
              Shape {
                appearance PBRAppearance {
                  baseColor 0.778497 0.793743 0.8
                  roughness 0.3
                  metalness 0
                }
                geometry Cylinder {
                  height 0.003
                  radius 0.0075
                }
              }
            ]
          }
        ]
        name "left wheel"
        boundingObject USE WHEEL
        physics Physics {
        }
      }
    }
    HingeJoint {
      jointParameters HingeJointParameters {
        position 157.67913953102223
        axis 0 1 0
        anchor 0 0 0.0075
      }
      device [
        RotationalMotor {
          name "right wheel motor"
        }
        PositionSensor {
          name "right wheel sensor"
          resolution 0.0314
        }
      ]
      endPoint Solid {
        translation 0 -0.02599999999999969 0.0075
        rotation 0.693658755439113 -0.6936587123321641 0.1941008032140634 3.5250261327148604
        children [
          USE WHEEL
        ]
        name "right wheel"
        boundingObject USE WHEEL
        physics Physics {
        }
      }
    }
    Transform {
      translation 0 0 0.02
      rotation 0 0 1 -1.570796
      children [
        Shape {
          appearance PBRAppearance {
            baseColor 0.015 0.48 0.1796
            roughness 0.4
            metalness 0
          }
          geometry Cylinder {
            height 0.0015
            radius 0.028
          }
        }
      ]
    }
    DEF LS0 LightSensor {
      translation 0.00215188 0.0227638 0.0144
      rotation 0.5102819257784789 0.6081179115480401 0.6081159115483309 2.19792
      name "ls0"
      lookupTable [
        0 0 0
        4 1024 0
      ]
    }
    DEF LS1 LightSensor {
      translation 0.0139291 0.0114289 0.0144
      rotation 0.6776599336428648 0.5199889490821645 0.5199889490821645 1.95044
      name "ls1"
      lookupTable [
        0 0 0
        4 1024 0
      ]
    }
    DEF LS2 LightSensor {
      translation 0.0123588 -0.0225 0.0144
      rotation -0.5773509358554485 0.5773489358556708 0.5773509358554485 -2.094395307179586
      name "ls2"
      lookupTable [
        0 0 0
        4 1024 0
      ]
    }
    DEF LS3 LightSensor {
      translation -0.00166025 -0.00785883 0.0144
      rotation -0.1861570160863869 0.6947460600350939 0.6947470600351803 -2.7734953071795863
      name "ls3"
      lookupTable [
        0 0 0
        4 1024 0
      ]
    }
    DEF LS4 LightSensor {
      translation -0.0072844 0.00978409 0.0144
      rotation 0.2810839910810645 0.6785979784677472 0.6785989784677153 2.59357
      name "ls4"
      lookupTable [
        0 0 0
        4 1024 0
      ]
    }
    DEF LS5 LightSensor {
      translation -0.0103523 -0.0251114 0.0144
      rotation -0.8053168807607647 0.4192049379304254 0.4192039379305735 -1.7856453071795864
      name "ls5"
      lookupTable [
        0 0 0
        4 1024 0
      ]
    }
    DEF LS6 LightSensor {
      translation -0.0163407 -0.00641179 0.0144
      rotation -0.09269154676500942 0.7040625956398727 0.7040625956398727 -2.9567353071795863
      name "ls6"
      lookupTable [
        0 0 0
        4 1024 0
      ]
    }
    DEF LS7 LightSensor {
      translation -0.016 0.00899998 0.0144
      rotation 0 -0.7071067811865476 -0.7071067811865476 -3.14159
      name "ls7"
      lookupTable [
        0 0 0
        4 1024 0
      ]
    }
    DEF LED0 LED {
      translation 0.042 -0.003 0.021
      rotation 0.5773502691896258 -0.5773502691896258 -0.5773502691896258 2.094395
      children [
        PointLight {
          attenuation 0 0 12.56
          color 1 0 0
          intensity 0.25
          radius 10
        }
        Shape {
          appearance PBRAppearance {
            baseColor 0.501961 0.501961 0.501961
            metalness 0
            emissiveIntensity 7
          }
          geometry Box {
            size 0.002 0.002 0.002
          }
        }
      ]
      name "led0"
    }
    DEF LED1 LED {
      translation 0.024 -0.01 0.021
      rotation 0.5773502691896258 -0.5773502691896258 -0.5773502691896258 2.094395
      children [
        Shape {
          appearance PBRAppearance {
            baseColor 0.501961 0.501961 0.501961
            metalness 0
            emissiveColor 1 0 0
          }
          geometry Box {
            size 0.002 0.002 0.002
          }
        }
      ]
      name "led1"
    }
    DEF RS232_OUT Emitter {
      name "rs232_out"
      type "serial"
      range 1000
      baudRate 57600
    }
    DEF RS232_IN Receiver {
      name "rs232_in"
      type "serial"
      baudRate 57600
    }
  ]
  name "k0"
  model "Khepera"
  description "A mini mobile robot by K-Team SA"
  contactMaterial "khepera"
  boundingObject Transform {
    translation 0 0 0.012
    rotation 0 0 1 -1.570796
    children [
      Cylinder {
        height 0.02
        radius 0.0285
      }
    ]
  }
  physics Physics {
    centerOfMass [
      0 0 0.005
    ]
  }
  controller "updated_generalized_ga_controller"
  supervisor TRUE
  linearVelocity 6.222079452499797e-05 -0.0017028594671920777 0.31868755145834393
  angularVelocity 0.005279563895309555 0.0009239450834570423 0.536466098152102
}
DEF khepera Robot {
  translation -0.09 -0.09 0.02
  rotation 0.022943592634373056 -0.570393840963951 0.8210508253131588 0.11483866441582982
  children [
    Emitter {
      name "emitter_processor"
    }
    Receiver {
      name "receiver_processor"
      channel 9
    }
    GPS {
      name "gps(1)"
    }
    Group {
      children [
        DistanceSensor {
          translation 0 0 0.02
          rotation 0 0 1 -0.523
          name "distance sensor right"
        }
        DistanceSensor {
          translation 0 0 0.02
          rotation 0 0 1 0.523
          name "distance sensor left"
        }
        LightSensor {
          translation -0.02 5.30722e-08 0
          rotation 0 0 1 3.14159
          lookupTable [
            0 0 0
            4 1024 0
          ]
        }
        LED {
          translation 0.04 0 0
          recognitionColors [
            0 0 0
          ]
        }
        TouchSensor {
        }
        GPS {
        }
        DistanceSensor {
          translation 0 0 0.02
          rotation 0 1 0 0
        }
        InertialUnit {
        }
        Receiver {
          channel 1
        }
        Emitter {
          channel 2
        }
        DEF LIFT_HINGE_JOINT HingeJoint {
          jointParameters HingeJointParameters {
            position -1.3999963543450258
            axis 0 1 0
            anchor -0.01 0 0.022
          }
          device [
            RotationalMotor {
              name "motor"
            }
          ]
          endPoint Solid {
            translation -0.010000272344826108 2.43785186482267e-09 0.021999275509449197
            rotation 0.7058147872449662 -0.7058147872448792 -0.06042327542271249 3.02089273873073
            children [
              DEF RIGHT_GRIP SliderJoint {
                jointParameters JointParameters {
                  position 0.00016848702506826413
                  axis 1 0 0
                }
                device [
                  LinearMotor {
                    name "right grip"
                    maxVelocity 0.1
                    minPosition -6.244776062687065e-14
                    maxPosition 0.029
                    maxForce 100
                  }
                ]
                endPoint Solid {
                  translation 0.00016848702544477795 0 -0.048
                  rotation 0 1 0 1.5708
                  children [
                    Shape {
                      appearance PBRAppearance {
                        baseColor 0.8 0.8 0.8
                        roughness 1
                        metalness 0
                      }
                      geometry IndexedFaceSet {
                        coord Coordinate {
                          point [
                            0 -0.004 0.004
                            0.03 -0.004 0.002
                            0.03 -0.004 0.0001
                            0 -0.004 0.0001
                            0 -0.004 0.004
                            0 0.004 0.004
                            0.03 0.004 0.002
                            0.03 0.004 0.0001
                            0 0.004 0.0001
                            0 0.004 0.004
                          ]
                        }
                        coordIndex [
                          4, 3, 2, 1, 0, -1, 5, 6, 7, 8, 9, -1, 0, 1, 6, 5, -1, 1, 2, 7, 6, -1, 2, 3, 8, 7, -1, 3, 4, 9, 8, -1
                        ]
                      }
                    }
                    DistanceSensor {
                      translation 0.015 0 0
                      rotation 0 1 0 1.5708
                      name "ds"
                      lookupTable [
                        0 0 0
                        0.05 1000 0
                      ]
                      type "infra-red"
                    }
                  ]
                  name "right grip"
                  contactMaterial "gripper"
                  boundingObject Transform {
                    translation 0.015 0 0.003
                    children [
                      Box {
                        size 0.028 0.007 0.005
                      }
                    ]
                  }
                  physics Physics {
                    density 100
                    centerOfMass [
                      0.01 0 0
                    ]
                  }
                }
              }
              DEF LEFT_GRIP SliderJoint {
                jointParameters JointParameters {
                  position -0.0001684916865150082
                  axis -1 0 0
                }
                device [
                  LinearMotor {
                    name "left grip"
                    maxVelocity 0.1
                    minPosition -0.00016864583241887318
                    maxPosition 0.029
                    maxForce 100
                  }
                ]
                endPoint Solid {
                  translation 0.00016849168689152223 0 -0.048
                  rotation 0 1 0 -1.5708
                  children [
                    Shape {
                      appearance PBRAppearance {
                        baseColor 0.8 0.8 0.8
                        roughness 1
                        metalness 0
                      }
                      geometry IndexedFaceSet {
                        coord Coordinate {
                          point [
                            0 -0.004 0.0001
                            -0.03 -0.004 0.0001
                            -0.03 -0.004 0.002
                            0 -0.004 0.004
                            0 -0.004 0.0001
                            0 0.004 0.0001
                            -0.03 0.004 0.0001
                            -0.03 0.004 0.002
                            0 0.004 0.004
                            0 0.004 0.0001
                          ]
                        }
                        coordIndex [
                          4, 3, 2, 1, 0, -1, 5, 6, 7, 8, 9, -1, 0, 1, 6, 5, -1, 1, 2, 7, 6, -1, 2, 3, 8, 7, -1, 3, 4, 9, 8, -1
                        ]
                      }
                    }
                  ]
                  name "left grip"
                  contactMaterial "gripper"
                  boundingObject Transform {
                    translation -0.015 0 0.003
                    children [
                      Box {
                        size 0.028 0.007 0.005
                      }
                    ]
                  }
                  physics Physics {
                    density 100
                    centerOfMass [
                      -0.01 0 0
                    ]
                  }
                }
              }
              Shape {
                appearance PBRAppearance {
                  baseColor 0.8 0.8 0.8
                  roughness 1
                  metalness 0
                }
                geometry IndexedFaceSet {
                  coord Coordinate {
                    point [
                      0.035 -0.004 0.006
                      0.035 -0.004 -0.048
                      -0.035 -0.004 -0.048
                      -0.035 -0.004 0.006
                      -0.025 -0.004 0.006
                      -0.025 -0.004 -0.03
                      -0.016 -0.004 -0.04
                      0.016 -0.004 -0.04
                      0.025 -0.004 -0.03
                      0.025 -0.004 0.006
                      0.035 -0.004 0.006
                      0.035 0.004 0.006
                      0.035 0.004 -0.048
                      -0.035 0.004 -0.048
                      -0.035 0.004 0.006
                      -0.025 0.004 0.006
                      -0.025 0.004 -0.03
                      -0.016 0.004 -0.04
                      0.016 0.004 -0.04
                      0.025 0.004 -0.03
                      0.025 0.004 0.006
                      0.035 0.004 0.006
                    ]
                  }
                  coordIndex [
                    10, 9, 8, 7, 6, 5, 4, 3, 2, 1, 0, -1, 11, 12, 13, 14, 15, 16, 17, 18, 19, 20, 21, -1, 0, 1, 12, 11, -1, 1, 2, 13, 12, -1, 2, 3, 14, 13, -1, 3, 4, 15, 14, -1, 4, 5, 16, 15, -1, 5, 6, 17, 16, -1, 6, 7, 18, 17, -1, 7, 8, 19, 18, -1, 8, 9, 20, 19, -1, 9, 10, 21, 20, -1
                  ]
                }
              }
            ]
            boundingObject Transform {
              translation 0 0 -0.021
              children [
                Box {
                  size 0.068 0.008 0.052
                }
              ]
            }
            physics Physics {
              density 100
              centerOfMass [
                0 0 -0.02
              ]
            }
          }
        }
        DEF GRIPPER_BASE Transform {
          translation -0.01 0 0.023
          rotation 0.5773502691896258 -0.5773502691896258 -0.5773502691896258 2.094395
          children [
            Shape {
              appearance PBRAppearance {
                baseColor 0.8 0.8 0.8
                roughness 1
                metalness 0
              }
              geometry Box {
                size 0.05 0.01 0.01
              }
            }
          ]
        }
        Camera {
          translation -0.01 0 0.035
          rotation -0.999759341318827 -0.016153505514822745 -0.014843305067519018 -5.307179586466759e-06
          children [
            Shape {
              appearance PBRAppearance {
                baseColor 0.70632 0.70632 0.70632
                roughness 1
                metalness 0
              }
              geometry DEF CAMERA Box {
                size 0.03 0.03 0.02
              }
            }
          ]
          boundingObject DEF CAMERA Box {
            size 0.03 0.03 0.02
          }
          physics Physics {
            density -1
            mass 0.02
          }
          fieldOfView 0.3
          recognition Recognition {
            maxRange 50
          }
        }
      ]
    }
    Shape {
      appearance PBRAppearance {
        baseColor 0.0539951 0.505576 0.0897663
        roughness 0.4
        metalness 0
      }
      geometry IndexedFaceSet {
        coord Coordinate {
          point [
            0.009 -0.0276 0.0025, 0.0194 -0.0215 0.0025, 0.0265 -0.0118 0.0025, 0.029 0 0.0025, 0.0265 0.0118 0.0025, 0.0194 0.0215 0.0025, 0.009 0.0276 0.0025, 0.009 0.0236 0.02, -0.009 0.0236 0.02, -0.009 -0.0236 0.02, 0.009 -0.0236 0.02, -0.009 0.0276 0.0025, -0.0194 0.0215 0.0025, -0.0265 0.0118 0.0025, -0.029 0 0.0025, -0.0265 -0.0118 0.0025, -0.0194 -0.0215 0.0025, -0.009 -0.0276 0.0025, 0.009 -0.0276 0.001, 0.0194 -0.0215 0.001, 0.0265 -0.0118 0.001, 0.029 0 0.001, 0.0265 0.0118 0.001, 0.0194 0.0215 0.001, 0.009 0.0276 0.001, 0.009 0.0236 0.001, -0.009 0.0236 0.001, -0.009 -0.0236 0.001, 0.009 -0.0236 0.001, -0.009 0.0276 0.001, -0.0194 0.0215 0.001, -0.0265 0.0118 0.001, -0.029 0 0.001, -0.0265 -0.0118 0.001, -0.0194 -0.0215 0.001, -0.009 -0.0276 0.001
          ]
        }
        coordIndex [
          0, 1, 2, 3, 4, 5, 6, -1, 11, 12, 13, 14, 15, 16, 17, -1, 24, 23, 22, 21, 20, 19, 18, -1, 35, 34, 33, 32, 31, 30, 29, -1, 1, 0, 18, 19, -1, 2, 1, 19, 20, -1, 3, 2, 20, 21, -1, 4, 3, 21, 22, -1, 5, 4, 22, 23, -1, 6, 5, 23, 24, -1, 0, 6, 24, 18, -1, 17, 16, 34, 35, -1, 16, 15, 33, 34, -1, 15, 14, 32, 33, -1, 14, 13, 31, 32, -1, 13, 12, 30, 31, -1, 12, 11, 29, 30, -1, 11, 17, 35, 29, -1, 7, 10, 28, 25, -1, 9, 8, 26, 27, -1, 8, 7, 25, 26, -1, 10, 9, 27, 28, -1, 28, 27, 26, 25, -1
        ]
        creaseAngle 0.5
      }
    }
    HingeJoint {
      jointParameters HingeJointParameters {
        position -40.79907988019871
        axis 0 1 0
        anchor 0 0 0.0075
      }
      device [
        RotationalMotor {
          name "left wheel motor"
        }
        PositionSensor {
          name "left wheel sensor"
          resolution 0.0314
        }
      ]
      endPoint Solid {
        translation 0 0.02599999999999993 0.0075
        rotation 0.44664349959805866 -0.44664362268310975 -0.7752541896586609 1.8226549398058822
        children [
          DEF WHEEL Transform {
            rotation 0.5773869352700204 -0.5773319352761864 0.5773319352761864 -2.094339
            children [
              Shape {
                appearance PBRAppearance {
                  baseColor 0.778497 0.793743 0.8
                  roughness 0.3
                  metalness 0
                }
                geometry Cylinder {
                  height 0.003
                  radius 0.0075
                }
              }
            ]
          }
        ]
        name "left wheel"
        boundingObject USE WHEEL
        physics Physics {
        }
      }
    }
    HingeJoint {
      jointParameters HingeJointParameters {
        position 157.67913953102223
        axis 0 1 0
        anchor 0 0 0.0075
      }
      device [
        RotationalMotor {
          name "right wheel motor"
        }
        PositionSensor {
          name "right wheel sensor"
          resolution 0.0314
        }
      ]
      endPoint Solid {
        translation 0 -0.02599999999999969 0.0075
        rotation 0.693658755439113 -0.6936587123321641 0.1941008032140634 3.5250261327148604
        children [
          USE WHEEL
        ]
        name "right wheel"
        boundingObject USE WHEEL
        physics Physics {
        }
      }
    }
    Transform {
      translation 0 0 0.02
      rotation 0 0 1 -1.570796
      children [
        Shape {
          appearance PBRAppearance {
            baseColor 0.015 0.48 0.1796
            roughness 0.4
            metalness 0
          }
          geometry Cylinder {
            height 0.0015
            radius 0.028
          }
        }
      ]
    }
    DEF LS0 LightSensor {
      translation 0.00215188 0.0227638 0.0144
      rotation 0.5102819257784789 0.6081179115480401 0.6081159115483309 2.19792
      name "ls0"
      lookupTable [
        0 0 0
        4 1024 0
      ]
    }
    DEF LS1 LightSensor {
      translation 0.0139291 0.0114289 0.0144
      rotation 0.6776599336428648 0.5199889490821645 0.5199889490821645 1.95044
      name "ls1"
      lookupTable [
        0 0 0
        4 1024 0
      ]
    }
    DEF LS2 LightSensor {
      translation 0.0123588 -0.0225 0.0144
      rotation -0.5773509358554485 0.5773489358556708 0.5773509358554485 -2.094395307179586
      name "ls2"
      lookupTable [
        0 0 0
        4 1024 0
      ]
    }
    DEF LS3 LightSensor {
      translation -0.00166025 -0.00785883 0.0144
      rotation -0.1861570160863869 0.6947460600350939 0.6947470600351803 -2.7734953071795863
      name "ls3"
      lookupTable [
        0 0 0
        4 1024 0
      ]
    }
    DEF LS4 LightSensor {
      translation -0.0072844 0.00978409 0.0144
      rotation 0.2810839910810645 0.6785979784677472 0.6785989784677153 2.59357
      name "ls4"
      lookupTable [
        0 0 0
        4 1024 0
      ]
    }
    DEF LS5 LightSensor {
      translation -0.0103523 -0.0251114 0.0144
      rotation -0.8053168807607647 0.4192049379304254 0.4192039379305735 -1.7856453071795864
      name "ls5"
      lookupTable [
        0 0 0
        4 1024 0
      ]
    }
    DEF LS6 LightSensor {
      translation -0.0163407 -0.00641179 0.0144
      rotation -0.09269154676500942 0.7040625956398727 0.7040625956398727 -2.9567353071795863
      name "ls6"
      lookupTable [
        0 0 0
        4 1024 0
      ]
    }
    DEF LS7 LightSensor {
      translation -0.016 0.00899998 0.0144
      rotation 0 -0.7071067811865476 -0.7071067811865476 -3.14159
      name "ls7"
      lookupTable [
        0 0 0
        4 1024 0
      ]
    }
    DEF LED0 LED {
      translation 0.042 -0.003 0.021
      rotation 0.5773502691896258 -0.5773502691896258 -0.5773502691896258 2.094395
      children [
        PointLight {
          attenuation 0 0 12.56
          color 1 0 0
          intensity 0.25
          radius 10
        }
        Shape {
          appearance PBRAppearance {
            baseColor 0.501961 0.501961 0.501961
            metalness 0
            emissiveIntensity 7
          }
          geometry Box {
            size 0.002 0.002 0.002
          }
        }
      ]
      name "led0"
    }
    DEF LED1 LED {
      translation 0.024 -0.01 0.021
      rotation 0.5773502691896258 -0.5773502691896258 -0.5773502691896258 2.094395
      children [
        Shape {
          appearance PBRAppearance {
            baseColor 0.501961 0.501961 0.501961
            metalness 0
            emissiveColor 1 0 0
          }
          geometry Box {
            size 0.002 0.002 0.002
          }
        }
      ]
      name "led1"
    }
    DEF RS232_OUT Emitter {
      name "rs232_out"
      type "serial"
      range 1000
      baudRate 57600
    }
    DEF RS232_IN Receiver {
      name "rs232_in"
      type "serial"
      baudRate 57600
    }
  ]
  name "k0(1)"
  model "Khepera"
  description "A mini mobile robot by K-Team SA"
  contactMaterial "khepera"
  boundingObject Transform {
    translation 0 0 0.012
    rotation 0 0 1 -1.570796
    children [
      Cylinder {
        height 0.02
        radius 0.0285
      }
    ]
  }
  physics Physics {
    centerOfMass [
      0 0 0.005
    ]
  }
  controller "updated_generalized_ga_controller"
  supervisor TRUE
  linearVelocity 6.222079452499797e-05 -0.0017028594671920777 0.31868755145834393
  angularVelocity 0.005279563895309555 0.0009239450834570423 0.536466098152102
}
DEF khepera Robot {
  translation 0.03 -0.18 0.02
  rotation 0.022943592634373056 -0.570393840963951 0.8210508253131588 0.11483866441582982
  children [
    Emitter {
      name "emitter_processor"
    }
    Receiver {
      name "receiver_processor"
      channel 19
    }
    GPS {
      name "gps(1)"
    }
    Group {
      children [
        DistanceSensor {
          translation 0 0 0.02
          rotation 0 0 1 -0.523
          name "distance sensor right"
        }
        DistanceSensor {
          translation 0 0 0.02
          rotation 0 0 1 0.523
          name "distance sensor left"
        }
        LightSensor {
          translation -0.02 5.30722e-08 0
          rotation 0 0 1 3.14159
          lookupTable [
            0 0 0
            4 1024 0
          ]
        }
        LED {
          translation 0.04 0 0
          recognitionColors [
            0 0 0
          ]
        }
        TouchSensor {
        }
        GPS {
        }
        DistanceSensor {
          translation 0 0 0.02
          rotation 0 1 0 0
        }
        InertialUnit {
        }
        Receiver {
          channel 1
        }
        Emitter {
          channel 2
        }
        DEF LIFT_HINGE_JOINT HingeJoint {
          jointParameters HingeJointParameters {
            position -1.3999963543450258
            axis 0 1 0
            anchor -0.01 0 0.022
          }
          device [
            RotationalMotor {
              name "motor"
            }
          ]
          endPoint Solid {
            translation -0.010000272344826108 2.43785186482267e-09 0.021999275509449197
            rotation 0.7058147872449662 -0.7058147872448792 -0.06042327542271249 3.02089273873073
            children [
              DEF RIGHT_GRIP SliderJoint {
                jointParameters JointParameters {
                  position 0.00016848702506826413
                  axis 1 0 0
                }
                device [
                  LinearMotor {
                    name "right grip"
                    maxVelocity 0.1
                    minPosition -6.244776062687065e-14
                    maxPosition 0.029
                    maxForce 100
                  }
                ]
                endPoint Solid {
                  translation 0.00016848702544477795 0 -0.048
                  rotation 0 1 0 1.5708
                  children [
                    Shape {
                      appearance PBRAppearance {
                        baseColor 0.8 0.8 0.8
                        roughness 1
                        metalness 0
                      }
                      geometry IndexedFaceSet {
                        coord Coordinate {
                          point [
                            0 -0.004 0.004
                            0.03 -0.004 0.002
                            0.03 -0.004 0.0001
                            0 -0.004 0.0001
                            0 -0.004 0.004
                            0 0.004 0.004
                            0.03 0.004 0.002
                            0.03 0.004 0.0001
                            0 0.004 0.0001
                            0 0.004 0.004
                          ]
                        }
                        coordIndex [
                          4, 3, 2, 1, 0, -1, 5, 6, 7, 8, 9, -1, 0, 1, 6, 5, -1, 1, 2, 7, 6, -1, 2, 3, 8, 7, -1, 3, 4, 9, 8, -1
                        ]
                      }
                    }
                    DistanceSensor {
                      translation 0.015 0 0
                      rotation 0 1 0 1.5708
                      name "ds"
                      lookupTable [
                        0 0 0
                        0.05 1000 0
                      ]
                      type "infra-red"
                    }
                  ]
                  name "right grip"
                  contactMaterial "gripper"
                  boundingObject Transform {
                    translation 0.015 0 0.003
                    children [
                      Box {
                        size 0.028 0.007 0.005
                      }
                    ]
                  }
                  physics Physics {
                    density 100
                    centerOfMass [
                      0.01 0 0
                    ]
                  }
                }
              }
              DEF LEFT_GRIP SliderJoint {
                jointParameters JointParameters {
                  position -0.0001684916865150082
                  axis -1 0 0
                }
                device [
                  LinearMotor {
                    name "left grip"
                    maxVelocity 0.1
                    minPosition -0.00016864583241887318
                    maxPosition 0.029
                    maxForce 100
                  }
                ]
                endPoint Solid {
                  translation 0.00016849168689152223 0 -0.048
                  rotation 0 1 0 -1.5708
                  children [
                    Shape {
                      appearance PBRAppearance {
                        baseColor 0.8 0.8 0.8
                        roughness 1
                        metalness 0
                      }
                      geometry IndexedFaceSet {
                        coord Coordinate {
                          point [
                            0 -0.004 0.0001
                            -0.03 -0.004 0.0001
                            -0.03 -0.004 0.002
                            0 -0.004 0.004
                            0 -0.004 0.0001
                            0 0.004 0.0001
                            -0.03 0.004 0.0001
                            -0.03 0.004 0.002
                            0 0.004 0.004
                            0 0.004 0.0001
                          ]
                        }
                        coordIndex [
                          4, 3, 2, 1, 0, -1, 5, 6, 7, 8, 9, -1, 0, 1, 6, 5, -1, 1, 2, 7, 6, -1, 2, 3, 8, 7, -1, 3, 4, 9, 8, -1
                        ]
                      }
                    }
                  ]
                  name "left grip"
                  contactMaterial "gripper"
                  boundingObject Transform {
                    translation -0.015 0 0.003
                    children [
                      Box {
                        size 0.028 0.007 0.005
                      }
                    ]
                  }
                  physics Physics {
                    density 100
                    centerOfMass [
                      -0.01 0 0
                    ]
                  }
                }
              }
              Shape {
                appearance PBRAppearance {
                  baseColor 0.8 0.8 0.8
                  roughness 1
                  metalness 0
                }
                geometry IndexedFaceSet {
                  coord Coordinate {
                    point [
                      0.035 -0.004 0.006
                      0.035 -0.004 -0.048
                      -0.035 -0.004 -0.048
                      -0.035 -0.004 0.006
                      -0.025 -0.004 0.006
                      -0.025 -0.004 -0.03
                      -0.016 -0.004 -0.04
                      0.016 -0.004 -0.04
                      0.025 -0.004 -0.03
                      0.025 -0.004 0.006
                      0.035 -0.004 0.006
                      0.035 0.004 0.006
                      0.035 0.004 -0.048
                      -0.035 0.004 -0.048
                      -0.035 0.004 0.006
                      -0.025 0.004 0.006
                      -0.025 0.004 -0.03
                      -0.016 0.004 -0.04
                      0.016 0.004 -0.04
                      0.025 0.004 -0.03
                      0.025 0.004 0.006
                      0.035 0.004 0.006
                    ]
                  }
                  coordIndex [
                    10, 9, 8, 7, 6, 5, 4, 3, 2, 1, 0, -1, 11, 12, 13, 14, 15, 16, 17, 18, 19, 20, 21, -1, 0, 1, 12, 11, -1, 1, 2, 13, 12, -1, 2, 3, 14, 13, -1, 3, 4, 15, 14, -1, 4, 5, 16, 15, -1, 5, 6, 17, 16, -1, 6, 7, 18, 17, -1, 7, 8, 19, 18, -1, 8, 9, 20, 19, -1, 9, 10, 21, 20, -1
                  ]
                }
              }
            ]
            boundingObject Transform {
              translation 0 0 -0.021
              children [
                Box {
                  size 0.068 0.008 0.052
                }
              ]
            }
            physics Physics {
              density 100
              centerOfMass [
                0 0 -0.02
              ]
            }
          }
        }
        DEF GRIPPER_BASE Transform {
          translation -0.01 0 0.023
          rotation 0.5773502691896258 -0.5773502691896258 -0.5773502691896258 2.094395
          children [
            Shape {
              appearance PBRAppearance {
                baseColor 0.8 0.8 0.8
                roughness 1
                metalness 0
              }
              geometry Box {
                size 0.05 0.01 0.01
              }
            }
          ]
        }
        Camera {
          translation -0.01 0 0.035
          rotation -0.999759341318827 -0.016153505514822745 -0.014843305067519018 -5.307179586466759e-06
          children [
            Shape {
              appearance PBRAppearance {
                baseColor 0.70632 0.70632 0.70632
                roughness 1
                metalness 0
              }
              geometry DEF CAMERA Box {
                size 0.03 0.03 0.02
              }
            }
          ]
          boundingObject DEF CAMERA Box {
            size 0.03 0.03 0.02
          }
          physics Physics {
            density -1
            mass 0.02
          }
          fieldOfView 0.3
          recognition Recognition {
            maxRange 50
          }
        }
      ]
    }
    Shape {
      appearance PBRAppearance {
        baseColor 0.0539951 0.505576 0.0897663
        roughness 0.4
        metalness 0
      }
      geometry IndexedFaceSet {
        coord Coordinate {
          point [
            0.009 -0.0276 0.0025, 0.0194 -0.0215 0.0025, 0.0265 -0.0118 0.0025, 0.029 0 0.0025, 0.0265 0.0118 0.0025, 0.0194 0.0215 0.0025, 0.009 0.0276 0.0025, 0.009 0.0236 0.02, -0.009 0.0236 0.02, -0.009 -0.0236 0.02, 0.009 -0.0236 0.02, -0.009 0.0276 0.0025, -0.0194 0.0215 0.0025, -0.0265 0.0118 0.0025, -0.029 0 0.0025, -0.0265 -0.0118 0.0025, -0.0194 -0.0215 0.0025, -0.009 -0.0276 0.0025, 0.009 -0.0276 0.001, 0.0194 -0.0215 0.001, 0.0265 -0.0118 0.001, 0.029 0 0.001, 0.0265 0.0118 0.001, 0.0194 0.0215 0.001, 0.009 0.0276 0.001, 0.009 0.0236 0.001, -0.009 0.0236 0.001, -0.009 -0.0236 0.001, 0.009 -0.0236 0.001, -0.009 0.0276 0.001, -0.0194 0.0215 0.001, -0.0265 0.0118 0.001, -0.029 0 0.001, -0.0265 -0.0118 0.001, -0.0194 -0.0215 0.001, -0.009 -0.0276 0.001
          ]
        }
        coordIndex [
          0, 1, 2, 3, 4, 5, 6, -1, 11, 12, 13, 14, 15, 16, 17, -1, 24, 23, 22, 21, 20, 19, 18, -1, 35, 34, 33, 32, 31, 30, 29, -1, 1, 0, 18, 19, -1, 2, 1, 19, 20, -1, 3, 2, 20, 21, -1, 4, 3, 21, 22, -1, 5, 4, 22, 23, -1, 6, 5, 23, 24, -1, 0, 6, 24, 18, -1, 17, 16, 34, 35, -1, 16, 15, 33, 34, -1, 15, 14, 32, 33, -1, 14, 13, 31, 32, -1, 13, 12, 30, 31, -1, 12, 11, 29, 30, -1, 11, 17, 35, 29, -1, 7, 10, 28, 25, -1, 9, 8, 26, 27, -1, 8, 7, 25, 26, -1, 10, 9, 27, 28, -1, 28, 27, 26, 25, -1
        ]
        creaseAngle 0.5
      }
    }
    HingeJoint {
      jointParameters HingeJointParameters {
        position -40.79907988019871
        axis 0 1 0
        anchor 0 0 0.0075
      }
      device [
        RotationalMotor {
          name "left wheel motor"
        }
        PositionSensor {
          name "left wheel sensor"
          resolution 0.0314
        }
      ]
      endPoint Solid {
        translation 0 0.02599999999999993 0.0075
        rotation 0.44664349959805866 -0.44664362268310975 -0.7752541896586609 1.8226549398058822
        children [
          DEF WHEEL Transform {
            rotation 0.5773869352700204 -0.5773319352761864 0.5773319352761864 -2.094339
            children [
              Shape {
                appearance PBRAppearance {
                  baseColor 0.778497 0.793743 0.8
                  roughness 0.3
                  metalness 0
                }
                geometry Cylinder {
                  height 0.003
                  radius 0.0075
                }
              }
            ]
          }
        ]
        name "left wheel"
        boundingObject USE WHEEL
        physics Physics {
        }
      }
    }
    HingeJoint {
      jointParameters HingeJointParameters {
        position 157.67913953102223
        axis 0 1 0
        anchor 0 0 0.0075
      }
      device [
        RotationalMotor {
          name "right wheel motor"
        }
        PositionSensor {
          name "right wheel sensor"
          resolution 0.0314
        }
      ]
      endPoint Solid {
        translation 0 -0.02599999999999969 0.0075
        rotation 0.693658755439113 -0.6936587123321641 0.1941008032140634 3.5250261327148604
        children [
          USE WHEEL
        ]
        name "right wheel"
        boundingObject USE WHEEL
        physics Physics {
        }
      }
    }
    Transform {
      translation 0 0 0.02
      rotation 0 0 1 -1.570796
      children [
        Shape {
          appearance PBRAppearance {
            baseColor 0.015 0.48 0.1796
            roughness 0.4
            metalness 0
          }
          geometry Cylinder {
            height 0.0015
            radius 0.028
          }
        }
      ]
    }
    DEF LS0 LightSensor {
      translation 0.00215188 0.0227638 0.0144
      rotation 0.5102819257784789 0.6081179115480401 0.6081159115483309 2.19792
      name "ls0"
      lookupTable [
        0 0 0
        4 1024 0
      ]
    }
    DEF LS1 LightSensor {
      translation 0.0139291 0.0114289 0.0144
      rotation 0.6776599336428648 0.5199889490821645 0.5199889490821645 1.95044
      name "ls1"
      lookupTable [
        0 0 0
        4 1024 0
      ]
    }
    DEF LS2 LightSensor {
      translation 0.0123588 -0.0225 0.0144
      rotation -0.5773509358554485 0.5773489358556708 0.5773509358554485 -2.094395307179586
      name "ls2"
      lookupTable [
        0 0 0
        4 1024 0
      ]
    }
    DEF LS3 LightSensor {
      translation -0.00166025 -0.00785883 0.0144
      rotation -0.1861570160863869 0.6947460600350939 0.6947470600351803 -2.7734953071795863
      name "ls3"
      lookupTable [
        0 0 0
        4 1024 0
      ]
    }
    DEF LS4 LightSensor {
      translation -0.0072844 0.00978409 0.0144
      rotation 0.2810839910810645 0.6785979784677472 0.6785989784677153 2.59357
      name "ls4"
      lookupTable [
        0 0 0
        4 1024 0
      ]
    }
    DEF LS5 LightSensor {
      translation -0.0103523 -0.0251114 0.0144
      rotation -0.8053168807607647 0.4192049379304254 0.4192039379305735 -1.7856453071795864
      name "ls5"
      lookupTable [
        0 0 0
        4 1024 0
      ]
    }
    DEF LS6 LightSensor {
      translation -0.0163407 -0.00641179 0.0144
      rotation -0.09269154676500942 0.7040625956398727 0.7040625956398727 -2.9567353071795863
      name "ls6"
      lookupTable [
        0 0 0
        4 1024 0
      ]
    }
    DEF LS7 LightSensor {
      translation -0.016 0.00899998 0.0144
      rotation 0 -0.7071067811865476 -0.7071067811865476 -3.14159
      name "ls7"
      lookupTable [
        0 0 0
        4 1024 0
      ]
    }
    DEF LED0 LED {
      translation 0.042 -0.003 0.021
      rotation 0.5773502691896258 -0.5773502691896258 -0.5773502691896258 2.094395
      children [
        PointLight {
          attenuation 0 0 12.56
          color 1 0 0
          intensity 0.25
          radius 10
        }
        Shape {
          appearance PBRAppearance {
            baseColor 0.501961 0.501961 0.501961
            metalness 0
            emissiveIntensity 7
          }
          geometry Box {
            size 0.002 0.002 0.002
          }
        }
      ]
      name "led0"
    }
    DEF LED1 LED {
      translation 0.024 -0.01 0.021
      rotation 0.5773502691896258 -0.5773502691896258 -0.5773502691896258 2.094395
      children [
        Shape {
          appearance PBRAppearance {
            baseColor 0.501961 0.501961 0.501961
            metalness 0
            emissiveColor 1 0 0
          }
          geometry Box {
            size 0.002 0.002 0.002
          }
        }
      ]
      name "led1"
    }
    DEF RS232_OUT Emitter {
      name "rs232_out"
      type "serial"
      range 1000
      baudRate 57600
    }
    DEF RS232_IN Receiver {
      name "rs232_in"
      type "serial"
      baudRate 57600
    }
  ]
  name "k0(2)"
  model "Khepera"
  description "A mini mobile robot by K-Team SA"
  contactMaterial "khepera"
  boundingObject Transform {
    translation 0 0 0.012
    rotation 0 0 1 -1.570796
    children [
      Cylinder {
        height 0.02
        radius 0.0285
      }
    ]
  }
  physics Physics {
    centerOfMass [
      0 0 0.005
    ]
  }
  controller "updated_generalized_ga_controller"
  supervisor TRUE
  linearVelocity 6.222079452499797e-05 -0.0017028594671920777 0.31868755145834393
  angularVelocity 0.005279563895309555 0.0009239450834570423 0.536466098152102
}
DEF khepera Robot {
  translation -0.1 0 0.02
  rotation 0.022943592634373056 -0.570393840963951 0.8210508253131588 0.11483866441582982
  children [
    Emitter {
      name "emitter_processor"
    }
    Receiver {
      name "receiver_processor"
      channel 29
    }
    GPS {
      name "gps(1)"
    }
    Group {
      children [
        DistanceSensor {
          translation 0 0 0.02
          rotation 0 0 1 -0.523
          name "distance sensor right"
        }
        DistanceSensor {
          translation 0 0 0.02
          rotation 0 0 1 0.523
          name "distance sensor left"
        }
        LightSensor {
          translation -0.02 5.30722e-08 0
          rotation 0 0 1 3.14159
          lookupTable [
            0 0 0
            4 1024 0
          ]
        }
        LED {
          translation 0.04 0 0
          recognitionColors [
            0 0 0
          ]
        }
        TouchSensor {
        }
        GPS {
        }
        DistanceSensor {
          translation 0 0 0.02
          rotation 0 1 0 0
        }
        InertialUnit {
        }
        Receiver {
          channel 1
        }
        Emitter {
          channel 2
        }
        DEF LIFT_HINGE_JOINT HingeJoint {
          jointParameters HingeJointParameters {
            position -1.3999963543450258
            axis 0 1 0
            anchor -0.01 0 0.022
          }
          device [
            RotationalMotor {
              name "motor"
            }
          ]
          endPoint Solid {
            translation -0.010000272344826108 2.43785186482267e-09 0.021999275509449197
            rotation 0.7058147872449662 -0.7058147872448792 -0.06042327542271249 3.02089273873073
            children [
              DEF RIGHT_GRIP SliderJoint {
                jointParameters JointParameters {
                  position 0.00016848702506826413
                  axis 1 0 0
                }
                device [
                  LinearMotor {
                    name "right grip"
                    maxVelocity 0.1
                    minPosition -6.244776062687065e-14
                    maxPosition 0.029
                    maxForce 100
                  }
                ]
                endPoint Solid {
                  translation 0.00016848702544477795 0 -0.048
                  rotation 0 1 0 1.5708
                  children [
                    Shape {
                      appearance PBRAppearance {
                        baseColor 0.8 0.8 0.8
                        roughness 1
                        metalness 0
                      }
                      geometry IndexedFaceSet {
                        coord Coordinate {
                          point [
                            0 -0.004 0.004
                            0.03 -0.004 0.002
                            0.03 -0.004 0.0001
                            0 -0.004 0.0001
                            0 -0.004 0.004
                            0 0.004 0.004
                            0.03 0.004 0.002
                            0.03 0.004 0.0001
                            0 0.004 0.0001
                            0 0.004 0.004
                          ]
                        }
                        coordIndex [
                          4, 3, 2, 1, 0, -1, 5, 6, 7, 8, 9, -1, 0, 1, 6, 5, -1, 1, 2, 7, 6, -1, 2, 3, 8, 7, -1, 3, 4, 9, 8, -1
                        ]
                      }
                    }
                    DistanceSensor {
                      translation 0.015 0 0
                      rotation 0 1 0 1.5708
                      name "ds"
                      lookupTable [
                        0 0 0
                        0.05 1000 0
                      ]
                      type "infra-red"
                    }
                  ]
                  name "right grip"
                  contactMaterial "gripper"
                  boundingObject Transform {
                    translation 0.015 0 0.003
                    children [
                      Box {
                        size 0.028 0.007 0.005
                      }
                    ]
                  }
                  physics Physics {
                    density 100
                    centerOfMass [
                      0.01 0 0
                    ]
                  }
                }
              }
              DEF LEFT_GRIP SliderJoint {
                jointParameters JointParameters {
                  position -0.0001684916865150082
                  axis -1 0 0
                }
                device [
                  LinearMotor {
                    name "left grip"
                    maxVelocity 0.1
                    minPosition -0.00016864583241887318
                    maxPosition 0.029
                    maxForce 100
                  }
                ]
                endPoint Solid {
                  translation 0.00016849168689152223 0 -0.048
                  rotation 0 1 0 -1.5708
                  children [
                    Shape {
                      appearance PBRAppearance {
                        baseColor 0.8 0.8 0.8
                        roughness 1
                        metalness 0
                      }
                      geometry IndexedFaceSet {
                        coord Coordinate {
                          point [
                            0 -0.004 0.0001
                            -0.03 -0.004 0.0001
                            -0.03 -0.004 0.002
                            0 -0.004 0.004
                            0 -0.004 0.0001
                            0 0.004 0.0001
                            -0.03 0.004 0.0001
                            -0.03 0.004 0.002
                            0 0.004 0.004
                            0 0.004 0.0001
                          ]
                        }
                        coordIndex [
                          4, 3, 2, 1, 0, -1, 5, 6, 7, 8, 9, -1, 0, 1, 6, 5, -1, 1, 2, 7, 6, -1, 2, 3, 8, 7, -1, 3, 4, 9, 8, -1
                        ]
                      }
                    }
                  ]
                  name "left grip"
                  contactMaterial "gripper"
                  boundingObject Transform {
                    translation -0.015 0 0.003
                    children [
                      Box {
                        size 0.028 0.007 0.005
                      }
                    ]
                  }
                  physics Physics {
                    density 100
                    centerOfMass [
                      -0.01 0 0
                    ]
                  }
                }
              }
              Shape {
                appearance PBRAppearance {
                  baseColor 0.8 0.8 0.8
                  roughness 1
                  metalness 0
                }
                geometry IndexedFaceSet {
                  coord Coordinate {
                    point [
                      0.035 -0.004 0.006
                      0.035 -0.004 -0.048
                      -0.035 -0.004 -0.048
                      -0.035 -0.004 0.006
                      -0.025 -0.004 0.006
                      -0.025 -0.004 -0.03
                      -0.016 -0.004 -0.04
                      0.016 -0.004 -0.04
                      0.025 -0.004 -0.03
                      0.025 -0.004 0.006
                      0.035 -0.004 0.006
                      0.035 0.004 0.006
                      0.035 0.004 -0.048
                      -0.035 0.004 -0.048
                      -0.035 0.004 0.006
                      -0.025 0.004 0.006
                      -0.025 0.004 -0.03
                      -0.016 0.004 -0.04
                      0.016 0.004 -0.04
                      0.025 0.004 -0.03
                      0.025 0.004 0.006
                      0.035 0.004 0.006
                    ]
                  }
                  coordIndex [
                    10, 9, 8, 7, 6, 5, 4, 3, 2, 1, 0, -1, 11, 12, 13, 14, 15, 16, 17, 18, 19, 20, 21, -1, 0, 1, 12, 11, -1, 1, 2, 13, 12, -1, 2, 3, 14, 13, -1, 3, 4, 15, 14, -1, 4, 5, 16, 15, -1, 5, 6, 17, 16, -1, 6, 7, 18, 17, -1, 7, 8, 19, 18, -1, 8, 9, 20, 19, -1, 9, 10, 21, 20, -1
                  ]
                }
              }
            ]
            boundingObject Transform {
              translation 0 0 -0.021
              children [
                Box {
                  size 0.068 0.008 0.052
                }
              ]
            }
            physics Physics {
              density 100
              centerOfMass [
                0 0 -0.02
              ]
            }
          }
        }
        DEF GRIPPER_BASE Transform {
          translation -0.01 0 0.023
          rotation 0.5773502691896258 -0.5773502691896258 -0.5773502691896258 2.094395
          children [
            Shape {
              appearance PBRAppearance {
                baseColor 0.8 0.8 0.8
                roughness 1
                metalness 0
              }
              geometry Box {
                size 0.05 0.01 0.01
              }
            }
          ]
        }
        Camera {
          translation -0.01 0 0.035
          rotation -0.999759341318827 -0.016153505514822745 -0.014843305067519018 -5.307179586466759e-06
          children [
            Shape {
              appearance PBRAppearance {
                baseColor 0.70632 0.70632 0.70632
                roughness 1
                metalness 0
              }
              geometry DEF CAMERA Box {
                size 0.03 0.03 0.02
              }
            }
          ]
          boundingObject DEF CAMERA Box {
            size 0.03 0.03 0.02
          }
          physics Physics {
            density -1
            mass 0.02
          }
          fieldOfView 0.3
          recognition Recognition {
            maxRange 50
          }
        }
      ]
    }
    Shape {
      appearance PBRAppearance {
        baseColor 0.0539951 0.505576 0.0897663
        roughness 0.4
        metalness 0
      }
      geometry IndexedFaceSet {
        coord Coordinate {
          point [
            0.009 -0.0276 0.0025, 0.0194 -0.0215 0.0025, 0.0265 -0.0118 0.0025, 0.029 0 0.0025, 0.0265 0.0118 0.0025, 0.0194 0.0215 0.0025, 0.009 0.0276 0.0025, 0.009 0.0236 0.02, -0.009 0.0236 0.02, -0.009 -0.0236 0.02, 0.009 -0.0236 0.02, -0.009 0.0276 0.0025, -0.0194 0.0215 0.0025, -0.0265 0.0118 0.0025, -0.029 0 0.0025, -0.0265 -0.0118 0.0025, -0.0194 -0.0215 0.0025, -0.009 -0.0276 0.0025, 0.009 -0.0276 0.001, 0.0194 -0.0215 0.001, 0.0265 -0.0118 0.001, 0.029 0 0.001, 0.0265 0.0118 0.001, 0.0194 0.0215 0.001, 0.009 0.0276 0.001, 0.009 0.0236 0.001, -0.009 0.0236 0.001, -0.009 -0.0236 0.001, 0.009 -0.0236 0.001, -0.009 0.0276 0.001, -0.0194 0.0215 0.001, -0.0265 0.0118 0.001, -0.029 0 0.001, -0.0265 -0.0118 0.001, -0.0194 -0.0215 0.001, -0.009 -0.0276 0.001
          ]
        }
        coordIndex [
          0, 1, 2, 3, 4, 5, 6, -1, 11, 12, 13, 14, 15, 16, 17, -1, 24, 23, 22, 21, 20, 19, 18, -1, 35, 34, 33, 32, 31, 30, 29, -1, 1, 0, 18, 19, -1, 2, 1, 19, 20, -1, 3, 2, 20, 21, -1, 4, 3, 21, 22, -1, 5, 4, 22, 23, -1, 6, 5, 23, 24, -1, 0, 6, 24, 18, -1, 17, 16, 34, 35, -1, 16, 15, 33, 34, -1, 15, 14, 32, 33, -1, 14, 13, 31, 32, -1, 13, 12, 30, 31, -1, 12, 11, 29, 30, -1, 11, 17, 35, 29, -1, 7, 10, 28, 25, -1, 9, 8, 26, 27, -1, 8, 7, 25, 26, -1, 10, 9, 27, 28, -1, 28, 27, 26, 25, -1
        ]
        creaseAngle 0.5
      }
    }
    HingeJoint {
      jointParameters HingeJointParameters {
        position -40.79907988019871
        axis 0 1 0
        anchor 0 0 0.0075
      }
      device [
        RotationalMotor {
          name "left wheel motor"
        }
        PositionSensor {
          name "left wheel sensor"
          resolution 0.0314
        }
      ]
      endPoint Solid {
        translation 0 0.02599999999999993 0.0075
        rotation 0.44664349959805866 -0.44664362268310975 -0.7752541896586609 1.8226549398058822
        children [
          DEF WHEEL Transform {
            rotation 0.5773869352700204 -0.5773319352761864 0.5773319352761864 -2.094339
            children [
              Shape {
                appearance PBRAppearance {
                  baseColor 0.778497 0.793743 0.8
                  roughness 0.3
                  metalness 0
                }
                geometry Cylinder {
                  height 0.003
                  radius 0.0075
                }
              }
            ]
          }
        ]
        name "left wheel"
        boundingObject USE WHEEL
        physics Physics {
        }
      }
    }
    HingeJoint {
      jointParameters HingeJointParameters {
        position 157.67913953102223
        axis 0 1 0
        anchor 0 0 0.0075
      }
      device [
        RotationalMotor {
          name "right wheel motor"
        }
        PositionSensor {
          name "right wheel sensor"
          resolution 0.0314
        }
      ]
      endPoint Solid {
        translation 0 -0.02599999999999969 0.0075
        rotation 0.693658755439113 -0.6936587123321641 0.1941008032140634 3.5250261327148604
        children [
          USE WHEEL
        ]
        name "right wheel"
        boundingObject USE WHEEL
        physics Physics {
        }
      }
    }
    Transform {
      translation 0 0 0.02
      rotation 0 0 1 -1.570796
      children [
        Shape {
          appearance PBRAppearance {
            baseColor 0.015 0.48 0.1796
            roughness 0.4
            metalness 0
          }
          geometry Cylinder {
            height 0.0015
            radius 0.028
          }
        }
      ]
    }
    DEF LS0 LightSensor {
      translation 0.00215188 0.0227638 0.0144
      rotation 0.5102819257784789 0.6081179115480401 0.6081159115483309 2.19792
      name "ls0"
      lookupTable [
        0 0 0
        4 1024 0
      ]
    }
    DEF LS1 LightSensor {
      translation 0.0139291 0.0114289 0.0144
      rotation 0.6776599336428648 0.5199889490821645 0.5199889490821645 1.95044
      name "ls1"
      lookupTable [
        0 0 0
        4 1024 0
      ]
    }
    DEF LS2 LightSensor {
      translation 0.0123588 -0.0225 0.0144
      rotation -0.5773509358554485 0.5773489358556708 0.5773509358554485 -2.094395307179586
      name "ls2"
      lookupTable [
        0 0 0
        4 1024 0
      ]
    }
    DEF LS3 LightSensor {
      translation -0.00166025 -0.00785883 0.0144
      rotation -0.1861570160863869 0.6947460600350939 0.6947470600351803 -2.7734953071795863
      name "ls3"
      lookupTable [
        0 0 0
        4 1024 0
      ]
    }
    DEF LS4 LightSensor {
      translation -0.0072844 0.00978409 0.0144
      rotation 0.2810839910810645 0.6785979784677472 0.6785989784677153 2.59357
      name "ls4"
      lookupTable [
        0 0 0
        4 1024 0
      ]
    }
    DEF LS5 LightSensor {
      translation -0.0103523 -0.0251114 0.0144
      rotation -0.8053168807607647 0.4192049379304254 0.4192039379305735 -1.7856453071795864
      name "ls5"
      lookupTable [
        0 0 0
        4 1024 0
      ]
    }
    DEF LS6 LightSensor {
      translation -0.0163407 -0.00641179 0.0144
      rotation -0.09269154676500942 0.7040625956398727 0.7040625956398727 -2.9567353071795863
      name "ls6"
      lookupTable [
        0 0 0
        4 1024 0
      ]
    }
    DEF LS7 LightSensor {
      translation -0.016 0.00899998 0.0144
      rotation 0 -0.7071067811865476 -0.7071067811865476 -3.14159
      name "ls7"
      lookupTable [
        0 0 0
        4 1024 0
      ]
    }
    DEF LED0 LED {
      translation 0.042 -0.003 0.021
      rotation 0.5773502691896258 -0.5773502691896258 -0.5773502691896258 2.094395
      children [
        PointLight {
          attenuation 0 0 12.56
          color 1 0 0
          intensity 0.25
          radius 10
        }
        Shape {
          appearance PBRAppearance {
            baseColor 0.501961 0.501961 0.501961
            metalness 0
            emissiveIntensity 7
          }
          geometry Box {
            size 0.002 0.002 0.002
          }
        }
      ]
      name "led0"
    }
    DEF LED1 LED {
      translation 0.024 -0.01 0.021
      rotation 0.5773502691896258 -0.5773502691896258 -0.5773502691896258 2.094395
      children [
        Shape {
          appearance PBRAppearance {
            baseColor 0.501961 0.501961 0.501961
            metalness 0
            emissiveColor 1 0 0
          }
          geometry Box {
            size 0.002 0.002 0.002
          }
        }
      ]
      name "led1"
    }
    DEF RS232_OUT Emitter {
      name "rs232_out"
      type "serial"
      range 1000
      baudRate 57600
    }
    DEF RS232_IN Receiver {
      name "rs232_in"
      type "serial"
      baudRate 57600
    }
  ]
  name "k0(3)"
  model "Khepera"
  description "A mini mobile robot by K-Team SA"
  contactMaterial "khepera"
  boundingObject Transform {
    translation 0 0 0.012
    rotation 0 0 1 -1.570796
    children [
      Cylinder {
        height 0.02
        radius 0.0285
      }
    ]
  }
  physics Physics {
    centerOfMass [
      0 0 0.005
    ]
  }
  controller "updated_generalized_ga_controller"
  supervisor TRUE
  linearVelocity 6.222079452499797e-05 -0.0017028594671920777 0.31868755145834393
  angularVelocity 0.005279563895309555 0.0009239450834570423 0.536466098152102
}
DEF khepera Robot {
  translation -0.1 -0.07 0.02
  rotation 0.022943592634373056 -0.570393840963951 0.8210508253131588 0.11483866441582982
  children [
    Emitter {
      name "emitter_processor"
    }
    Receiver {
      name "receiver_processor"
      channel 39
    }
    GPS {
      name "gps(1)"
    }
    Group {
      children [
        DistanceSensor {
          translation 0 0 0.02
          rotation 0 0 1 -0.523
          name "distance sensor right"
        }
        DistanceSensor {
          translation 0 0 0.02
          rotation 0 0 1 0.523
          name "distance sensor left"
        }
        LightSensor {
          translation -0.02 5.30722e-08 0
          rotation 0 0 1 3.14159
          lookupTable [
            0 0 0
            4 1024 0
          ]
        }
        LED {
          translation 0.04 0 0
          recognitionColors [
            0 0 0
          ]
        }
        TouchSensor {
        }
        GPS {
        }
        DistanceSensor {
          translation 0 0 0.02
          rotation 0 1 0 0
        }
        InertialUnit {
        }
        Receiver {
          channel 1
        }
        Emitter {
          channel 2
        }
        DEF LIFT_HINGE_JOINT HingeJoint {
          jointParameters HingeJointParameters {
            position -1.3999963543450258
            axis 0 1 0
            anchor -0.01 0 0.022
          }
          device [
            RotationalMotor {
              name "motor"
            }
          ]
          endPoint Solid {
            translation -0.010000272344826108 2.43785186482267e-09 0.021999275509449197
            rotation 0.7058147872449662 -0.7058147872448792 -0.06042327542271249 3.02089273873073
            children [
              DEF RIGHT_GRIP SliderJoint {
                jointParameters JointParameters {
                  position 0.00016848702506826413
                  axis 1 0 0
                }
                device [
                  LinearMotor {
                    name "right grip"
                    maxVelocity 0.1
                    minPosition -6.244776062687065e-14
                    maxPosition 0.029
                    maxForce 100
                  }
                ]
                endPoint Solid {
                  translation 0.00016848702544477795 0 -0.048
                  rotation 0 1 0 1.5708
                  children [
                    Shape {
                      appearance PBRAppearance {
                        baseColor 0.8 0.8 0.8
                        roughness 1
                        metalness 0
                      }
                      geometry IndexedFaceSet {
                        coord Coordinate {
                          point [
                            0 -0.004 0.004
                            0.03 -0.004 0.002
                            0.03 -0.004 0.0001
                            0 -0.004 0.0001
                            0 -0.004 0.004
                            0 0.004 0.004
                            0.03 0.004 0.002
                            0.03 0.004 0.0001
                            0 0.004 0.0001
                            0 0.004 0.004
                          ]
                        }
                        coordIndex [
                          4, 3, 2, 1, 0, -1, 5, 6, 7, 8, 9, -1, 0, 1, 6, 5, -1, 1, 2, 7, 6, -1, 2, 3, 8, 7, -1, 3, 4, 9, 8, -1
                        ]
                      }
                    }
                    DistanceSensor {
                      translation 0.015 0 0
                      rotation 0 1 0 1.5708
                      name "ds"
                      lookupTable [
                        0 0 0
                        0.05 1000 0
                      ]
                      type "infra-red"
                    }
                  ]
                  name "right grip"
                  contactMaterial "gripper"
                  boundingObject Transform {
                    translation 0.015 0 0.003
                    children [
                      Box {
                        size 0.028 0.007 0.005
                      }
                    ]
                  }
                  physics Physics {
                    density 100
                    centerOfMass [
                      0.01 0 0
                    ]
                  }
                }
              }
              DEF LEFT_GRIP SliderJoint {
                jointParameters JointParameters {
                  position -0.0001684916865150082
                  axis -1 0 0
                }
                device [
                  LinearMotor {
                    name "left grip"
                    maxVelocity 0.1
                    minPosition -0.00016864583241887318
                    maxPosition 0.029
                    maxForce 100
                  }
                ]
                endPoint Solid {
                  translation 0.00016849168689152223 0 -0.048
                  rotation 0 1 0 -1.5708
                  children [
                    Shape {
                      appearance PBRAppearance {
                        baseColor 0.8 0.8 0.8
                        roughness 1
                        metalness 0
                      }
                      geometry IndexedFaceSet {
                        coord Coordinate {
                          point [
                            0 -0.004 0.0001
                            -0.03 -0.004 0.0001
                            -0.03 -0.004 0.002
                            0 -0.004 0.004
                            0 -0.004 0.0001
                            0 0.004 0.0001
                            -0.03 0.004 0.0001
                            -0.03 0.004 0.002
                            0 0.004 0.004
                            0 0.004 0.0001
                          ]
                        }
                        coordIndex [
                          4, 3, 2, 1, 0, -1, 5, 6, 7, 8, 9, -1, 0, 1, 6, 5, -1, 1, 2, 7, 6, -1, 2, 3, 8, 7, -1, 3, 4, 9, 8, -1
                        ]
                      }
                    }
                  ]
                  name "left grip"
                  contactMaterial "gripper"
                  boundingObject Transform {
                    translation -0.015 0 0.003
                    children [
                      Box {
                        size 0.028 0.007 0.005
                      }
                    ]
                  }
                  physics Physics {
                    density 100
                    centerOfMass [
                      -0.01 0 0
                    ]
                  }
                }
              }
              Shape {
                appearance PBRAppearance {
                  baseColor 0.8 0.8 0.8
                  roughness 1
                  metalness 0
                }
                geometry IndexedFaceSet {
                  coord Coordinate {
                    point [
                      0.035 -0.004 0.006
                      0.035 -0.004 -0.048
                      -0.035 -0.004 -0.048
                      -0.035 -0.004 0.006
                      -0.025 -0.004 0.006
                      -0.025 -0.004 -0.03
                      -0.016 -0.004 -0.04
                      0.016 -0.004 -0.04
                      0.025 -0.004 -0.03
                      0.025 -0.004 0.006
                      0.035 -0.004 0.006
                      0.035 0.004 0.006
                      0.035 0.004 -0.048
                      -0.035 0.004 -0.048
                      -0.035 0.004 0.006
                      -0.025 0.004 0.006
                      -0.025 0.004 -0.03
                      -0.016 0.004 -0.04
                      0.016 0.004 -0.04
                      0.025 0.004 -0.03
                      0.025 0.004 0.006
                      0.035 0.004 0.006
                    ]
                  }
                  coordIndex [
                    10, 9, 8, 7, 6, 5, 4, 3, 2, 1, 0, -1, 11, 12, 13, 14, 15, 16, 17, 18, 19, 20, 21, -1, 0, 1, 12, 11, -1, 1, 2, 13, 12, -1, 2, 3, 14, 13, -1, 3, 4, 15, 14, -1, 4, 5, 16, 15, -1, 5, 6, 17, 16, -1, 6, 7, 18, 17, -1, 7, 8, 19, 18, -1, 8, 9, 20, 19, -1, 9, 10, 21, 20, -1
                  ]
                }
              }
            ]
            boundingObject Transform {
              translation 0 0 -0.021
              children [
                Box {
                  size 0.068 0.008 0.052
                }
              ]
            }
            physics Physics {
              density 100
              centerOfMass [
                0 0 -0.02
              ]
            }
          }
        }
        DEF GRIPPER_BASE Transform {
          translation -0.01 0 0.023
          rotation 0.5773502691896258 -0.5773502691896258 -0.5773502691896258 2.094395
          children [
            Shape {
              appearance PBRAppearance {
                baseColor 0.8 0.8 0.8
                roughness 1
                metalness 0
              }
              geometry Box {
                size 0.05 0.01 0.01
              }
            }
          ]
        }
        Camera {
          translation -0.01 0 0.035
          rotation -0.999759341318827 -0.016153505514822745 -0.014843305067519018 -5.307179586466759e-06
          children [
            Shape {
              appearance PBRAppearance {
                baseColor 0.70632 0.70632 0.70632
                roughness 1
                metalness 0
              }
              geometry DEF CAMERA Box {
                size 0.03 0.03 0.02
              }
            }
          ]
          boundingObject DEF CAMERA Box {
            size 0.03 0.03 0.02
          }
          physics Physics {
            density -1
            mass 0.02
          }
          fieldOfView 0.3
          recognition Recognition {
            maxRange 50
          }
        }
      ]
    }
    Shape {
      appearance PBRAppearance {
        baseColor 0.0539951 0.505576 0.0897663
        roughness 0.4
        metalness 0
      }
      geometry IndexedFaceSet {
        coord Coordinate {
          point [
            0.009 -0.0276 0.0025, 0.0194 -0.0215 0.0025, 0.0265 -0.0118 0.0025, 0.029 0 0.0025, 0.0265 0.0118 0.0025, 0.0194 0.0215 0.0025, 0.009 0.0276 0.0025, 0.009 0.0236 0.02, -0.009 0.0236 0.02, -0.009 -0.0236 0.02, 0.009 -0.0236 0.02, -0.009 0.0276 0.0025, -0.0194 0.0215 0.0025, -0.0265 0.0118 0.0025, -0.029 0 0.0025, -0.0265 -0.0118 0.0025, -0.0194 -0.0215 0.0025, -0.009 -0.0276 0.0025, 0.009 -0.0276 0.001, 0.0194 -0.0215 0.001, 0.0265 -0.0118 0.001, 0.029 0 0.001, 0.0265 0.0118 0.001, 0.0194 0.0215 0.001, 0.009 0.0276 0.001, 0.009 0.0236 0.001, -0.009 0.0236 0.001, -0.009 -0.0236 0.001, 0.009 -0.0236 0.001, -0.009 0.0276 0.001, -0.0194 0.0215 0.001, -0.0265 0.0118 0.001, -0.029 0 0.001, -0.0265 -0.0118 0.001, -0.0194 -0.0215 0.001, -0.009 -0.0276 0.001
          ]
        }
        coordIndex [
          0, 1, 2, 3, 4, 5, 6, -1, 11, 12, 13, 14, 15, 16, 17, -1, 24, 23, 22, 21, 20, 19, 18, -1, 35, 34, 33, 32, 31, 30, 29, -1, 1, 0, 18, 19, -1, 2, 1, 19, 20, -1, 3, 2, 20, 21, -1, 4, 3, 21, 22, -1, 5, 4, 22, 23, -1, 6, 5, 23, 24, -1, 0, 6, 24, 18, -1, 17, 16, 34, 35, -1, 16, 15, 33, 34, -1, 15, 14, 32, 33, -1, 14, 13, 31, 32, -1, 13, 12, 30, 31, -1, 12, 11, 29, 30, -1, 11, 17, 35, 29, -1, 7, 10, 28, 25, -1, 9, 8, 26, 27, -1, 8, 7, 25, 26, -1, 10, 9, 27, 28, -1, 28, 27, 26, 25, -1
        ]
        creaseAngle 0.5
      }
    }
    HingeJoint {
      jointParameters HingeJointParameters {
        position -40.79907988019871
        axis 0 1 0
        anchor 0 0 0.0075
      }
      device [
        RotationalMotor {
          name "left wheel motor"
        }
        PositionSensor {
          name "left wheel sensor"
          resolution 0.0314
        }
      ]
      endPoint Solid {
        translation 0 0.02599999999999993 0.0075
        rotation 0.44664349959805866 -0.44664362268310975 -0.7752541896586609 1.8226549398058822
        children [
          DEF WHEEL Transform {
            rotation 0.5773869352700204 -0.5773319352761864 0.5773319352761864 -2.094339
            children [
              Shape {
                appearance PBRAppearance {
                  baseColor 0.778497 0.793743 0.8
                  roughness 0.3
                  metalness 0
                }
                geometry Cylinder {
                  height 0.003
                  radius 0.0075
                }
              }
            ]
          }
        ]
        name "left wheel"
        boundingObject USE WHEEL
        physics Physics {
        }
      }
    }
    HingeJoint {
      jointParameters HingeJointParameters {
        position 157.67913953102223
        axis 0 1 0
        anchor 0 0 0.0075
      }
      device [
        RotationalMotor {
          name "right wheel motor"
        }
        PositionSensor {
          name "right wheel sensor"
          resolution 0.0314
        }
      ]
      endPoint Solid {
        translation 0 -0.02599999999999969 0.0075
        rotation 0.693658755439113 -0.6936587123321641 0.1941008032140634 3.5250261327148604
        children [
          USE WHEEL
        ]
        name "right wheel"
        boundingObject USE WHEEL
        physics Physics {
        }
      }
    }
    Transform {
      translation 0 0 0.02
      rotation 0 0 1 -1.570796
      children [
        Shape {
          appearance PBRAppearance {
            baseColor 0.015 0.48 0.1796
            roughness 0.4
            metalness 0
          }
          geometry Cylinder {
            height 0.0015
            radius 0.028
          }
        }
      ]
    }
    DEF LS0 LightSensor {
      translation 0.00215188 0.0227638 0.0144
      rotation 0.5102819257784789 0.6081179115480401 0.6081159115483309 2.19792
      name "ls0"
      lookupTable [
        0 0 0
        4 1024 0
      ]
    }
    DEF LS1 LightSensor {
      translation 0.0139291 0.0114289 0.0144
      rotation 0.6776599336428648 0.5199889490821645 0.5199889490821645 1.95044
      name "ls1"
      lookupTable [
        0 0 0
        4 1024 0
      ]
    }
    DEF LS2 LightSensor {
      translation 0.0123588 -0.0225 0.0144
      rotation -0.5773509358554485 0.5773489358556708 0.5773509358554485 -2.094395307179586
      name "ls2"
      lookupTable [
        0 0 0
        4 1024 0
      ]
    }
    DEF LS3 LightSensor {
      translation -0.00166025 -0.00785883 0.0144
      rotation -0.1861570160863869 0.6947460600350939 0.6947470600351803 -2.7734953071795863
      name "ls3"
      lookupTable [
        0 0 0
        4 1024 0
      ]
    }
    DEF LS4 LightSensor {
      translation -0.0072844 0.00978409 0.0144
      rotation 0.2810839910810645 0.6785979784677472 0.6785989784677153 2.59357
      name "ls4"
      lookupTable [
        0 0 0
        4 1024 0
      ]
    }
    DEF LS5 LightSensor {
      translation -0.0103523 -0.0251114 0.0144
      rotation -0.8053168807607647 0.4192049379304254 0.4192039379305735 -1.7856453071795864
      name "ls5"
      lookupTable [
        0 0 0
        4 1024 0
      ]
    }
    DEF LS6 LightSensor {
      translation -0.0163407 -0.00641179 0.0144
      rotation -0.09269154676500942 0.7040625956398727 0.7040625956398727 -2.9567353071795863
      name "ls6"
      lookupTable [
        0 0 0
        4 1024 0
      ]
    }
    DEF LS7 LightSensor {
      translation -0.016 0.00899998 0.0144
      rotation 0 -0.7071067811865476 -0.7071067811865476 -3.14159
      name "ls7"
      lookupTable [
        0 0 0
        4 1024 0
      ]
    }
    DEF LED0 LED {
      translation 0.042 -0.003 0.021
      rotation 0.5773502691896258 -0.5773502691896258 -0.5773502691896258 2.094395
      children [
        PointLight {
          attenuation 0 0 12.56
          color 1 0 0
          intensity 0.25
          radius 10
        }
        Shape {
          appearance PBRAppearance {
            baseColor 0.501961 0.501961 0.501961
            metalness 0
            emissiveIntensity 7
          }
          geometry Box {
            size 0.002 0.002 0.002
          }
        }
      ]
      name "led0"
    }
    DEF LED1 LED {
      translation 0.024 -0.01 0.021
      rotation 0.5773502691896258 -0.5773502691896258 -0.5773502691896258 2.094395
      children [
        Shape {
          appearance PBRAppearance {
            baseColor 0.501961 0.501961 0.501961
            metalness 0
            emissiveColor 1 0 0
          }
          geometry Box {
            size 0.002 0.002 0.002
          }
        }
      ]
      name "led1"
    }
    DEF RS232_OUT Emitter {
      name "rs232_out"
      type "serial"
      range 1000
      baudRate 57600
    }
    DEF RS232_IN Receiver {
      name "rs232_in"
      type "serial"
      baudRate 57600
    }
  ]
  name "k0(4)"
  model "Khepera"
  description "A mini mobile robot by K-Team SA"
  contactMaterial "khepera"
  boundingObject Transform {
    translation 0 0 0.012
    rotation 0 0 1 -1.570796
    children [
      Cylinder {
        height 0.02
        radius 0.0285
      }
    ]
  }
  physics Physics {
    centerOfMass [
      0 0 0.005
    ]
  }
  controller "updated_generalized_ga_controller"
  supervisor TRUE
  linearVelocity 6.222079452499797e-05 -0.0017028594671920777 0.31868755145834393
  angularVelocity 0.005279563895309555 0.0009239450834570423 0.536466098152102
}
DEF r11 Solid {
  translation -0.06 0.51 0.02
  rotation -0.13196338955375952 -0.48148235857258037 0.86646431097932 1.8138686062099732e-17
  scale 2 2 2
  children [
    DEF STICK_SHAPE Shape {
      appearance PBRAppearance {
        baseColor 1 0.155604 0.246125
        roughness 0.783569247
        metalness 0
      }
      geometry Cylinder {
        height 0.06
        radius 0.008
      }
    }
  ]
  name "red stick(9)"
  model "red-rod-1"
  contactMaterial "stick"
  boundingObject Box {
    size 0.013 0.013 0.06
  }
  physics Physics {
    density 100
  }
  recognitionColors [
    0.8 0 0
  ]
  linearVelocity 2.941167474984914e-17 -1.1135660267595766e-17 3.295254361075188e-16
  angularVelocity 1.3298034687434809e-16 4.255378135189308e-16 -1.1072499514964799e-17
}
DEF r11 Solid {
  translation -0.9 0.65 0.02
  rotation -0.13196338955375952 -0.48148235857258037 0.86646431097932 1.8138686062099732e-17
  scale 2 2 2
  children [
    DEF STICK_SHAPE Shape {
      appearance PBRAppearance {
        baseColor 1 0.155604 0.246125
        roughness 0.783569247
        metalness 0
      }
      geometry Cylinder {
        height 0.06
        radius 0.008
      }
    }
  ]
  name "red stick(1)"
  model "red-rod-1"
  contactMaterial "stick"
  boundingObject Box {
    size 0.013 0.013 0.06
  }
  physics Physics {
    density 100
  }
  recognitionColors [
    0.8 0 0
  ]
  linearVelocity 2.941167474984914e-17 -1.1135660267595766e-17 3.295254361075188e-16
  angularVelocity 1.3298034687434809e-16 4.255378135189308e-16 -1.1072499514964799e-17
}
DEF r11 Solid {
  translation -0.36 0.72 0.02
  rotation -0.13196338955375952 -0.48148235857258037 0.86646431097932 1.8138686062099732e-17
  scale 2 2 2
  children [
    DEF STICK_SHAPE Shape {
      appearance PBRAppearance {
        baseColor 1 0.155604 0.246125
        roughness 0.783569247
        metalness 0
      }
      geometry Cylinder {
        height 0.06
        radius 0.008
      }
    }
  ]
  name "red stick(2)"
  model "red-rod-1"
  contactMaterial "stick"
  boundingObject Box {
    size 0.013 0.013 0.06
  }
  physics Physics {
    density 100
  }
  recognitionColors [
    0.8 0 0
  ]
  linearVelocity 2.941167474984914e-17 -1.1135660267595766e-17 3.295254361075188e-16
  angularVelocity 1.3298034687434809e-16 4.255378135189308e-16 -1.1072499514964799e-17
}
DEF r11 Solid {
  translation -0.86 0.31 0.02
  rotation -0.13196338955375952 -0.48148235857258037 0.86646431097932 1.8138686062099732e-17
  scale 2 2 2
  children [
    DEF STICK_SHAPE Shape {
      appearance PBRAppearance {
        baseColor 1 0.155604 0.246125
        roughness 0.783569247
        metalness 0
      }
      geometry Cylinder {
        height 0.06
        radius 0.008
      }
    }
  ]
  name "red stick(3)"
  model "red-rod-1"
  contactMaterial "stick"
  boundingObject Box {
    size 0.013 0.013 0.06
  }
  physics Physics {
    density 100
  }
  recognitionColors [
    0.8 0 0
  ]
  linearVelocity 2.941167474984914e-17 -1.1135660267595766e-17 3.295254361075188e-16
  angularVelocity 1.3298034687434809e-16 4.255378135189308e-16 -1.1072499514964799e-17
}
DEF r11 Solid {
  translation -0.21 0.71 0.02
  rotation -0.13196338955375952 -0.48148235857258037 0.86646431097932 1.8138686062099732e-17
  scale 2 2 2
  children [
    DEF STICK_SHAPE Shape {
      appearance PBRAppearance {
        baseColor 1 0.155604 0.246125
        roughness 0.783569247
        metalness 0
      }
      geometry Cylinder {
        height 0.06
        radius 0.008
      }
    }
  ]
  name "red stick(4)"
  model "red-rod-1"
  contactMaterial "stick"
  boundingObject Box {
    size 0.013 0.013 0.06
  }
  physics Physics {
    density 100
  }
  recognitionColors [
    0.8 0 0
  ]
  linearVelocity 2.941167474984914e-17 -1.1135660267595766e-17 3.295254361075188e-16
  angularVelocity 1.3298034687434809e-16 4.255378135189308e-16 -1.1072499514964799e-17
}
DEF r11 Solid {
  translation 0.44 0.52 0.02
  rotation -0.13196338955375952 -0.48148235857258037 0.86646431097932 1.8138686062099732e-17
  scale 2 2 2
  children [
    DEF STICK_SHAPE Shape {
      appearance PBRAppearance {
        baseColor 1 0.155604 0.246125
        roughness 0.783569247
        metalness 0
      }
      geometry Cylinder {
        height 0.06
        radius 0.008
      }
    }
  ]
  name "red stick(5)"
  model "red-rod-1"
  contactMaterial "stick"
  boundingObject Box {
    size 0.013 0.013 0.06
  }
  physics Physics {
    density 100
  }
  recognitionColors [
    0.8 0 0
  ]
  linearVelocity 2.941167474984914e-17 -1.1135660267595766e-17 3.295254361075188e-16
  angularVelocity 1.3298034687434809e-16 4.255378135189308e-16 -1.1072499514964799e-17
}
DEF r11 Solid {
  translation 0.81 0.41 0.02
  rotation -0.13196338955375952 -0.48148235857258037 0.86646431097932 1.8138686062099732e-17
  scale 2 2 2
  children [
    DEF STICK_SHAPE Shape {
      appearance PBRAppearance {
        baseColor 1 0.155604 0.246125
        roughness 0.783569247
        metalness 0
      }
      geometry Cylinder {
        height 0.06
        radius 0.008
      }
    }
  ]
  name "red stick(6)"
  model "red-rod-1"
  contactMaterial "stick"
  boundingObject Box {
    size 0.013 0.013 0.06
  }
  physics Physics {
    density 100
  }
  recognitionColors [
    0.8 0 0
  ]
  linearVelocity 2.941167474984914e-17 -1.1135660267595766e-17 3.295254361075188e-16
  angularVelocity 1.3298034687434809e-16 4.255378135189308e-16 -1.1072499514964799e-17
}
DEF r11 Solid {
  translation 0.22 0.35 0.02
  rotation -0.13196338955375952 -0.48148235857258037 0.86646431097932 1.8138686062099732e-17
  scale 2 2 2
  children [
    DEF STICK_SHAPE Shape {
      appearance PBRAppearance {
        baseColor 1 0.155604 0.246125
        roughness 0.783569247
        metalness 0
      }
      geometry Cylinder {
        height 0.06
        radius 0.008
      }
    }
  ]
  name "red stick(7)"
  model "red-rod-1"
  contactMaterial "stick"
  boundingObject Box {
    size 0.013 0.013 0.06
  }
  physics Physics {
    density 100
  }
  recognitionColors [
    0.8 0 0
  ]
  linearVelocity 2.941167474984914e-17 -1.1135660267595766e-17 3.295254361075188e-16
  angularVelocity 1.3298034687434809e-16 4.255378135189308e-16 -1.1072499514964799e-17
}
DEF r11 Solid {
  translation 0.45 0.8 0.02
  rotation -0.13196338955375952 -0.48148235857258037 0.86646431097932 1.8138686062099732e-17
  scale 2 2 2
  children [
    DEF STICK_SHAPE Shape {
      appearance PBRAppearance {
        baseColor 1 0.155604 0.246125
        roughness 0.783569247
        metalness 0
      }
      geometry Cylinder {
        height 0.06
        radius 0.008
      }
    }
  ]
  name "red stick(8)"
  model "red-rod-1"
  contactMaterial "stick"
  boundingObject Box {
    size 0.013 0.013 0.06
  }
  physics Physics {
    density 100
  }
  recognitionColors [
    0.8 0 0
  ]
  linearVelocity 2.941167474984914e-17 -1.1135660267595766e-17 3.295254361075188e-16
  angularVelocity 1.3298034687434809e-16 4.255378135189308e-16 -1.1072499514964799e-17
}
DEF r11 Solid {
  translation -0.09 0.58 0.02
  rotation -0.13196338955375952 -0.48148235857258037 0.86646431097932 1.8138686062099732e-17
  scale 2 2 2
  children [
    DEF STICK_SHAPE Shape {
      appearance PBRAppearance {
        baseColor 1 0.155604 0.246125
        roughness 0.783569247
        metalness 0
      }
      geometry Cylinder {
        height 0.06
        radius 0.008
      }
    }
  ]
  name "red stick(10)"
  model "red-rod-1"
  contactMaterial "stick"
  boundingObject Box {
    size 0.013 0.013 0.06
  }
  physics Physics {
    density 100
  }
  recognitionColors [
    0.8 0 0
  ]
  linearVelocity 2.941167474984914e-17 -1.1135660267595766e-17 3.295254361075188e-16
  angularVelocity 1.3298034687434809e-16 4.255378135189308e-16 -1.1072499514964799e-17
}
DEF r11 Solid {
  translation -0.84 -0.3 0.02
  rotation -0.13196338955375952 -0.48148235857258037 0.86646431097932 1.8138686062099732e-17
  scale 2 2 2
  children [
    DEF STICK_SHAPE Shape {
      appearance PBRAppearance {
        baseColor 1 0.155604 0.246125
        roughness 0.783569247
        metalness 0
      }
      geometry Cylinder {
        height 0.06
        radius 0.008
      }
    }
  ]
  name "red stick(11)"
  model "red-rod-1"
  contactMaterial "stick"
  boundingObject Box {
    size 0.013 0.013 0.06
  }
  physics Physics {
    density 100
  }
  recognitionColors [
    0.8 0 0
  ]
  linearVelocity 2.941167474984914e-17 -1.1135660267595766e-17 3.295254361075188e-16
  angularVelocity 1.3298034687434809e-16 4.255378135189308e-16 -1.1072499514964799e-17
}
DEF r11 Solid {
  translation -0.89 -0.22 0.02
  rotation -0.13196338955375952 -0.48148235857258037 0.86646431097932 1.8138686062099732e-17
  scale 2 2 2
  children [
    DEF STICK_SHAPE Shape {
      appearance PBRAppearance {
        baseColor 1 0.155604 0.246125
        roughness 0.783569247
        metalness 0
      }
      geometry Cylinder {
        height 0.06
        radius 0.008
      }
    }
  ]
  name "red stick(12)"
  model "red-rod-1"
  contactMaterial "stick"
  boundingObject Box {
    size 0.013 0.013 0.06
  }
  physics Physics {
    density 100
  }
  recognitionColors [
    0.8 0 0
  ]
  linearVelocity 2.941167474984914e-17 -1.1135660267595766e-17 3.295254361075188e-16
  angularVelocity 1.3298034687434809e-16 4.255378135189308e-16 -1.1072499514964799e-17
}
DEF r11 Solid {
  translation -0.56 -0.91 0.02
  rotation -0.13196338955375952 -0.48148235857258037 0.86646431097932 1.8138686062099732e-17
  scale 2 2 2
  children [
    DEF STICK_SHAPE Shape {
      appearance PBRAppearance {
        baseColor 1 0.155604 0.246125
        roughness 0.783569247
        metalness 0
      }
      geometry Cylinder {
        height 0.06
        radius 0.008
      }
    }
  ]
  name "red stick(13)"
  model "red-rod-1"
  contactMaterial "stick"
  boundingObject Box {
    size 0.013 0.013 0.06
  }
  physics Physics {
    density 100
  }
  recognitionColors [
    0.8 0 0
  ]
  linearVelocity 2.941167474984914e-17 -1.1135660267595766e-17 3.295254361075188e-16
  angularVelocity 1.3298034687434809e-16 4.255378135189308e-16 -1.1072499514964799e-17
}
DEF r11 Solid {
  translation -0.18 -0.07 0.02
  rotation -0.13196338955375952 -0.48148235857258037 0.86646431097932 1.8138686062099732e-17
  scale 2 2 2
  children [
    DEF STICK_SHAPE Shape {
      appearance PBRAppearance {
        baseColor 1 0.155604 0.246125
        roughness 0.783569247
        metalness 0
      }
      geometry Cylinder {
        height 0.06
        radius 0.008
      }
    }
  ]
  name "red stick(14)"
  model "red-rod-1"
  contactMaterial "stick"
  boundingObject Box {
    size 0.013 0.013 0.06
  }
  physics Physics {
    density 100
  }
  recognitionColors [
    0.8 0 0
  ]
  linearVelocity 2.941167474984914e-17 -1.1135660267595766e-17 3.295254361075188e-16
  angularVelocity 1.3298034687434809e-16 4.255378135189308e-16 -1.1072499514964799e-17
}
DEF r11 Solid {
  translation 0.82 0.14 0.02
  rotation -0.13196338955375952 -0.48148235857258037 0.86646431097932 1.8138686062099732e-17
  scale 2 2 2
  children [
    DEF STICK_SHAPE Shape {
      appearance PBRAppearance {
        baseColor 1 0.155604 0.246125
        roughness 0.783569247
        metalness 0
      }
      geometry Cylinder {
        height 0.06
        radius 0.008
      }
    }
  ]
  name "red stick(15)"
  model "red-rod-1"
  contactMaterial "stick"
  boundingObject Box {
    size 0.013 0.013 0.06
  }
  physics Physics {
    density 100
  }
  recognitionColors [
    0.8 0 0
  ]
  linearVelocity 2.941167474984914e-17 -1.1135660267595766e-17 3.295254361075188e-16
  angularVelocity 1.3298034687434809e-16 4.255378135189308e-16 -1.1072499514964799e-17
}
DEF r11 Solid {
  translation 0.61 -0.42 0.02
  rotation -0.13196338955375952 -0.48148235857258037 0.86646431097932 1.8138686062099732e-17
  scale 2 2 2
  children [
    DEF STICK_SHAPE Shape {
      appearance PBRAppearance {
        baseColor 1 0.155604 0.246125
        roughness 0.783569247
        metalness 0
      }
      geometry Cylinder {
        height 0.06
        radius 0.008
      }
    }
  ]
  name "red stick(16)"
  model "red-rod-1"
  contactMaterial "stick"
  boundingObject Box {
    size 0.013 0.013 0.06
  }
  physics Physics {
    density 100
  }
  recognitionColors [
    0.8 0 0
  ]
  linearVelocity 2.941167474984914e-17 -1.1135660267595766e-17 3.295254361075188e-16
  angularVelocity 1.3298034687434809e-16 4.255378135189308e-16 -1.1072499514964799e-17
}
DEF r11 Solid {
  translation 0.6 -0.39 0.02
  rotation -0.13196338955375952 -0.48148235857258037 0.86646431097932 1.8138686062099732e-17
  scale 2 2 2
  children [
    DEF STICK_SHAPE Shape {
      appearance PBRAppearance {
        baseColor 1 0.155604 0.246125
        roughness 0.783569247
        metalness 0
      }
      geometry Cylinder {
        height 0.06
        radius 0.008
      }
    }
  ]
  name "red stick(17)"
  model "red-rod-1"
  contactMaterial "stick"
  boundingObject Box {
    size 0.013 0.013 0.06
  }
  physics Physics {
    density 100
  }
  recognitionColors [
    0.8 0 0
  ]
  linearVelocity 2.941167474984914e-17 -1.1135660267595766e-17 3.295254361075188e-16
  angularVelocity 1.3298034687434809e-16 4.255378135189308e-16 -1.1072499514964799e-17
}
DEF r11 Solid {
  translation -0.2 -0.93 0.02
  rotation -0.13196338955375952 -0.48148235857258037 0.86646431097932 1.8138686062099732e-17
  scale 2 2 2
  children [
    DEF STICK_SHAPE Shape {
      appearance PBRAppearance {
        baseColor 1 0.155604 0.246125
        roughness 0.783569247
        metalness 0
      }
      geometry Cylinder {
        height 0.06
        radius 0.008
      }
    }
  ]
  name "red stick(18)"
  model "red-rod-1"
  contactMaterial "stick"
  boundingObject Box {
    size 0.013 0.013 0.06
  }
  physics Physics {
    density 100
  }
  recognitionColors [
    0.8 0 0
  ]
  linearVelocity 2.941167474984914e-17 -1.1135660267595766e-17 3.295254361075188e-16
  angularVelocity 1.3298034687434809e-16 4.255378135189308e-16 -1.1072499514964799e-17
}
DEF r11 Solid {
  translation -0.8 -0.48 0.02
  rotation -0.13196338955375952 -0.48148235857258037 0.86646431097932 1.8138686062099732e-17
  scale 2 2 2
  children [
    DEF STICK_SHAPE Shape {
      appearance PBRAppearance {
        baseColor 1 0.155604 0.246125
        roughness 0.783569247
        metalness 0
      }
      geometry Cylinder {
        height 0.06
        radius 0.008
      }
    }
  ]
  name "red stick(19)"
  model "red-rod-1"
  contactMaterial "stick"
  boundingObject Box {
    size 0.013 0.013 0.06
  }
  physics Physics {
    density 100
  }
  recognitionColors [
    0.8 0 0
  ]
  linearVelocity 2.941167474984914e-17 -1.1135660267595766e-17 3.295254361075188e-16
  angularVelocity 1.3298034687434809e-16 4.255378135189308e-16 -1.1072499514964799e-17
}
DEF r11 Solid {
  translation -0.05 -0.26 0.02
  rotation -0.13196338955375952 -0.48148235857258037 0.86646431097932 1.8138686062099732e-17
  scale 2 2 2
  children [
    DEF STICK_SHAPE Shape {
      appearance PBRAppearance {
        baseColor 1 0.155604 0.246125
        roughness 0.783569247
        metalness 0
      }
      geometry Cylinder {
        height 0.06
        radius 0.008
      }
    }
  ]
  name "red stick(20)"
  model "red-rod-1"
  contactMaterial "stick"
  boundingObject Box {
    size 0.013 0.013 0.06
  }
  physics Physics {
    density 100
  }
  recognitionColors [
    0.8 0 0
  ]
  linearVelocity 2.941167474984914e-17 -1.1135660267595766e-17 3.295254361075188e-16
  angularVelocity 1.3298034687434809e-16 4.255378135189308e-16 -1.1072499514964799e-17
}
DEF supervisor TinkerbotsBase {
  hidden linearVelocity_0 -0.1403356463442722 9.265493166269262e-07 1.4924542441845437e-05
  hidden angularVelocity_0 -4.9967842377872946e-05 0.0001939739256235664 -1.3445444413483125e-05
  translation 0 2 0
  rotation -0.00021026392449943353 1.9966319444159918e-05 0.9999999776952139 -3.065140180655414
  name "Tinkerbots(1)"
  controller "ga_individual_supervisor"
  supervisor TRUE
  extensionSlot [
    Receiver {
      name "receiver_processor"
    }
    Receiver {
      channel 5
    }
    Emitter {
      channel 1
    }
  ]
}
DEF supervisor TinkerbotsBase {
  hidden linearVelocity_0 -0.1403356463442722 9.265493166269262e-07 1.4924542441845437e-05
  hidden angularVelocity_0 -4.9967842377872946e-05 0.0001939739256235664 -1.3445444413483125e-05
  translation 0 2 0
  rotation -0.00021026392449943353 1.9966319444159918e-05 0.9999999776952139 -3.065140180655414
  name "Tinkerbots(2)"
  controller "ga_individual_supervisor"
  supervisor TRUE
  extensionSlot [
    Receiver {
      name "receiver_processor"
      channel 10
    }
    Receiver {
      channel 5
    }
    Emitter {
      channel 1
    }
  ]
}
DEF supervisor TinkerbotsBase {
  hidden linearVelocity_0 -0.1403356463442722 9.265493166269262e-07 1.4924542441845437e-05
  hidden angularVelocity_0 -4.9967842377872946e-05 0.0001939739256235664 -1.3445444413483125e-05
  translation 0 2 0
  rotation -0.00021026392449943353 1.9966319444159918e-05 0.9999999776952139 -3.065140180655414
  name "Tinkerbots(3)"
  controller "ga_individual_supervisor"
  supervisor TRUE
  extensionSlot [
    Receiver {
      name "receiver_processor"
      channel 20
    }
    Receiver {
      channel 5
    }
    Emitter {
      channel 1
    }
  ]
}
DEF supervisor TinkerbotsBase {
  hidden linearVelocity_0 -0.1403356463442722 9.265493166269262e-07 1.4924542441845437e-05
  hidden angularVelocity_0 -4.9967842377872946e-05 0.0001939739256235664 -1.3445444413483125e-05
  translation 0 2 0
  rotation -0.00021026392449943353 1.9966319444159918e-05 0.9999999776952139 -3.065140180655414
  name "Tinkerbots(4)"
  controller "ga_individual_supervisor"
  supervisor TRUE
  extensionSlot [
    Receiver {
      name "receiver_processor"
      channel 30
    }
    Receiver {
      channel 5
    }
    Emitter {
      channel 1
    }
  ]
}
DEF supervisor TinkerbotsBase {
  hidden linearVelocity_0 -0.1403356463442722 9.265493166269262e-07 1.4924542441845437e-05
  hidden angularVelocity_0 -4.9967842377872946e-05 0.0001939739256235664 -1.3445444413483125e-05
  translation 0.46968840912076926 -0.8866490563260657 0.02048963985946303
  rotation -0.00021026392449943353 1.9966319444159918e-05 0.9999999776952139 -3.065140180655414
  name "Tinkerbots(5)"
  controller "ga_individual_supervisor"
  supervisor TRUE
  extensionSlot [
    Receiver {
      name "receiver_processor"
      channel 40
    }
    Receiver {
      channel 5
    }
    Emitter {
      channel 1
    }
  ]
}
